Workbook

Sheet COURSE ASSESSMENT
A1: PANIMALAR ENGINEERING COLLEGE
A3: Department of AI&DS
A4: Course Assessment Work Sheet
A6: SUBJECT NAME | B6: MATRICES AND CALCULUS | L6: Threshold | M6: Level 1 | N6: 60% students scoring more than threshold
A7: SUBJECT CODE | B7: 23MA1301 | L7: 65 | M7: Level 2 | N7: 70% students scoring more than threshold
A8: COURSE CODE | B8: C101 | M8: Level 3 | N8: 80% students scoring more than threshold
A9: YEAR / SEM | B9: I/I
A10: BATCH | B10: 2023-2027
A11: ACADEMIC YEAR | B11: 2023 - 2024
A12: THRESHOLD | B12: 65
A16: Upon Successful Completion of this Course, Students will be able to
A18: CO1 | B18: Determine the Eigen values and eigenvectors,diagonalizationof amatrix, symmetric matrices,positive definite matrices and Similar matrices.
A19: CO2 | B19: Apply limit definition and rules of differentiation to differentiate functions
A20: CO3 | B20: Apply the knowledge of Maxima and Minima, Jacobian, Taylor series and apply the problems involving Science and Engineering.
A21: CO4 | B21: Apply the knowledge of Integration by parts,Trigonometric integrals, Trigonometric substitutions, Integration of rational functions by partial fraction.
A22: CO5 | B22: Apply the knowledge of Area enclosed by plane curves,Change Of variables in double integrals,Tripleintegrals,Volumeof Solids.
A25: Program Outcomes
A27: 1 | B27: PO1: Engineering Knowledge Apply knowledge of mathematics, natural science, computing, engineering fundamentals and an engineering specialization as specified in WK1 to WK4 respectively to develop to the solution of complex engineering problems.
A28: 2 | B28: PO2: Problem Analysis Identify, formulate, review research literature and analyze complex engineering problems reaching substantiated conclusions with consideration for sustainable development. (WK1 to WK4)
A29: 3 | B29: PO3: Design/Development of Solutions Design creative solutions for complex engineering problems and design/develop systems/components/processes to meet identified needs with consideration for the public health and safety, whole-life cost, net zero carbon, culture, society and environment as required. (WK5)
A30: 4 | B30: PO4: Conduct Investigations of Complex Problems Conduct investigations of complex engineering problems using research-based knowledge including design of experiments, modelling, analysis & interpretation of data to provide valid conclusions. (WK8).
A31: 5 | B31: PO5: Engineering Tool Usage Create, select and apply appropriate techniques, resources and modern engineering & IT tools, including prediction and modelling recognizing their limitations to solve complex engineering problems. (WK2 and WK6)
A32: 6 | B32: PO6: The Engineer and the World Analyze and evaluate societal and environmental aspects while solving complex engineering problems for its impact on sustainability with reference to economy, health, safety, legal framework, culture and environment. (WK1, WK5 and WK8).
A33: 8 | B33: PO8: Ethics Apply ethical principles and commit to professional ethics, human values, diversity and inclusion; adhere to national & international laws. (WK9).
A34: 8 | B34: PO8: Individual and Collaborative Team Work Function effectively as an individual, and as a member or leader in diverse/multi-disciplinary teams.
A35: 9 | B35: PO9: Communication Communicate effectively and inclusively within the engineering community and society at large, such as being able to comprehend and write effective reports and design documentation, make effective presentations considering cultural, language, and learning differences.
A36: 10 | B36: PO10: Project Management and Finance Apply knowledge and understanding of engineering management principles and economic decision-making and apply these to one’s own work, as a member and leader in a team, and to manage projects and in multidisciplinary environments.
A37: 11 | B37: PO11: Life-Long Learning Recognize the need for, and have the preparation and ability for i) independent and life-long learning ii) adaptability to new and emerging technologies and iii) critical thinking in the broadest context of technological change. (WK8) .
A41: Program Specific Outcomes
A43: 1 | B43: PSO 1 : AI Driven Innovation Graduates should be able to evolve AI based efficient domain specific processes for effective decision making in several domains such as business and governance domains.
A44: 2 | B44: PSO 2 : Data-Driven Decision Making Insight Graduates should be able to arrive at actionable fore sight, insight, hind sight from data for solving business and engineering problems.
A45: 3 | B45: PSO 3 : Societal Intelligence Solutions Graduates should be able to create, select and apply the theoretical knowledge of AI and Data Analytics along with practical industrial tools and techniques to manage and solve wicked societal problems.
A49: CO - PO Matrix
A51: CO | B51: PO1 | C51: PO2 | D51: PO3 | E51: PO4 | F51: PO5 | G51: PO6 | H51: PO8 | I51: PO8 | J51: PO9 | K51: PO10 | L51: PO13 | M51: PSO1 | O51: PSO2 | Q51: PSO3
A52: C101.1 | B52: 3 | C52: 3 | L52: 2
A53: C101.2 | B53: 3 | C53: 3 | L53: 2
A54: C101.3 | B54: 3 | C54: 3 | L54: 2
A55: C101.4 | B55: 3 | C55: 3 | L55: 2
A56: C101.5 | B56: 3 | C56: 3 | L56: 2
A57: C301.AVG | B57: =IFERROR(AVERAGEIF(B52:B56,"<>"),"") -> 3 | C57: =IFERROR(AVERAGEIF(C52:C56,"<>"),"") -> 3 | D57: =IFERROR(AVERAGEIF(D52:D56,"<>"),"") | E57: =IFERROR(AVERAGEIF(E52:E56,"<>"),"") | F57: =IFERROR(AVERAGEIF(F52:F56,"<>"),"") | G57: =IFERROR(AVERAGEIF(G52:G56,"<>"),"") | H57: =IFERROR(AVERAGEIF(H52:H56,"<>"),"") | I57: =IFERROR(AVERAGEIF(I52:I56,"<>"),"") | ... Q57: =IFERROR(AVERAGEIF(Q52:Q56,"<>"),"")
...

Sheet STUDENT NAMELIST
A1: PANIMALAR ENGINEERING COLLEGE
A2: STUDENTS NAMELIST
A3: S.NO | B3: REG.NO | C3: ROLL.NO | D3: STUDENT NAME
A5: 1 | B5: 211423243003 | C5: 2023PEC AI 101 | D5: ABINAYA M
A6: 2 | B6: 211423243005 | C6: 2023PEC AI 102 | D6: ABIRAMI A
A7: 3 | B7: 211423243006 | C7: 2023PEC AI 103 | D7: ABIRAMI G
A8: 4 | B8: 211423243009 | C8: 2023PEC AI 104 | D8: ABITHA R D
A9: 5 | B9: 211423243011 | C9: 2023PEC AI 105 | D9: ADELINE JERUSHA AUGUSTINE
A10: 6 | B10: 211423243014 | C10: 2023PEC AI 106 | D10: AFIFA FATHIMA S
A11: 7 | B11: 211423243016 | C11: 2023PEC AI 107 | D11: AFSHAN TAJ F
A12: 8 | B12: 211423243017 | C12: 2023PEC AI 108 | D12: AISHWARYA P
A13: 9 | B13: 211423243022 | C13: 2023PEC AI 109 | D13: AKSHAYA SAKTHI G
A14: 10 | B14: 211423243025 | C14: 2023PEC AI 110 | D14: AMIRTHA A
A15: 11 | B15: 211423243033 | C15: 2023PEC AI 111 | D15: ANTONY AMALA TRINITA J
A16: 12 | B16: 211423243041 | C16: 2023PEC AI 112 | D16: ARSHIYA ROSELINE P
... A508: 504 | B508: 211423243114 | C508: 2023PEC AI 604 | D508: ELANCHEZHIAN V

Sheet INTERNAL - I
A1: SUBJECT NAME | C1: OBJECT ORIENTED PROGRAMMING PARADIGM | E1: =IF(E14="NA",1,0) -> 0 | F1: =IF(F14="NA",1,0) -> 0 | G1: =IF(G14="NA",1,0) -> 0 | H1: =IF(H14="NA",1,0) -> 0 | J1: =IF(J14="NA",1,0) -> 0 | K1: =IF(K14="NA",1,0) -> 0 | L1: =IF(L14="NA",1,0) -> 0 | M1: =IF(M14="NA",1,0) -> 0 | O1: =IF(O14="NA",1,0) -> 0 | P1: =IF(P14="NA",1,0) -> 0 | Q1: =IF(Q14="NA",1,0) -> 0 | R1: =IF(R14="NA",1,0) -> 0 | S1: =IF(S14="NA",1,0) -> 0 | T1: =IF(T14="NA",1,0) -> 0 | U1: =IF(U14="NA",1,0) -> 0 | V1: =IF(V14="NA",1,0) -> 0 | ... Z1: =IF(Z14="NA",1,0) -> 0
A2: SUBJECT CODE | C2: 21AD1603 | D2: COURSE CODE | E2: 0
A3: YEAR / SEM | C3: II / III | D3: BATCH | E3: 2022-26
A4: ACADEMIC YEAR | C4: 2023-24
A5: FACULTY NAME(S) | C5: MRS.J.ANITHA,MRS.S.SRINIDHI,Dr.S.HEMAMALINI
A6: REGULATION | C6: 0 | E6: INTERNAL ASSESSMENT - I
A7: PANIMALAR ENGINEERING COLLEGE
A8: ACEDAMIC YEAR: | E8: ='COURSE ASSESSMENT'!$B$6 -> MATRICES AND CALCULUS | H8: INTERNAL - I RESULT | AA8: TOTAL
A9: Sl. No | B9: ROLL NO. | C9: REG NO. | D9: QUESTION NUMBER >> | E9: PART A
E10: Q. No.1 | F10: Q. No.2 | G10: Q. No.3 | H10: Q. No. 4 | I10: Q. No. 5 | J10: Q. No. 6 | K10: Q. No. 8 | L10: Q. No. 8 | M10: Q. No. 9 | N10: Q. No. 10 | O10: Q. No. 13 | Q10: Q. No. 14 | S10: Q. No. 16 | U10: Q. No. 14 | W10: Q. No. 15 | Y10: Q. No. 16 | AB10: =SUMIF($E$14:$N$14,"CO1",$E$13:$N$13) -> 8 | AC10: =SUMIF($E$14:$N$14,"CO2",$E$13:$N$13) -> 8 | AD10: =SUMIF($E$14:$N$14,"CO3",$E$13:$N$13) -> 4 | AE10: =SUMIF($E$14:$N$14,"CO4",$E$13:$N$13) -> 0 | AF10: =SUMIF($E$14:$N$14,"CO5",$E$13:$N$13) -> 0 | AG10: =SUMIF($E$14:$N$14,"CO6",$E$13:$N$13) -> 0
AB11: =SUMPRODUCT(($O$14:$Z$14="CO1")*($O$13:$Z$13)*MOD(COLUMN($O$14:$Z$14)-COLUMN($O$14)+1,2)) -> 32 | AC11: =SUMPRODUCT(($O$14:$Z$14="CO2")*($O$13:$Z$13)*MOD(COLUMN($O$14:$Z$14)-COLUMN($O$14)+1,2)) -> 32 | AD11: =SUMPRODUCT(($O$14:$Z$14="CO3")*($O$13:$Z$13)*MOD(COLUMN($O$14:$Z$14)-COLUMN($O$14)+1,2)) -> 16 | AE11: =SUMPRODUCT(($O$14:$Z$14="CO4")*($O$13:$Z$13)*MOD(COLUMN($O$14:$Z$14)-COLUMN($O$14)+1,2)) -> 0 | AF11: =SUMPRODUCT(($O$14:$Z$14="CO5")*($O$13:$Z$13)*MOD(COLUMN($O$14:$Z$14)-COLUMN($O$14)+1,2)) -> 0 | AG11: =SUMPRODUCT(($O$14:$Z$14="CO6")*($O$13:$Z$13)*MOD(COLUMN($O$14:$Z$14)-COLUMN($O$14)+1,2)) -> 0
O12: 13.a | P12: 13.b | Q12: 14.a | R12: 14.b | S12: 16.a | T12: 16.b | U12: 14.a | V12: 14.b | W12: 15 a | X12: 15 b | AB12: =SUMPRODUCT(($P$14:$Z$14="CO1")*($P$13:$Z$13)*MOD(COLUMN($P$14:$Z$14)-COLUMN($P$14)+1,2)) -> 32 | AC12: =SUMPRODUCT(($P$14:$Z$14="CO2")*($P$13:$Z$13)*MOD(COLUMN($P$14:$Z$14)-COLUMN($P$14)+1,2)) -> 32 | AD12: =SUMPRODUCT(($P$14:$Z$14="CO3")*($P$13:$Z$13)*MOD(COLUMN($P$14:$Z$14)-COLUMN($P$14)+1,2)) -> 16 | AE12: =SUMPRODUCT(($P$14:$Z$14="CO4")*($P$13:$Z$13)*MOD(COLUMN($P$14:$Z$14)-COLUMN($P$14)+1,2)) -> 0 | AF12: =SUMPRODUCT(($P$14:$Z$14="CO5")*($P$13:$Z$13)*MOD(COLUMN($P$14:$Z$14)-COLUMN($P$14)+1,2)) -> 0 | AG12: =SUMPRODUCT(($P$14:$Z$14="CO6")*($P$13:$Z$13)*MOD(COLUMN($P$14:$Z$14)-COLUMN($P$14)+1,2)) -> 0
D13: MAXIMUM MARK >> | E13: 2 | F13: 2 | G13: 2 | H13: 2 | I13: 2 | J13: 2 | K13: 2 | L13: 2 | M13: 2 | N13: 2 | O13: 16 | P13: 16 | Q13: 16 | R13: 16 | S13: 16 | T13: 16 | U13: 16 | V13: 16 | W13: 16 | X13: 16 | AA13: 100 | AH13: TOTAL (100)
D14: COURSE OUTCOME >> | E14: CO1 | F14: CO1 | G14: CO1 | H14: CO1 | I14: CO2 | J14: CO2 | K14: CO2 | L14: CO2 | M14: CO3 | N14: CO3 | O14: CO1 | P14: CO1 | Q14: CO1 | R14: CO1 | S14: CO2 | T14: CO2 | U14: CO2 | V14: CO2 | W14: CO3 | X14: CO3 | AB14: CO1 | AC14: CO2 | AD14: CO3 | AE14: CO4 | AF14: CO5 | AG14: CO6 | AI14: CO1% | AJ14: CO2% | AK14: CO3% | AL14: CO4% | AM14: CO5% | AN14: CO6%
D15: STUDENT NAME | AB15: =SUMIF($E$14:$Z$14,"CO1",$E$13:$Z$13) -> 72 | AC15: =SUMIF($E$14:$Z$14,"CO2",$E$13:$Z$13) -> 72 | AD15: =SUMIF($E$14:$Z$14,"CO3",$E$13:$Z$13) -> 36 | AE15: =SUMIF($E$14:$Z$14,"CO4",$E$13:$Z$13) -> 0 | AF15: =SUMIF($E$14:$Z$14,"CO5",$E$13:$Z$13) -> 0 | AG15: =SUMIF($E$14:$Z$14,"CO6",$E$13:$Z$13) -> 0
A17: 1 | B17: ='STUDENT NAMELIST'!B5 -> 211423243003 | C17: ='STUDENT NAMELIST'!C5 -> 2023PEC AI 101 | D17: ='STUDENT NAMELIST'!D5 -> ABINAYA M | E17: 0 | F17: 1 | G17: 1 | H17: 0 | I17: 2 | J17: 2 | K17: 2 | L17: 0 | M17: 0 | N17: 0 | O17: 13 | P17: 0 | Q17: 0 | R17: 16 | S17: 13 | T17: 0 | U17: 16 | V17: 0 | W17: 0 | X17: 8 | AA17: =SUM(E17,F17,G17,H17,I17,J17,K17,L17,M17,N17,O17,P17,Q17,R17,S17,T17,U17,V17,W17,X17,Y17,Z17) -> 74 | AB17: =SUMIF($E$14:$N$14,"CO1",E17:N17)+IF(O17>=0,SUMPRODUCT(($O$14:$Z$14="CO1")*(O17:Z17)*MOD(COLUMN($O$14:$Z$14)-COLUMN($O$14)+1,2))+SUMPRODUCT(($P$14:$Z$14="CO1")*(P17:Z17)*MOD(COLUMN($P$14:$Z$14)-COLUMN($P$14)+1,2))) -> 31 | AC17: =SUMIF($E$14:$N$14,"CO1",F17:O17)+IF(P17>=0,SUMPRODUCT(($O$14:$Z$14="CO1")*(P17:AA17)*MOD(COLUMN($O$14:$Z$14)-COLUMN($O$14)+1,2))+SUMPRODUCT(($P$14:$Z$14="CO1")*(Q17:AA17)*MOD(COLUMN($P$14:$Z$14)-COLUMN($P$14)+1,2))) -> 33 | AD17: =SUMIF($E$14:$N$14,"CO3",E17:N17)+IF(O17>=0, SUMPRODUCT(($O$14:$Z$14="CO3")*(O17:Z17)*MOD(COLUMN($O$14:$Z$14)-COLUMN($O$14)+1,2))+ SUMPRODUCT(($P$14:$Z$14="CO3")*(P17:Z17)*MOD(COLUMN($P$14:$Z$14)-COLUMN($P$14)+1,2))) -> 8 | AE17: =SUMIF($E$14:$N$14,"CO4",$E$17:$N$17) + IF(O17>=0, SUMPRODUCT(($O$14:$Z$14="CO4")*(O17:Z17)*MOD(COLUMN($O$14:$Z$14)-COLUMN($O$14)+1,2))+ SUMPRODUCT(($P$14:$Z$14="CO4")*(P17:Z17)*MOD(COLUMN($P$14:$Z$14)-COLUMN($P$14)+1,2))) -> 0 | AF17: 0 | AG17: =SUMIF($E$14:$N$14,"CO6",$E$17:$N$17) + IF(O17>0, SUMPRODUCT(($O$14:$Z$14="CO6")*($O$17:$Z$17)*MOD(COLUMN($O$14:$Z$14)-COLUMN($O$14)+1,2))+ SUMPRODUCT(($P$14:$Z$14="CO6")*($P$17:$Z$17)*MOD(COLUMN($P$14:$Z$14)-COLUMN($P$14)+1,2)) ) -> 0 | AH17: =SUM(AB17:AG17) -> 72 | AI17: =AB17/(SUMIF($E$14:$N$14,"CO1",$E$13:$N$13)+SUMPRODUCT(($O$14:$Z$14="CO1")*($O17:$Z17>0)*($O$13:$Z$13)))*100 -> 77.5 | AJ17: =AC17/(SUMIF($E$14:$N$14,"CO1",$E$13:$N$13)+SUMPRODUCT(($O$14:$Z$14="CO1")*($O17:$Z17>0)*($O$13:$Z$13)))*100 -> 82.5 | AK17: =AD17/(SUMIF($E$14:$N$14,"CO3",$E$13:$N$13)+SUMPRODUCT(($O$14:$Z$14="CO3")*($O17:$Z17>0)*($O$13:$Z$13)))*100 -> 40
A18: 2 | B18: ='STUDENT NAMELIST'!B6 -> 211423243005 | C18: ='STUDENT NAMELIST'!C6 -> 2023PEC AI 102 | D18: ='STUDENT NAMELIST'!D6 -> ABIRAMI A | E18: 2 | F18: 1 | G18: 0 | H18: 0 | I18: 0 | J18: 1 | K18: 1 | L18: 1 | M18: 0 | N18: 1 | O18: 0 | P18: 10 | Q18: 16 | R18: 0 | S18: 0 | T18: 10 | U18: 0 | V18: 16 | W18: 15 | X18: 0 | AA18: =SUM(E18,F18,G18,H18,I18,J18,K18,L18,M18,N18,O18,P18,Q18,R18,S18,T18,U18,V18,W18,X18,Y18,Z18) -> 74 | AB18: =SUMIF($E$14:$N$14,"CO1",E18:N18)+IF(O18>=0,SUMPRODUCT(($O$14:$Z$14="CO1")*(O18:Z18)*MOD(COLUMN($O$14:$Z$14)-COLUMN($O$14)+1,2))+SUMPRODUCT(($P$14:$Z$14="CO1")*(P18:Z18)*MOD(COLUMN($P$14:$Z$14)-COLUMN($P$14)+1,2))) -> 29 | AC18: =SUMIF($E$14:$N$14,"CO1",F18:O18)+IF(P18>=0,SUMPRODUCT(($O$14:$Z$14="CO1")*(P18:AA18)*MOD(COLUMN($O$14:$Z$14)-COLUMN($O$14)+1,2))+SUMPRODUCT(($P$14:$Z$14="CO1")*(Q18:AA18)*MOD(COLUMN($P$14:$Z$14)-COLUMN($P$14)+1,2))) -> 27 | AD18: =SUMIF($E$14:$N$14,"CO3",E18:N18)+IF(O18>=0, SUMPRODUCT(($O$14:$Z$14="CO3")*(O18:Z18)*MOD(COLUMN($O$14:$Z$14)-COLUMN($O$14)+1,2))+ SUMPRODUCT(($P$14:$Z$14="CO3")*(P18:Z18)*MOD(COLUMN($P$14:$Z$14)-COLUMN($P$14)+1,2))) -> 16 | AE18: =SUMIF($E$14:$N$14,"CO4",$E$17:$N$17) + IF(O18>=0, SUMPRODUCT(($O$14:$Z$14="CO4")*(O18:Z18)*MOD(COLUMN($O$14:$Z$14)-COLUMN($O$14)+1,2))+ SUMPRODUCT(($P$14:$Z$14="CO4")*(P18:Z18)*MOD(COLUMN($P$14:$Z$14)-COLUMN($P$14)+1,2))) -> 0 | AF18: =SUMIF($E$14:$N$14,"CO5",$E$17:$N$17) + IF(O18>=0, SUMPRODUCT(($O$14:$Z$14="CO5")*(O18:Z18)*MOD(COLUMN($O$14:$Z$14)-COLUMN($O$14)+1,2))+ SUMPRODUCT(($P$14:$Z$14="CO5")*(P18:Z18)*MOD(COLUMN($P$14:$Z$14)-COLUMN($P$14)+1,2)) ) -> 0 | AG18: =SUMIF($E$14:$N$14,"CO6",$E$17:$N$17) + IF(O18>0, SUMPRODUCT(($O$14:$Z$14="CO6")*($O$17:$Z$17)*MOD(COLUMN($O$14:$Z$14)-COLUMN($O$14)+1,2))+ SUMPRODUCT(($P$14:$Z$14="CO6")*($P$17:$Z$17)*MOD(COLUMN($P$14:$Z$14)-COLUMN($P$14)+1,2)) ) -> 0 | AH18: =SUM(AB18:AG18) -> 72 | AI18: =AB18/(SUMIF($E$14:$N$14,"CO1",$E$13:$N$13)+SUMPRODUCT(($O$14:$Z$14="CO1")*($O18:$Z18>0)*($O$13:$Z$13)))*100 -> 72.5 | AJ18: =AC18/(SUMIF($E$14:$N$14,"CO2",$E$13:$N$13)+SUMPRODUCT(($O$14:$Z$14="CO2")*($O18:$Z18>0)*($O$13:$Z$13)))*100 -> 67.5 | AK18: =AD18/(SUMIF($E$14:$N$14,"CO3",$E$13:$N$13)+SUMPRODUCT(($O$14:$Z$14="CO3")*($O18:$Z18>0)*($O$13:$Z$13)))*100 -> 80
A19: 3 | B19: ='STUDENT NAMELIST'!B7 -> 211423243006 | C19: ='STUDENT NAMELIST'!C7 -> 2023PEC AI 103 | D19: ='STUDENT NAMELIST'!D7 -> ABIRAMI G | E19: 0 | F19: 0 | G19: 1 | H19: 2 | I19: 0 | J19: 2 | K19: 2 | L19: 0 | M19: 0 | N19: 1 | O19: 0 | P19: 0 | Q19: 0 | R19: 14 | S19: 13 | T19: 0 | U19: 14 | V19: 0 | W19: 0 | X19: 8 | AA19: =SUM(E19,F19,G19,H19,I19,J19,K19,L19,M19,N19,O19,P19,Q19,R19,S19,T19,U19,V19,W19,X19,Y19,Z19) -> 57 | AB19: =SUMIF($E$14:$N$14,"CO1",E19:N19)+IF(O19>=0,SUMPRODUCT(($O$14:$Z$14="CO1")*(O19:Z19)*MOD(COLUMN($O$14:$Z$14)-COLUMN($O$14)+1,2))+SUMPRODUCT(($P$14:$Z$14="CO1")*(P19:Z19)*MOD(COLUMN($P$14:$Z$14)-COLUMN($P$14)+1,2))) -> 17 | AC19: =SUMIF($E$14:$N$14,"CO1",F19:O19)+IF(P19>=0,SUMPRODUCT(($O$14:$Z$14="CO1")*(P19:AA19)*MOD(COLUMN($O$14:$Z$14)-COLUMN($O$14)+1,2))+SUMPRODUCT(($P$14:$Z$14="CO1")*(Q19:AA19)*MOD(COLUMN($P$14:$Z$14)-COLUMN($P$14)+1,2))) -> 30 | AD19: =SUMIF($E$14:$N$14,"CO3",E19:N19)+IF(O19>=0, SUMPRODUCT(($O$14:$Z$14="CO3")*(O19:Z19)*MOD(COLUMN($O$14:$Z$14)-COLUMN($O$14)+1,2))+ SUMPRODUCT(($P$14:$Z$14="CO3")*(P19:Z19)*MOD(COLUMN($P$14:$Z$14)-COLUMN($P$14)+1,2))) -> 9 | AE19: =SUMIF($E$14:$N$14,"CO4",$E$17:$N$17) + IF(O19>=0, SUMPRODUCT(($O$14:$Z$14="CO4")*(O19:Z19)*MOD(COLUMN($O$14:$Z$14)-COLUMN($O$14)+1,2))+ SUMPRODUCT(($P$14:$Z$14="CO4")*(P19:Z19)*MOD(COLUMN($P$14:$Z$14)-COLUMN($P$14)+1,2))) -> 0 | AF19: =SUMIF($E$14:$N$14,"CO5",$E$17:$N$17) + IF(O19>=0, SUMPRODUCT(($O$14:$Z$14="CO5")*(O19:Z19)*MOD(COLUMN($O$14:$Z$14)-COLUMN($O$14)+1,2))+ SUMPRODUCT(($P$14:$Z$14="CO5")*(P19:Z19)*MOD(COLUMN($P$14:$Z$14)-COLUMN($P$14)+1,2)) ) -> 0 | AG19: =SUMIF($E$14:$N$14,"CO6",$E$17:$N$17) + IF(O19>0, SUMPRODUCT(($O$14:$Z$14="CO6")*($O$17:$Z$17)*MOD(COLUMN($O$14:$Z$14)-COLUMN($O$14)+1,2))+ SUMPRODUCT(($P$14:$Z$14="CO6")*($P$17:$Z$17)*MOD(COLUMN($P$14:$Z$14)-COLUMN($P$14)+1,2)) ) -> 0 | AH19: =SUM(AB19:AG19) -> 56 | AI19: =AB19/(SUMIF($E$14:$N$14,"CO1",$E$13:$N$13)+SUMPRODUCT(($O$14:$Z$14="CO1")*($O19:$Z19>0)*($O$13:$Z$13)))*100 -> 70.833333 | AJ19: =AC19/(SUMIF($E$14:$N$14,"CO2",$E$13:$N$13)+SUMPRODUCT(($O$14:$Z$14="CO2")*($O19:$Z19>0)*($O$13:$Z$13)))*100 -> 75 | AK19: =AD19/(SUMIF($E$14:$N$14,"CO3",$E$13:$N$13)+SUMPRODUCT(($O$14:$Z$14="CO3")*($O19:$Z19>0)*($O$13:$Z$13)))*100 -> 45
A20: 4 | B20: ='STUDENT NAMELIST'!B8 -> 211423243009 | C20: ='STUDENT NAMELIST'!C8 -> 2023PEC AI 104 | D20: ='STUDENT NAMELIST'!D8 -> ABITHA R D | E20: 2 | F20: 0 | G20: 0 | H20: 2 | I20: 0 | J20: 0 | K20: 2 | L20: 2 | M20: 1 | N20: 1 | O20: 0 | P20: 11 | Q20: 12 | R20: 0 | S20: 0 | T20: 16 | U20: 0 | V20: 12 | W20: 14 | X20: 0 | AA20: =SUM(E20,F20,G20,H20,I20,J20,K20,L20,M20,N20,O20,P20,Q20,R20,S20,T20,U20,V20,W20,X20,Y20,Z20) -> 75 | AB20: =SUMIF($E$14:$N$14,"CO1",E20:N20)+IF(O20>=0,SUMPRODUCT(($O$14:$Z$14="CO1")*(O20:Z20)*MOD(COLUMN($O$14:$Z$14)-COLUMN($O$14)+1,2))+SUMPRODUCT(($P$14:$Z$14="CO1")*(P20:Z20)*MOD(COLUMN($P$14:$Z$14)-COLUMN($P$14)+1,2))) -> 27 | AC20: =SUMIF($E$14:$N$14,"CO1",F20:O20)+IF(P20>=0,SUMPRODUCT(($O$14:$Z$14="CO1")*(P20:AA20)*MOD(COLUMN($O$14:$Z$14)-COLUMN($O$14)+1,2))+SUMPRODUCT(($P$14:$Z$14="CO1")*(Q20:AA20)*MOD(COLUMN($P$14:$Z$14)-COLUMN($P$14)+1,2))) -> 25 | AD20: =SUMIF($E$14:$N$14,"CO3",E20:N20)+IF(O20>=0, SUMPRODUCT(($O$14:$Z$14="CO3")*(O20:Z20)*MOD(COLUMN($O$14:$Z$14)-COLUMN($O$14)+1,2))+ SUMPRODUCT(($P$14:$Z$14="CO3")*(P20:Z20)*MOD(COLUMN($P$14:$Z$14)-COLUMN($P$14)+1,2))) -> 16 | AE20: =SUMIF($E$14:$N$14,"CO4",$E$17:$N$17) + IF(O20>=0, SUMPRODUCT(($O$14:$Z$14="CO4")*(O20:Z20)*MOD(COLUMN($O$14:$Z$14)-COLUMN($O$14)+1,2))+ SUMPRODUCT(($P$14:$Z$14="CO4")*(P20:Z20)*MOD(COLUMN($P$14:$Z$14)-COLUMN($P$14)+1,2))) -> 0 | AF20: =SUMIF($E$14:$N$14,"CO5",$E$17:$N$17) + IF(O20>=0, SUMPRODUCT(($O$14:$Z$14="CO5")*(O20:Z20)*MOD(COLUMN($O$14:$Z$14)-COLUMN($O$14)+1,2))+ SUMPRODUCT(($P$14:$Z$14="CO5")*(P20:Z20)*MOD(COLUMN($P$14:$Z$14)-COLUMN($P$14)+1,2)) ) -> 0 | AG20: =SUMIF($E$14:$N$14,"CO6",$E$17:$N$17) + IF(O20>0, SUMPRODUCT(($O$14:$Z$14="CO6")*($O$17:$Z$17)*MOD(COLUMN($O$14:$Z$14)-COLUMN($O$14)+1,2))+ SUMPRODUCT(($P$14:$Z$14="CO6")*($P$17:$Z$17)*MOD(COLUMN($P$14:$Z$14)-COLUMN($P$14)+1,2)) ) -> 0 | AH20: =SUM(AB20:AG20) -> 68 | AI20: =AB20/(SUMIF($E$14:$N$14,"CO1",$E$13:$N$13)+SUMPRODUCT(($O$14:$Z$14="CO1")*($O20:$Z20>0)*($O$13:$Z$13)))*100 -> 67.5 | AJ20: =AC20/(SUMIF($E$14:$N$14,"CO2",$E$13:$N$13)+SUMPRODUCT(($O$14:$Z$14="CO2")*($O20:$Z20>0)*($O$13:$Z$13)))*100 -> 62.5 | AK20: =AD20/(SUMIF($E$14:$N$14,"CO3",$E$13:$N$13)+SUMPRODUCT(($O$14:$Z$14="CO3")*($O20:$Z20>0)*($O$13:$Z$13)))*100 -> 80
A21: 5 | B21: ='STUDENT NAMELIST'!B9 -> 211423243011 | C21: ='STUDENT NAMELIST'!C9 -> 2023PEC AI 105 | D21: ='STUDENT NAMELIST'!D9 -> ADELINE JERUSHA AUGUSTINE | E21: 2 | F21: 2 | G21: 0 | H21: 1 | I21: 1 | J21: 2 | K21: 2 | L21: 1 | M21: 0 | N21: 1 | O21: 9 | P21: 0 | Q21: 0 | R21: 16 | S21: 14 | T21: 0 | U21: 16 | V21: 0 | W21: 0 | X21: 13 | AA21: =SUM(E21,F21,G21,H21,I21,J21,K21,L21,M21,N21,O21,P21,Q21,R21,S21,T21,U21,V21,W21,X21,Y21,Z21) -> 80 | AB21: =SUMIF($E$14:$N$14,"CO1",E21:N21)+IF(O21>=0,SUMPRODUCT(($O$14:$Z$14="CO1")*(O21:Z21)*MOD(COLUMN($O$14:$Z$14)-COLUMN($O$14)+1,2))+SUMPRODUCT(($P$14:$Z$14="CO1")*(P21:Z21)*MOD(COLUMN($P$14:$Z$14)-COLUMN($P$14)+1,2))) -> 30 | AC21: =SUMIF($E$14:$N$14,"CO1",F21:O21)+IF(P21>=0,SUMPRODUCT(($O$14:$Z$14="CO1")*(P21:AA21)*MOD(COLUMN($O$14:$Z$14)-COLUMN($O$14)+1,2))+SUMPRODUCT(($P$14:$Z$14="CO1")*(Q21:AA21)*MOD(COLUMN($P$14:$Z$14)-COLUMN($P$14)+1,2))) -> 34 | AD21: =SUMIF($E$14:$N$14,"CO3",E21:N21)+IF(O21>=0, SUMPRODUCT(($O$14:$Z$14="CO3")*(O21:Z21)*MOD(COLUMN($O$14:$Z$14)-COLUMN($O$14)+1,2))+ SUMPRODUCT(($P$14:$Z$14="CO3")*(P21:Z21)*MOD(COLUMN($P$14:$Z$14)-COLUMN($P$14)+1,2))) -> 14 | AE21: =SUMIF($E$14:$N$14,"CO4",$E$17:$N$17) + IF(O21>=0, SUMPRODUCT(($O$14:$Z$14="CO4")*(O21:Z21)*MOD(COLUMN($O$14:$Z$14)-COLUMN($O$14)+1,2))+ SUMPRODUCT(($P$14:$Z$14="CO4")*(P21:Z21)*MOD(COLUMN($P$14:$Z$14)-COLUMN($P$14)+1,2))) -> 0 | AF21: =SUMIF($E$14:$N$14,"CO5",$E$17:$N$17) + IF(O21>=0, SUMPRODUCT(($O$14:$Z$14="CO5")*(O21:Z21)*MOD(COLUMN($O$14:$Z$14)-COLUMN($O$14)+1,2))+ SUMPRODUCT(($P$14:$Z$14="CO5")*(P21:Z21)*MOD(COLUMN($P$14:$Z$14)-COLUMN($P$14)+1,2)) ) -> 0 | AG21: =SUMIF($E$14:$N$14,"CO6",$E$17:$N$17) + IF(O21>0, SUMPRODUCT(($O$14:$Z$14="CO6")*($O$17:$Z$17)*MOD(COLUMN($O$14:$Z$14)-COLUMN($O$14)+1,2))+ SUMPRODUCT(($P$14:$Z$14="CO6")*($P$17:$Z$17)*MOD(COLUMN($P$14:$Z$14)-COLUMN($P$14)+1,2)) ) -> 0 | AH21: =SUM(AB21:AG21) -> 78 | AI21: =AB21/(SUMIF($E$14:$N$14,"CO1",$E$13:$N$13)+SUMPRODUCT(($O$14:$Z$14="CO1")*($O21:$Z21>0)*($O$13:$Z$13)))*100 -> 75 | AJ21: =AC21/(SUMIF($E$14:$N$14,"CO2",$E$13:$N$13)+SUMPRODUCT(($O$14:$Z$14="CO2")*($O21:$Z21>0)*($O$13:$Z$13)))*100 -> 85 | AK21: =AD21/(SUMIF($E$14:$N$14,"CO3",$E$13:$N$13)+SUMPRODUCT(($O$14:$Z$14="CO3")*($O21:$Z21>0)*($O$13:$Z$13)))*100 -> 70
A22: 6 | B22: ='STUDENT NAMELIST'!B10 -> 211423243014 | C22: ='STUDENT NAMELIST'!C10 -> 2023PEC AI 106 | D22: ='STUDENT NAMELIST'!D10 -> AFIFA FATHIMA S | E22: 0 | F22: 1 | G22: 0 | H22: 0 | I22: 2 | J22: 1 | K22: 1 | L22: 1 | M22: 2 | N22: 2 | O22: 0 | P22: 10 | Q22: 16 | R22: 0 | S22: 0 | T22: 10 | U22: 0 | V22: 16 | W22: 15 | X22: 0 | AA22: =SUM(E22,F22,G22,H22,I22,J22,K22,L22,M22,N22,O22,P22,Q22,R22,S22,T22,U22,V22,W22,X22,Y22,Z22) -> 77 | AB22: =SUMIF($E$14:$N$14,"CO1",E22:N22)+IF(O22>=0,SUMPRODUCT(($O$14:$Z$14="CO1")*(O22:Z22)*MOD(COLUMN($O$14:$Z$14)-COLUMN($O$14)+1,2))+SUMPRODUCT(($P$14:$Z$14="CO1")*(P22:Z22)*MOD(COLUMN($P$14:$Z$14)-COLUMN($P$14)+1,2))) -> 27 | AC22: =SUMIF($E$14:$N$14,"CO1",F22:O22)+IF(P22>=0,SUMPRODUCT(($O$14:$Z$14="CO1")*(P22:AA22)*MOD(COLUMN($O$14:$Z$14)-COLUMN($O$14)+1,2))+SUMPRODUCT(($P$14:$Z$14="CO1")*(Q22:AA22)*MOD(COLUMN($P$14:$Z$14)-COLUMN($P$14)+1,2))) -> 29 | AD22: =SUMIF($E$14:$N$14,"CO3",E22:N22)+IF(O22>=0, SUMPRODUCT(($O$14:$Z$14="CO3")*(O22:Z22)*MOD(COLUMN($O$14:$Z$14)-COLUMN($O$14)+1,2))+ SUMPRODUCT(($P$14:$Z$14="CO3")*(P22:Z22)*MOD(COLUMN($P$14:$Z$14)-COLUMN($P$14)+1,2))) -> 19 | AE22: =SUMIF($E$14:$N$14,"CO4",$E$17:$N$17) + IF(O22>=0, SUMPRODUCT(($O$14:$Z$14="CO4")*(O22:Z22)*MOD(COLUMN($O$14:$Z$14)-COLUMN($O$14)+1,2))+ SUMPRODUCT(($P$14:$Z$14="CO4")*(P22:Z22)*MOD(COLUMN($P$14:$Z$14)-COLUMN($P$14)+1,2))) -> 0 | AF22: =SUMIF($E$14:$N$14,"CO5",$E$17:$N$17) + IF(O22>=0, SUMPRODUCT(($O$14:$Z$14="CO5")*(O22:Z22)*MOD(COLUMN($O$14:$Z$14)-COLUMN($O$14)+1,2))+ SUMPRODUCT(($P$14:$Z$14="CO5")*(P22:Z22)*MOD(COLUMN($P$14:$Z$14)-COLUMN($P$14)+1,2)) ) -> 0 | AG22: =SUMIF($E$14:$N$14,"CO6",$E$17:$N$17) + IF(O22>0, SUMPRODUCT(($O$14:$Z$14="CO6")*($O$17:$Z$17)*MOD(COLUMN($O$14:$Z$14)-COLUMN($O$14)+1,2))+ SUMPRODUCT(($P$14:$Z$14="CO6")*($P$17:$Z$17)*MOD(COLUMN($P$14:$Z$14)-COLUMN($P$14)+1,2)) ) -> 0 | AH22: =SUM(AB22:AG22) -> 75 | AI22: =AB22/(SUMIF($E$14:$N$14,"CO1",$E$13:$N$13)+SUMPRODUCT(($O$14:$Z$14="CO1")*($O22:$Z22>0)*($O$13:$Z$13)))*100 -> 67.5 | AJ22: =AC22/(SUMIF($E$14:$N$14,"CO2",$E$13:$N$13)+SUMPRODUCT(($O$14:$Z$14="CO2")*($O22:$Z22>0)*($O$13:$Z$13)))*100 -> 72.5 | AK22: =AD22/(SUMIF($E$14:$N$14,"CO3",$E$13:$N$13)+SUMPRODUCT(($O$14:$Z$14="CO3")*($O22:$Z22>0)*($O$13:$Z$13)))*100 -> 95
A23: 8 | B23: ='STUDENT NAMELIST'!B11 -> 211423243016 | C23: ='STUDENT NAMELIST'!C11 -> 2023PEC AI 107 | D23: ='STUDENT NAMELIST'!D11 -> AFSHAN TAJ F | E23: 1 | F23: 0 | G23: 1 | H23: 2 | I23: 1 | J23: 2 | K23: 1 | L23: 2 | M23: 0 | N23: 1 | O23: 12 | P23: 0 | Q23: 0 | R23: 16 | S23: 14 | T23: 0 | U23: 16 | V23: 0 | W23: 0 | X23: 13 | AA23: =SUM(E23,F23,G23,H23,I23,J23,K23,L23,M23,N23,O23,P23,Q23,R23,S23,T23,U23,V23,W23,X23,Y23,Z23) -> 82 | AB23: =SUMIF($E$14:$N$14,"CO1",E23:N23)+IF(O23>=0,SUMPRODUCT(($O$14:$Z$14="CO1")*(O23:Z23)*MOD(COLUMN($O$14:$Z$14)-COLUMN($O$14)+1,2))+SUMPRODUCT(($P$14:$Z$14="CO1")*(P23:Z23)*MOD(COLUMN($P$14:$Z$14)-COLUMN($P$14)+1,2))) -> 32 | AC23: =SUMIF($E$14:$N$14,"CO1",F23:O23)+IF(P23>=0,SUMPRODUCT(($O$14:$Z$14="CO1")*(P23:AA23)*MOD(COLUMN($O$14:$Z$14)-COLUMN($O$14)+1,2))+SUMPRODUCT(($P$14:$Z$14="CO1")*(Q23:AA23)*MOD(COLUMN($P$14:$Z$14)-COLUMN($P$14)+1,2))) -> 34 | AD23: =SUMIF($E$14:$N$14,"CO3",E23:N23)+IF(O23>=0, SUMPRODUCT(($O$14:$Z$14="CO3")*(O23:Z23)*MOD(COLUMN($O$14:$Z$14)-COLUMN($O$14)+1,2))+ SUMPRODUCT(($P$14:$Z$14="CO3")*(P23:Z23)*MOD(COLUMN($P$14:$Z$14)-COLUMN($P$14)+1,2))) -> 14 | AE23: =SUMIF($E$14:$N$14,"CO4",$E$17:$N$17) + IF(O23>=0, SUMPRODUCT(($O$14:$Z$14="CO4")*(O23:Z23)*MOD(COLUMN($O$14:$Z$14)-COLUMN($O$14)+1,2))+ SUMPRODUCT(($P$14:$Z$14="CO4")*(P23:Z23)*MOD(COLUMN($P$14:$Z$14)-COLUMN($P$14)+1,2))) -> 0 | AF23: =SUMIF($E$14:$N$14,"CO5",$E$17:$N$17) + IF(O23>=0, SUMPRODUCT(($O$14:$Z$14="CO5")*(O23:Z23)*MOD(COLUMN($O$14:$Z$14)-COLUMN($O$14)+1,2))+ SUMPRODUCT(($P$14:$Z$14="CO5")*(P23:Z23)*MOD(COLUMN($P$14:$Z$14)-COLUMN($P$14)+1,2)) ) -> 0 | AG23: =SUMIF($E$14:$N$14,"CO6",$E$17:$N$17) + IF(O23>0, SUMPRODUCT(($O$14:$Z$14="CO6")*($O$17:$Z$17)*MOD(COLUMN($O$14:$Z$14)-COLUMN($O$14)+1,2))+ SUMPRODUCT(($P$14:$Z$14="CO6")*($P$17:$Z$17)*MOD(COLUMN($P$14:$Z$14)-COLUMN($P$14)+1,2)) ) -> 0 | AH23: =SUM(AB23:AG23) -> 80 | AI23: =AB23/(SUMIF($E$14:$N$14,"CO1",$E$13:$N$13)+SUMPRODUCT(($O$14:$Z$14="CO1")*($O23:$Z23>0)*($O$13:$Z$13)))*100 -> 80 | AJ23: =AC23/(SUMIF($E$14:$N$14,"CO2",$E$13:$N$13)+SUMPRODUCT(($O$14:$Z$14="CO2")*($O23:$Z23>0)*($O$13:$Z$13)))*100 -> 85 | AK23: =AD23/(SUMIF($E$14:$N$14,"CO3",$E$13:$N$13)+SUMPRODUCT(($O$14:$Z$14="CO3")*($O23:$Z23>0)*($O$13:$Z$13)))*100 -> 70
A24: 8 | B24: ='STUDENT NAMELIST'!B12 -> 211423243017 | C24: ='STUDENT NAMELIST'!C12 -> 2023PEC AI 108 | D24: ='STUDENT NAMELIST'!D12 -> AISHWARYA P | E24: 2 | F24: 0 | G24: 2 | H24: 2 | I24: 1 | J24: 1 | K24: 2 | L24: 1 | M24: 0 | N24: 2 | O24: 0 | P24: 10 | Q24: 16 | R24: 0 | S24: 0 | T24: 10 | U24: 0 | V24: 16 | W24: 15 | X24: 0 | AA24: =SUM(E24,F24,G24,H24,I24,J24,K24,L24,M24,N24,O24,P24,Q24,R24,S24,T24,U24,V24,W24,X24,Y24,Z24) -> 80 | AB24: =SUMIF($E$14:$N$14,"CO1",E24:N24)+IF(O24>=0,SUMPRODUCT(($O$14:$Z$14="CO1")*(O24:Z24)*MOD(COLUMN($O$14:$Z$14)-COLUMN($O$14)+1,2))+SUMPRODUCT(($P$14:$Z$14="CO1")*(P24:Z24)*MOD(COLUMN($P$14:$Z$14)-COLUMN($P$14)+1,2))) -> 32 | AC24: =SUMIF($E$14:$N$14,"CO1",F24:O24)+IF(P24>=0,SUMPRODUCT(($O$14:$Z$14="CO1")*(P24:AA24)*MOD(COLUMN($O$14:$Z$14)-COLUMN($O$14)+1,2))+SUMPRODUCT(($P$14:$Z$14="CO1")*(Q24:AA24)*MOD(COLUMN($P$14:$Z$14)-COLUMN($P$14)+1,2))) -> 31 | AD24: =SUMIF($E$14:$N$14,"CO3",E24:N24)+IF(O24>=0, SUMPRODUCT(($O$14:$Z$14="CO3")*(O24:Z24)*MOD(COLUMN($O$14:$Z$14)-COLUMN($O$14)+1,2))+ SUMPRODUCT(($P$14:$Z$14="CO3")*(P24:Z24)*MOD(COLUMN($P$14:$Z$14)-COLUMN($P$14)+1,2))) -> 17 | AE24: =SUMIF($E$14:$N$14,"CO4",$E$17:$N$17) + IF(O24>=0, SUMPRODUCT(($O$14:$Z$14="CO4")*(O24:Z24)*MOD(COLUMN($O$14:$Z$14)-COLUMN($O$14)+1,2))+ SUMPRODUCT(($P$14:$Z$14="CO4")*(P24:Z24)*MOD(COLUMN($P$14:$Z$14)-COLUMN($P$14)+1,2))) -> 0 | AF24: 0 | AG24: =SUMIF($E$14:$N$14,"CO6",$E$17:$N$17) + IF(O24>0, SUMPRODUCT(($O$14:$Z$14="CO6")*($O$17:$Z$17)*MOD(COLUMN($O$14:$Z$14)-COLUMN($O$14)+1,2))+ SUMPRODUCT(($P$14:$Z$14="CO6")*($P$17:$Z$17)*MOD(COLUMN($P$14:$Z$14)-COLUMN($P$14)+1,2)) ) -> 0 | AH24: =SUM(AB24:AG24) -> 80 | AI24: =AB24/(SUMIF($E$14:$N$14,"CO1",$E$13:$N$13)+SUMPRODUCT(($O$14:$Z$14="CO1")*($O24:$Z24>0)*($O$13:$Z$13)))*100 -> 80 | AJ24: =AC24/(SUMIF($E$14:$N$14,"CO2",$E$13:$N$13)+SUMPRODUCT(($O$14:$Z$14="CO2")*($O24:$Z24>0)*($O$13:$Z$13)))*100 -> 77.5 | AK24: =AD24/(SUMIF($E$14:$N$14,"CO3",$E$13:$N$13)+SUMPRODUCT(($O$14:$Z$14="CO3")*($O24:$Z24>0)*($O$13:$Z$13)))*100 -> 85
A25: 9 | B25: ='STUDENT NAMELIST'!B13 -> 211423243022 | C25: ='STUDENT NAMELIST'!C13 -> 2023PEC AI 109 | D25: ='STUDENT NAMELIST'!D13 -> AKSHAYA SAKTHI G | E25: 1 | F25: 1 | G25: 1 | H25: 2 | I25: 0 | J25: 1 | K25: 1 | L25: 2 | M25: 0 | N25: 0 | O25: 13 | P25: 0 | Q25: 0 | R25: 16 | S25: 14 | T25: 0 | U25: 16 | V25: 0 | W25: 0 | X25: 13 | AA25: =SUM(E25,F25,G25,H25,I25,J25,K25,L25,M25,N25,O25,P25,Q25,R25,S25,T25,U25,V25,W25,X25,Y25,Z25) -> 81 | AB25: =SUMIF($E$14:$N$14,"CO1",E25:N25)+IF(O25>=0,SUMPRODUCT(($O$14:$Z$14="CO1")*(O25:Z25)*MOD(COLUMN($O$14:$Z$14)-COLUMN($O$14)+1,2))+SUMPRODUCT(($P$14:$Z$14="CO1")*(P25:Z25)*MOD(COLUMN($P$14:$Z$14)-COLUMN($P$14)+1,2))) -> 34 | AC25: =SUMIF($E$14:$N$14,"CO1",F25:O25)+IF(P25>=0,SUMPRODUCT(($O$14:$Z$14="CO1")*(P25:AA25)*MOD(COLUMN($O$14:$Z$14)-COLUMN($O$14)+1,2))+SUMPRODUCT(($P$14:$Z$14="CO1")*(Q25:AA25)*MOD(COLUMN($P$14:$Z$14)-COLUMN($P$14)+1,2))) -> 34 | AD25: =SUMIF($E$14:$N$14,"CO3",E25:N25)+IF(O25>=0, SUMPRODUCT(($O$14:$Z$14="CO3")*(O25:Z25)*MOD(COLUMN($O$14:$Z$14)-COLUMN($O$14)+1,2))+ SUMPRODUCT(($P$14:$Z$14="CO3")*(P25:Z25)*MOD(COLUMN($P$14:$Z$14)-COLUMN($P$14)+1,2))) -> 13 | AE25: =SUMIF($E$14:$N$14,"CO4",$E$17:$N$17) + IF(O25>=0, SUMPRODUCT(($O$14:$Z$14="CO4")*(O25:Z25)*MOD(COLUMN($O$14:$Z$14)-COLUMN($O$14)+1,2))+ SUMPRODUCT(($P$14:$Z$14="CO4")*(P25:Z25)*MOD(COLUMN($P$14:$Z$14)-COLUMN($P$14)+1,2))) -> 0 | AF25: =SUMIF($E$14:$N$14,"CO5",$E$17:$N$17) + IF(O25>=0, SUMPRODUCT(($O$14:$Z$14="CO5")*(O25:Z25)*MOD(COLUMN($O$14:$Z$14)-COLUMN($O$14)+1,2))+ SUMPRODUCT(($P$14:$Z$14="CO5")*(P25:Z25)*MOD(COLUMN($P$14:$Z$14)-COLUMN($P$14)+1,2)) ) -> 0 | AG25: =SUMIF($E$14:$N$14,"CO6",$E$17:$N$17) + IF(O25>0, SUMPRODUCT(($O$14:$Z$14="CO6")*($O$17:$Z$17)*MOD(COLUMN($O$14:$Z$14)-COLUMN($O$14)+1,2))+ SUMPRODUCT(($P$14:$Z$14="CO6")*($P$17:$Z$17)*MOD(COLUMN($P$14:$Z$14)-COLUMN($P$14)+1,2)) ) -> 0 | AH25: =SUM(AB25:AG25) -> 81 | AI25: =AB25/(SUMIF($E$14:$N$14,"CO1",$E$13:$N$13)+SUMPRODUCT(($O$14:$Z$14="CO1")*($O25:$Z25>0)*($O$13:$Z$13)))*100 -> 85 | AJ25: =AC25/(SUMIF($E$14:$N$14,"CO2",$E$13:$N$13)+SUMPRODUCT(($O$14:$Z$14="CO2")*($O25:$Z25>0)*($O$13:$Z$13)))*100 -> 85 | AK25: =AD25/(SUMIF($E$14:$N$14,"CO3",$E$13:$N$13)+SUMPRODUCT(($O$14:$Z$14="CO3")*($O25:$Z25>0)*($O$13:$Z$13)))*100 -> 65
A26: 10 | B26: ='STUDENT NAMELIST'!B14 -> 211423243025 | C26: ='STUDENT NAMELIST'!C14 -> 2023PEC AI 110 | D26: ='STUDENT NAMELIST'!D14 -> AMIRTHA A | E26: 0 | F26: 2 | G26: 0 | H26: 0 | I26: 2 | J26: 1 | K26: 1 | L26: 1 | M26: 1 | N26: 1 | P26: 11 | R26: 14 | T26: 14 | V26: 16 | W26: 14 | AA26: =SUM(E26,F26,G26,H26,I26,J26,K26,L26,M26,N26,O26,P26,Q26,R26,S26,T26,U26,V26,W26,X26,Y26,Z26) -> 78 | AB26: =SUMIF($E$14:$N$14,"CO1",E26:N26)+IF(O26>=0,SUMPRODUCT(($O$14:$Z$14="CO1")*(O26:Z26)*MOD(COLUMN($O$14:$Z$14)-COLUMN($O$14)+1,2))+SUMPRODUCT(($P$14:$Z$14="CO1")*(P26:Z26)*MOD(COLUMN($P$14:$Z$14)-COLUMN($P$14)+1,2))) -> 27 | AC26: =SUMIF($E$14:$N$14,"CO1",F26:O26)+IF(P26>=0,SUMPRODUCT(($O$14:$Z$14="CO1")*(P26:AA26)*MOD(COLUMN($O$14:$Z$14)-COLUMN($O$14)+1,2))+SUMPRODUCT(($P$14:$Z$14="CO1")*(Q26:AA26)*MOD(COLUMN($P$14:$Z$14)-COLUMN($P$14)+1,2))) -> 29 | AD26: =SUMIF($E$14:$N$14,"CO3",E26:N26)+IF(O26>=0, SUMPRODUCT(($O$14:$Z$14="CO3")*(O26:Z26)*MOD(COLUMN($O$14:$Z$14)-COLUMN($O$14)+1,2))+ SUMPRODUCT(($P$14:$Z$14="CO3")*(P26:Z26)*MOD(COLUMN($P$14:$Z$14)-COLUMN($P$14)+1,2))) -> 16 | AE26: =SUMIF($E$14:$N$14,"CO4",$E$17:$N$17) + IF(O26>=0, SUMPRODUCT(($O$14:$Z$14="CO4")*(O26:Z26)*MOD(COLUMN($O$14:$Z$14)-COLUMN($O$14)+1,2))+ SUMPRODUCT(($P$14:$Z$14="CO4")*(P26:Z26)*MOD(COLUMN($P$14:$Z$14)-COLUMN($P$14)+1,2))) -> 0 | AF26: =SUMIF($E$14:$N$14,"CO5",$E$17:$N$17) + IF(O26>=0, SUMPRODUCT(($O$14:$Z$14="CO5")*(O26:Z26)*MOD(COLUMN($O$14:$Z$14)-COLUMN($O$14)+1,2))+ SUMPRODUCT(($P$14:$Z$14="CO5")*(P26:Z26)*MOD(COLUMN($P$14:$Z$14)-COLUMN($P$14)+1,2)) ) -> 0 | AG26: =SUMIF($E$14:$N$14,"CO6",$E$17:$N$17) + IF(O26>0, SUMPRODUCT(($O$14:$Z$14="CO6")*($O$17:$Z$17)*MOD(COLUMN($O$14:$Z$14)-COLUMN($O$14)+1,2))+ SUMPRODUCT(($P$14:$Z$14="CO6")*($P$17:$Z$17)*MOD(COLUMN($P$14:$Z$14)-COLUMN($P$14)+1,2)) ) -> 0 | AH26: =SUM(AB26:AG26) -> 72 | AI26: =AB26/(SUMIF($E$14:$N$14,"CO1",$E$13:$N$13)+SUMPRODUCT(($O$14:$Z$14="CO1")*($O26:$Z26>0)*($O$13:$Z$13)))*100 -> 67.5 | AJ26: =AC26/(SUMIF($E$14:$N$14,"CO2",$E$13:$N$13)+SUMPRODUCT(($O$14:$Z$14="CO2")*($O26:$Z26>0)*($O$13:$Z$13)))*100 -> 72.5 | AK26: =AD26/(SUMIF($E$14:$N$14,"CO3",$E$13:$N$13)+SUMPRODUCT(($O$14:$Z$14="CO3")*($O26:$Z26>0)*($O$13:$Z$13)))*100 -> 80
A27: 13 | B27: ='STUDENT NAMELIST'!B15 -> 211423243033 | C27: ='STUDENT NAMELIST'!C15 -> 2023PEC AI 111 | D27: ='STUDENT NAMELIST'!D15 -> ANTONY AMALA TRINITA J | E27: 1 | F27: 1 | G27: 0 | H27: 1 | I27: 2 | J27: 0 | K27: 1 | L27: 2 | M27: 1 | N27: 2 | O27: 15 | Q27: 14 | T27: 16 | V27: 16 | X27: 16 | AA27: =SUM(E27,F27,G27,H27,I27,J27,K27,L27,M27,N27,O27,P27,Q27,R27,S27,T27,U27,V27,W27,X27,Y27,Z27) -> 88 | AB27: =SUMIF($E$14:$N$14,"CO1",E27:N27)+IF(O27>=0,SUMPRODUCT(($O$14:$Z$14="CO1")*(O27:Z27)*MOD(COLUMN($O$14:$Z$14)-COLUMN($O$14)+1,2))+SUMPRODUCT(($P$14:$Z$14="CO1")*(P27:Z27)*MOD(COLUMN($P$14:$Z$14)-COLUMN($P$14)+1,2))) -> 32 | AC27: =SUMIF($E$14:$N$14,"CO1",F27:O27)+IF(P27>=0,SUMPRODUCT(($O$14:$Z$14="CO1")*(P27:AA27)*MOD(COLUMN($O$14:$Z$14)-COLUMN($O$14)+1,2))+SUMPRODUCT(($P$14:$Z$14="CO1")*(Q27:AA27)*MOD(COLUMN($P$14:$Z$14)-COLUMN($P$14)+1,2))) -> 18 | AD27: =SUMIF($E$14:$N$14,"CO3",E27:N27)+IF(O27>=0, SUMPRODUCT(($O$14:$Z$14="CO3")*(O27:Z27)*MOD(COLUMN($O$14:$Z$14)-COLUMN($O$14)+1,2))+ SUMPRODUCT(($P$14:$Z$14="CO3")*(P27:Z27)*MOD(COLUMN($P$14:$Z$14)-COLUMN($P$14)+1,2))) -> 19 | AE27: =SUMIF($E$14:$N$14,"CO4",$E$17:$N$17) + IF(O27>=0, SUMPRODUCT(($O$14:$Z$14="CO4")*(O27:Z27)*MOD(COLUMN($O$14:$Z$14)-COLUMN($O$14)+1,2))+ SUMPRODUCT(($P$14:$Z$14="CO4")*(P27:Z27)*MOD(COLUMN($P$14:$Z$14)-COLUMN($P$14)+1,2))) -> 0 | AF27: =SUMIF($E$14:$N$14,"CO5",$E$17:$N$17) + IF(O27>=0, SUMPRODUCT(($O$14:$Z$14="CO5")*(O27:Z27)*MOD(COLUMN($O$14:$Z$14)-COLUMN($O$14)+1,2))+ SUMPRODUCT(($P$14:$Z$14="CO5")*(P27:Z27)*MOD(COLUMN($P$14:$Z$14)-COLUMN($P$14)+1,2)) ) -> 0 | AG27: =SUMIF($E$14:$N$14,"CO6",$E$17:$N$17) + IF(O27>0, SUMPRODUCT(($O$14:$Z$14="CO6")*($O$17:$Z$17)*MOD(COLUMN($O$14:$Z$14)-COLUMN($O$14)+1,2))+ SUMPRODUCT(($P$14:$Z$14="CO6")*($P$17:$Z$17)*MOD(COLUMN($P$14:$Z$14)-COLUMN($P$14)+1,2)) ) -> 0 | AH27: =SUM(AB27:AG27) -> 69 | AI27: =AB27/(SUMIF($E$14:$N$14,"CO1",$E$13:$N$13)+SUMPRODUCT(($O$14:$Z$14="CO1")*($O27:$Z27>0)*($O$13:$Z$13)))*100 -> 80 | AJ27: =AC27/(SUMIF($E$14:$N$14,"CO2",$E$13:$N$13)+SUMPRODUCT(($O$14:$Z$14="CO2")*($O27:$Z27>0)*($O$13:$Z$13)))*100 -> 45 | AK27: =AD27/(SUMIF($E$14:$N$14,"CO3",$E$13:$N$13)+SUMPRODUCT(($O$14:$Z$14="CO3")*($O27:$Z27>0)*($O$13:$Z$13)))*100 -> 95
A28: 14 | B28: ='STUDENT NAMELIST'!B16 -> 211423243041 | C28: ='STUDENT NAMELIST'!C16 -> 2023PEC AI 112 | D28: ='STUDENT NAMELIST'!D16 -> ARSHIYA ROSELINE P | E28: 0 | F28: 0 | G28: 2 | H28: 0 | I28: 2 | J28: 1 | K28: 2 | L28: 0 | M28: 0 | N28: 0 | P28: 15 | R28: 16 | T28: 12 | U28: 16 | W28: 16 | AA28: =SUM(E28,F28,G28,H28,I28,J28,K28,L28,M28,N28,O28,P28,Q28,R28,S28,T28,U28,V28,W28,X28,Y28,Z28) -> 82 | AB28: =SUMIF($E$14:$N$14,"CO1",E28:N28)+IF(O28>=0,SUMPRODUCT(($O$14:$Z$14="CO1")*(O28:Z28)*MOD(COLUMN($O$14:$Z$14)-COLUMN($O$14)+1,2))+SUMPRODUCT(($P$14:$Z$14="CO1")*(P28:Z28)*MOD(COLUMN($P$14:$Z$14)-COLUMN($P$14)+1,2))) -> 33 | AC28: =SUMIF($E$14:$N$14,"CO1",F28:O28)+IF(P28>=0,SUMPRODUCT(($O$14:$Z$14="CO1")*(P28:AA28)*MOD(COLUMN($O$14:$Z$14)-COLUMN($O$14)+1,2))+SUMPRODUCT(($P$14:$Z$14="CO1")*(Q28:AA28)*MOD(COLUMN($P$14:$Z$14)-COLUMN($P$14)+1,2))) -> 35 | AD28: =SUMIF($E$14:$N$14,"CO3",E28:N28)+IF(O28>=0, SUMPRODUCT(($O$14:$Z$14="CO3")*(O28:Z28)*MOD(COLUMN($O$14:$Z$14)-COLUMN($O$14)+1,2))+ SUMPRODUCT(($P$14:$Z$14="CO3")*(P28:Z28)*MOD(COLUMN($P$14:$Z$14)-COLUMN($P$14)+1,2))) -> 16 | AE28: =SUMIF($E$14:$N$14,"CO4",$E$17:$N$17) + IF(O28>=0, SUMPRODUCT(($O$14:$Z$14="CO4")*(O28:Z28)*MOD(COLUMN($O$14:$Z$14)-COLUMN($O$14)+1,2))+ SUMPRODUCT(($P$14:$Z$14="CO4")*(P28:Z28)*MOD(COLUMN($P$14:$Z$14)-COLUMN($P$14)+1,2))) -> 0 | AF28: =SUMIF($E$14:$N$14,"CO5",$E$17:$N$17) + IF(O28>=0, SUMPRODUCT(($O$14:$Z$14="CO5")*(O28:Z28)*MOD(COLUMN($O$14:$Z$14)-COLUMN($O$14)+1,2))+ SUMPRODUCT(($P$14:$Z$14="CO5")*(P28:Z28)*MOD(COLUMN($P$14:$Z$14)-COLUMN($P$14)+1,2)) ) -> 0 | AG28: =SUMIF($E$14:$N$14,"CO6",$E$17:$N$17) + IF(O28>0, SUMPRODUCT(($O$14:$Z$14="CO6")*($O$17:$Z$17)*MOD(COLUMN($O$14:$Z$14)-COLUMN($O$14)+1,2))+ SUMPRODUCT(($P$14:$Z$14="CO6")*($P$17:$Z$17)*MOD(COLUMN($P$14:$Z$14)-COLUMN($P$14)+1,2)) ) -> 0 | AH28: =SUM(AB28:AG28) -> 84 | AI28: =AB28/(SUMIF($E$14:$N$14,"CO1",$E$13:$N$13)+SUMPRODUCT(($O$14:$Z$14="CO1")*($O28:$Z28>0)*($O$13:$Z$13)))*100 -> 82.5 | AJ28: =AC28/(SUMIF($E$14:$N$14,"CO2",$E$13:$N$13)+SUMPRODUCT(($O$14:$Z$14="CO2")*($O28:$Z28>0)*($O$13:$Z$13)))*100 -> 87.5 | AK28: =AD28/(SUMIF($E$14:$N$14,"CO3",$E$13:$N$13)+SUMPRODUCT(($O$14:$Z$14="CO3")*($O28:$Z28>0)*($O$13:$Z$13)))*100 -> 80
A29: 16 | B29: ='STUDENT NAMELIST'!B17 -> 211423243042 | C29: ='STUDENT NAMELIST'!C17 -> 2023PEC AI 113 | D29: ='STUDENT NAMELIST'!D17 -> ARTHI B | E29: 2 | F29: 2 | G29: 0 | H29: 1 | I29: 0 | J29: 0 | K29: 1 | L29: 1 | M29: 2 | N29: 1 | O29: 16 | P29: 0 | Q29: 0 | R29: 16 | S29: 14 | T29: 0 | U29: 16 | V29: 0 | W29: 0 | X29: 13 | AA29: =SUM(E29,F29,G29,H29,I29,J29,K29,L29,M29,N29,O29,P29,Q29,R29,S29,T29,U29,V29,W29,X29,Y29,Z29) -> 85 | AB29: =SUMIF($E$14:$N$14,"CO1",E29:N29)+IF(O29>=0,SUMPRODUCT(($O$14:$Z$14="CO1")*(O29:Z29)*MOD(COLUMN($O$14:$Z$14)-COLUMN($O$14)+1,2))+SUMPRODUCT(($P$14:$Z$14="CO1")*(P29:Z29)*MOD(COLUMN($P$14:$Z$14)-COLUMN($P$14)+1,2))) -> 37 | AC29: =SUMIF($E$14:$N$14,"CO1",F29:O29)+IF(P29>=0,SUMPRODUCT(($O$14:$Z$14="CO1")*(P29:AA29)*MOD(COLUMN($O$14:$Z$14)-COLUMN($O$14)+1,2))+SUMPRODUCT(($P$14:$Z$14="CO1")*(Q29:AA29)*MOD(COLUMN($P$14:$Z$14)-COLUMN($P$14)+1,2))) -> 33 | AD29: =SUMIF($E$14:$N$14,"CO3",E29:N29)+IF(O29>=0, SUMPRODUCT(($O$14:$Z$14="CO3")*(O29:Z29)*MOD(COLUMN($O$14:$Z$14)-COLUMN($O$14)+1,2))+ SUMPRODUCT(($P$14:$Z$14="CO3")*(P29:Z29)*MOD(COLUMN($P$14:$Z$14)-COLUMN($P$14)+1,2))) -> 16 | AE29: =SUMIF($E$14:$N$14,"CO4",$E$17:$N$17) + IF(O29>=0, SUMPRODUCT(($O$14:$Z$14="CO4")*(O29:Z29)*MOD(COLUMN($O$14:$Z$14)-COLUMN($O$14)+1,2))+ SUMPRODUCT(($P$14:$Z$14="CO4")*(P29:Z29)*MOD(COLUMN($P$14:$Z$14)-COLUMN($P$14)+1,2))) -> 0 | AF29: =SUMIF($E$14:$N$14,"CO5",$E$17:$N$17) + IF(O29>=0, SUMPRODUCT(($O$14:$Z$14="CO5")*(O29:Z29)*MOD(COLUMN($O$14:$Z$14)-COLUMN($O$14)+1,2))+ SUMPRODUCT(($P$14:$Z$14="CO5")*(P29:Z29)*MOD(COLUMN($P$14:$Z$14)-COLUMN($P$14)+1,2)) ) -> 0 | AG29: =SUMIF($E$14:$N$14,"CO6",$E$17:$N$17) + IF(O29>0, SUMPRODUCT(($O$14:$Z$14="CO6")*($O$17:$Z$17)*MOD(COLUMN($O$14:$Z$14)-COLUMN($O$14)+1,2))+ SUMPRODUCT(($P$14:$Z$14="CO6")*($P$17:$Z$17)*MOD(COLUMN($P$14:$Z$14)-COLUMN($P$14)+1,2)) ) -> 0 | AH29: =SUM(AB29:AG29) -> 86 | AI29: =AB29/(SUMIF($E$14:$N$14,"CO1",$E$13:$N$13)+SUMPRODUCT(($O$14:$Z$14="CO1")*($O29:$Z29>0)*($O$13:$Z$13)))*100 -> 92.5 | AJ29: =AC29/(SUMIF($E$14:$N$14,"CO2",$E$13:$N$13)+SUMPRODUCT(($O$14:$Z$14="CO2")*($O29:$Z29>0)*($O$13:$Z$13)))*100 -> 82.5 | AK29: =AD29/(SUMIF($E$14:$N$14,"CO3",$E$13:$N$13)+SUMPRODUCT(($O$14:$Z$14="CO3")*($O29:$Z29>0)*($O$13:$Z$13)))*100 -> 80
A30: 14 | B30: ='STUDENT NAMELIST'!B18 -> 211423243044 | C30: ='STUDENT NAMELIST'!C18 -> 2023PEC AI 114 | D30: ='STUDENT NAMELIST'!D18 -> ARUNA S | E30: 1 | F30: 1 | G30: 0 | H30: 0 | I30: 0 | J30: 2 | K30: 0 | L30: 1 | M30: 2 | N30: 2 | O30: 16 | P30: 0 | Q30: 0 | R30: 16 | S30: 14 | T30: 0 | U30: 16 | V30: 0 | W30: 0 | X30: 13 | AA30: =SUM(E30,F30,G30,H30,I30,J30,K30,L30,M30,N30,O30,P30,Q30,R30,S30,T30,U30,V30,W30,X30,Y30,Z30) -> 84 | AB30: =SUMIF($E$14:$N$14,"CO1",E30:N30)+IF(O30>=0,SUMPRODUCT(($O$14:$Z$14="CO1")*(O30:Z30)*MOD(COLUMN($O$14:$Z$14)-COLUMN($O$14)+1,2))+SUMPRODUCT(($P$14:$Z$14="CO1")*(P30:Z30)*MOD(COLUMN($P$14:$Z$14)-COLUMN($P$14)+1,2))) -> 34 | AC30: =SUMIF($E$14:$N$14,"CO1",F30:O30)+IF(P30>=0,SUMPRODUCT(($O$14:$Z$14="CO1")*(P30:AA30)*MOD(COLUMN($O$14:$Z$14)-COLUMN($O$14)+1,2))+SUMPRODUCT(($P$14:$Z$14="CO1")*(Q30:AA30)*MOD(COLUMN($P$14:$Z$14)-COLUMN($P$14)+1,2))) -> 31 | AD30: =SUMIF($E$14:$N$14,"CO3",E30:N30)+IF(O30>=0, SUMPRODUCT(($O$14:$Z$14="CO3")*(O30:Z30)*MOD(COLUMN($O$14:$Z$14)-COLUMN($O$14)+1,2))+ SUMPRODUCT(($P$14:$Z$14="CO3")*(P30:Z30)*MOD(COLUMN($P$14:$Z$14)-COLUMN($P$14)+1,2))) -> 17 | AE30: =SUMIF($E$14:$N$14,"CO4",$E$17:$N$17) + IF(O30>=0, SUMPRODUCT(($O$14:$Z$14="CO4")*(O30:Z30)*MOD(COLUMN($O$14:$Z$14)-COLUMN($O$14)+1,2))+ SUMPRODUCT(($P$14:$Z$14="CO4")*(P30:Z30)*MOD(COLUMN($P$14:$Z$14)-COLUMN($P$14)+1,2))) -> 0 | AF30: =SUMIF($E$14:$N$14,"CO5",$E$17:$N$17) + IF(O30>=0, SUMPRODUCT(($O$14:$Z$14="CO5")*(O30:Z30)*MOD(COLUMN($O$14:$Z$14)-COLUMN($O$14)+1,2))+ SUMPRODUCT(($P$14:$Z$14="CO5")*(P30:Z30)*MOD(COLUMN($P$14:$Z$14)-COLUMN($P$14)+1,2)) ) -> 0 | AG30: =SUMIF($E$14:$N$14,"CO6",$E$17:$N$17) + IF(O30>0, SUMPRODUCT(($O$14:$Z$14="CO6")*($O$17:$Z$17)*MOD(COLUMN($O$14:$Z$14)-COLUMN($O$14)+1,2))+ SUMPRODUCT(($P$14:$Z$14="CO6")*($P$17:$Z$17)*MOD(COLUMN($P$14:$Z$14)-COLUMN($P$14)+1,2)) ) -> 0 | AH30: =SUM(AB30:AG30) -> 82 | AI30: =AB30/(SUMIF($E$14:$N$14,"CO1",$E$13:$N$13)+SUMPRODUCT(($O$14:$Z$14="CO1")*($O30:$Z30>0)*($O$13:$Z$13)))*100 -> 85 | AJ30: =AC30/(SUMIF($E$14:$N$14,"CO2",$E$13:$N$13)+SUMPRODUCT(($O$14:$Z$14="CO2")*($O30:$Z30>0)*($O$13:$Z$13)))*100 -> 77.5 | AK30: =AD30/(SUMIF($E$14:$N$14,"CO3",$E$13:$N$13)+SUMPRODUCT(($O$14:$Z$14="CO3")*($O30:$Z30>0)*($O$13:$Z$13)))*100 -> 85
A31: 15 | B31: ='STUDENT NAMELIST'!B19 -> 211423243047 | C31: ='STUDENT NAMELIST'!C19 -> 2023PEC AI 115 | D31: ='STUDENT NAMELIST'!D19 -> ASHIKA D | E31: 0 | F31: 0 | G31: 1 | H31: 0 | I31: 0 | J31: 0 | K31: 1 | L31: 0 | M31: 2 | N31: 1 | O31: 14 | Q31: 14 | S31: 14 | U31: 14 | W31: 14 | AA31: =SUM(E31,F31,G31,H31,I31,J31,K31,L31,M31,N31,O31,P31,Q31,R31,S31,T31,U31,V31,W31,X31,Y31,Z31) -> 75 | AB31: =SUMIF($E$14:$N$14,"CO1",E31:N31)+IF(O31>=0,SUMPRODUCT(($O$14:$Z$14="CO1")*(O31:Z31)*MOD(COLUMN($O$14:$Z$14)-COLUMN($O$14)+1,2))+SUMPRODUCT(($P$14:$Z$14="CO1")*(P31:Z31)*MOD(COLUMN($P$14:$Z$14)-COLUMN($P$14)+1,2))) -> 29 | AC31: =SUMIF($E$14:$N$14,"CO1",F31:O31)+IF(P31>=0,SUMPRODUCT(($O$14:$Z$14="CO1")*(P31:AA31)*MOD(COLUMN($O$14:$Z$14)-COLUMN($O$14)+1,2))+SUMPRODUCT(($P$14:$Z$14="CO1")*(Q31:AA31)*MOD(COLUMN($P$14:$Z$14)-COLUMN($P$14)+1,2))) -> 29 | AD31: =SUMIF($E$14:$N$14,"CO3",E31:N31)+IF(O31>=0, SUMPRODUCT(($O$14:$Z$14="CO3")*(O31:Z31)*MOD(COLUMN($O$14:$Z$14)-COLUMN($O$14)+1,2))+ SUMPRODUCT(($P$14:$Z$14="CO3")*(P31:Z31)*MOD(COLUMN($P$14:$Z$14)-COLUMN($P$14)+1,2))) -> 17 | AE31: =SUMIF($E$14:$N$14,"CO4",$E$17:$N$17) + IF(O31>=0, SUMPRODUCT(($O$14:$Z$14="CO4")*(O31:Z31)*MOD(COLUMN($O$14:$Z$14)-COLUMN($O$14)+1,2))+ SUMPRODUCT(($P$14:$Z$14="CO4")*(P31:Z31)*MOD(COLUMN($P$14:$Z$14)-COLUMN($P$14)+1,2))) -> 0 | AF31: =SUMIF($E$14:$N$14,"CO5",$E$17:$N$17) + IF(O31>=0, SUMPRODUCT(($O$14:$Z$14="CO5")*(O31:Z31)*MOD(COLUMN($O$14:$Z$14)-COLUMN($O$14)+1,2))+ SUMPRODUCT(($P$14:$Z$14="CO5")*(P31:Z31)*MOD(COLUMN($P$14:$Z$14)-COLUMN($P$14)+1,2)) ) -> 0 | AG31: =SUMIF($E$14:$N$14,"CO6",$E$17:$N$17) + IF(O31>0, SUMPRODUCT(($O$14:$Z$14="CO6")*($O$17:$Z$17)*MOD(COLUMN($O$14:$Z$14)-COLUMN($O$14)+1,2))+ SUMPRODUCT(($P$14:$Z$14="CO6")*($P$17:$Z$17)*MOD(COLUMN($P$14:$Z$14)-COLUMN($P$14)+1,2)) ) -> 0 | AH31: =SUM(AB31:AG31) -> 75 | AI31: =AB31/(SUMIF($E$14:$N$14,"CO1",$E$13:$N$13)+SUMPRODUCT(($O$14:$Z$14="CO1")*($O31:$Z31>0)*($O$13:$Z$13)))*100 -> 72.5 | AJ31: =AC31/(SUMIF($E$14:$N$14,"CO2",$E$13:$N$13)+SUMPRODUCT(($O$14:$Z$14="CO2")*($O31:$Z31>0)*($O$13:$Z$13)))*100 -> 72.5 | AK31: =AD31/(SUMIF($E$14:$N$14,"CO3",$E$13:$N$13)+SUMPRODUCT(($O$14:$Z$14="CO3")*($O31:$Z31>0)*($O$13:$Z$13)))*100 -> 85
A32: 16 | B32: ='STUDENT NAMELIST'!B20 -> 211423243048 | C32: ='STUDENT NAMELIST'!C20 -> 2023PEC AI 116 | D32: ='STUDENT NAMELIST'!D20 -> ASHIKHA P | E32: 1 | F32: 2 | G32: 2 | H32: 0 | I32: 2 | J32: 2 | K32: 0 | L32: 0 | M32: 1 | N32: 2 | O32: 16 | P32: 0 | Q32: 0 | R32: 16 | S32: 14 | T32: 0 | U32: 16 | V32: 0 | W32: 0 | X32: 13 | AA32: =SUM(E32,F32,G32,H32,I32,J32,K32,L32,M32,N32,O32,P32,Q32,R32,S32,T32,U32,V32,W32,X32,Y32,Z32) -> 87 | AB32: =SUMIF($E$14:$N$14,"CO1",E32:N32)+IF(O32>=0,SUMPRODUCT(($O$14:$Z$14="CO1")*(O32:Z32)*MOD(COLUMN($O$14:$Z$14)-COLUMN($O$14)+1,2))+SUMPRODUCT(($P$14:$Z$14="CO1")*(P32:Z32)*MOD(COLUMN($P$14:$Z$14)-COLUMN($P$14)+1,2))) -> 37 | AC32: =SUMIF($E$14:$N$14,"CO1",F32:O32)+IF(P32>=0,SUMPRODUCT(($O$14:$Z$14="CO1")*(P32:AA32)*MOD(COLUMN($O$14:$Z$14)-COLUMN($O$14)+1,2))+SUMPRODUCT(($P$14:$Z$14="CO1")*(Q32:AA32)*MOD(COLUMN($P$14:$Z$14)-COLUMN($P$14)+1,2))) -> 36 | AD32: =SUMIF($E$14:$N$14,"CO3",E32:N32)+IF(O32>=0, SUMPRODUCT(($O$14:$Z$14="CO3")*(O32:Z32)*MOD(COLUMN($O$14:$Z$14)-COLUMN($O$14)+1,2))+ SUMPRODUCT(($P$14:$Z$14="CO3")*(P32:Z32)*MOD(COLUMN($P$14:$Z$14)-COLUMN($P$14)+1,2))) -> 16 | AE32: =SUMIF($E$14:$N$14,"CO4",$E$17:$N$17) + IF(O32>=0, SUMPRODUCT(($O$14:$Z$14="CO4")*(O32:Z32)*MOD(COLUMN($O$14:$Z$14)-COLUMN($O$14)+1,2))+ SUMPRODUCT(($P$14:$Z$14="CO4")*(P32:Z32)*MOD(COLUMN($P$14:$Z$14)-COLUMN($P$14)+1,2))) -> 0 | AF32: =SUMIF($E$14:$N$14,"CO5",$E$17:$N$17) + IF(O32>=0, SUMPRODUCT(($O$14:$Z$14="CO5")*(O32:Z32)*MOD(COLUMN($O$14:$Z$14)-COLUMN($O$14)+1,2))+ SUMPRODUCT(($P$14:$Z$14="CO5")*(P32:Z32)*MOD(COLUMN($P$14:$Z$14)-COLUMN($P$14)+1,2)) ) -> 0 | AG32: =SUMIF($E$14:$N$14,"CO6",$E$17:$N$17) + IF(O32>0, SUMPRODUCT(($O$14:$Z$14="CO6")*($O$17:$Z$17)*MOD(COLUMN($O$14:$Z$14)-COLUMN($O$14)+1,2))+ SUMPRODUCT(($P$14:$Z$14="CO6")*($P$17:$Z$17)*MOD(COLUMN($P$14:$Z$14)-COLUMN($P$14)+1,2)) ) -> 0 | AH32: =SUM(AB32:AG32) -> 89 | AI32: =AB32/(SUMIF($E$14:$N$14,"CO1",$E$13:$N$13)+SUMPRODUCT(($O$14:$Z$14="CO1")*($O32:$Z32>0)*($O$13:$Z$13)))*100 -> 92.5 | AJ32: =AC32/(SUMIF($E$14:$N$14,"CO2",$E$13:$N$13)+SUMPRODUCT(($O$14:$Z$14="CO2")*($O32:$Z32>0)*($O$13:$Z$13)))*100 -> 90 | AK32: =AD32/(SUMIF($E$14:$N$14,"CO3",$E$13:$N$13)+SUMPRODUCT(($O$14:$Z$14="CO3")*($O32:$Z32>0)*($O$13:$Z$13)))*100 -> 80
A33: 18 | B33: ='STUDENT NAMELIST'!B21 -> 211423243049 | C33: ='STUDENT NAMELIST'!C21 -> 2023PEC AI 117 | D33: ='STUDENT NAMELIST'!D21 -> ASHIN LATHIKA E J | E33: 2 | F33: 1 | G33: 2 | H33: 0 | I33: 0 | J33: 2 | K33: 1 | L33: 2 | M33: 0 | N33: 0 | O33: 16 | P33: 0 | Q33: 0 | R33: 16 | S33: 14 | T33: 0 | U33: 16 | V33: 0 | W33: 0 | X33: 13 | AA33: =SUM(E33,F33,G33,H33,I33,J33,K33,L33,M33,N33,O33,P33,Q33,R33,S33,T33,U33,V33,W33,X33,Y33,Z33) -> 85 | AB33: =SUMIF($E$14:$N$14,"CO1",E33:N33)+IF(O33>=0,SUMPRODUCT(($O$14:$Z$14="CO1")*(O33:Z33)*MOD(COLUMN($O$14:$Z$14)-COLUMN($O$14)+1,2))+SUMPRODUCT(($P$14:$Z$14="CO1")*(P33:Z33)*MOD(COLUMN($P$14:$Z$14)-COLUMN($P$14)+1,2))) -> 37 | AC33: =SUMIF($E$14:$N$14,"CO1",F33:O33)+IF(P33>=0,SUMPRODUCT(($O$14:$Z$14="CO1")*(P33:AA33)*MOD(COLUMN($O$14:$Z$14)-COLUMN($O$14)+1,2))+SUMPRODUCT(($P$14:$Z$14="CO1")*(Q33:AA33)*MOD(COLUMN($P$14:$Z$14)-COLUMN($P$14)+1,2))) -> 33 | AD33: =SUMIF($E$14:$N$14,"CO3",E33:N33)+IF(O33>=0, SUMPRODUCT(($O$14:$Z$14="CO3")*(O33:Z33)*MOD(COLUMN($O$14:$Z$14)-COLUMN($O$14)+1,2))+ SUMPRODUCT(($P$14:$Z$14="CO3")*(P33:Z33)*MOD(COLUMN($P$14:$Z$14)-COLUMN($P$14)+1,2))) -> 13 | AE33: =SUMIF($E$14:$N$14,"CO4",$E$17:$N$17) + IF(O33>=0, SUMPRODUCT(($O$14:$Z$14="CO4")*(O33:Z33)*MOD(COLUMN($O$14:$Z$14)-COLUMN($O$14)+1,2))+ SUMPRODUCT(($P$14:$Z$14="CO4")*(P33:Z33)*MOD(COLUMN($P$14:$Z$14)-COLUMN($P$14)+1,2))) -> 0 | AF33: =SUMIF($E$14:$N$14,"CO5",$E$17:$N$17) + IF(O33>=0, SUMPRODUCT(($O$14:$Z$14="CO5")*(O33:Z33)*MOD(COLUMN($O$14:$Z$14)-COLUMN($O$14)+1,2))+ SUMPRODUCT(($P$14:$Z$14="CO5")*(P33:Z33)*MOD(COLUMN($P$14:$Z$14)-COLUMN($P$14)+1,2)) ) -> 0 | AG33: =SUMIF($E$14:$N$14,"CO6",$E$17:$N$17) + IF(O33>0, SUMPRODUCT(($O$14:$Z$14="CO6")*($O$17:$Z$17)*MOD(COLUMN($O$14:$Z$14)-COLUMN($O$14)+1,2))+ SUMPRODUCT(($P$14:$Z$14="CO6")*($P$17:$Z$17)*MOD(COLUMN($P$14:$Z$14)-COLUMN($P$14)+1,2)) ) -> 0 | AH33: =SUM(AB33:AG33) -> 83 | AI33: =AB33/(SUMIF($E$14:$N$14,"CO1",$E$13:$N$13)+SUMPRODUCT(($O$14:$Z$14="CO1")*($O33:$Z33>0)*($O$13:$Z$13)))*100 -> 92.5 | AJ33: =AC33/(SUMIF($E$14:$N$14,"CO2",$E$13:$N$13)+SUMPRODUCT(($O$14:$Z$14="CO2")*($O33:$Z33>0)*($O$13:$Z$13)))*100 -> 82.5 | AK33: =AD33/(SUMIF($E$14:$N$14,"CO3",$E$13:$N$13)+SUMPRODUCT(($O$14:$Z$14="CO3")*($O33:$Z33>0)*($O$13:$Z$13)))*100 -> 65
A34: 18 | B34: ='STUDENT NAMELIST'!B22 -> 211423243050 | C34: ='STUDENT NAMELIST'!C22 -> 2023PEC AI 118 | D34: ='STUDENT NAMELIST'!D22 -> ASHVITHA R | E34: 1 | F34: 2 | G34: 1 | H34: 0 | I34: 0 | J34: 0 | K34: 1 | L34: 1 | M34: 1 | N34: 1 | O34: 14 | Q34: 14 | S34: 14 | U34: 14 | W34: 14 | AA34: =SUM(E34,F34,G34,H34,I34,J34,K34,L34,M34,N34,O34,P34,Q34,R34,S34,T34,U34,V34,W34,X34,Y34,Z34) -> 78 | AB34: =SUMIF($E$14:$N$14,"CO1",E34:N34)+IF(O34>=0,SUMPRODUCT(($O$14:$Z$14="CO1")*(O34:Z34)*MOD(COLUMN($O$14:$Z$14)-COLUMN($O$14)+1,2))+SUMPRODUCT(($P$14:$Z$14="CO1")*(P34:Z34)*MOD(COLUMN($P$14:$Z$14)-COLUMN($P$14)+1,2))) -> 32 | AC34: =SUMIF($E$14:$N$14,"CO1",F34:O34)+IF(P34>=0,SUMPRODUCT(($O$14:$Z$14="CO1")*(P34:AA34)*MOD(COLUMN($O$14:$Z$14)-COLUMN($O$14)+1,2))+SUMPRODUCT(($P$14:$Z$14="CO1")*(Q34:AA34)*MOD(COLUMN($P$14:$Z$14)-COLUMN($P$14)+1,2))) -> 31 | AD34: =SUMIF($E$14:$N$14,"CO3",E34:N34)+IF(O34>=0, SUMPRODUCT(($O$14:$Z$14="CO3")*(O34:Z34)*MOD(COLUMN($O$14:$Z$14)-COLUMN($O$14)+1,2))+ SUMPRODUCT(($P$14:$Z$14="CO3")*(P34:Z34)*MOD(COLUMN($P$14:$Z$14)-COLUMN($P$14)+1,2))) -> 16 | AE34: =SUMIF($E$14:$N$14,"CO4",$E$17:$N$17) + IF(O34>=0, SUMPRODUCT(($O$14:$Z$14="CO4")*(O34:Z34)*MOD(COLUMN($O$14:$Z$14)-COLUMN($O$14)+1,2))+ SUMPRODUCT(($P$14:$Z$14="CO4")*(P34:Z34)*MOD(COLUMN($P$14:$Z$14)-COLUMN($P$14)+1,2))) -> 0 | AF34: =SUMIF($E$14:$N$14,"CO5",$E$17:$N$17) + IF(O34>=0, SUMPRODUCT(($O$14:$Z$14="CO5")*(O34:Z34)*MOD(COLUMN($O$14:$Z$14)-COLUMN($O$14)+1,2))+ SUMPRODUCT(($P$14:$Z$14="CO5")*(P34:Z34)*MOD(COLUMN($P$14:$Z$14)-COLUMN($P$14)+1,2)) ) -> 0 | AG34: =SUMIF($E$14:$N$14,"CO6",$E$17:$N$17) + IF(O34>0, SUMPRODUCT(($O$14:$Z$14="CO6")*($O$17:$Z$17)*MOD(COLUMN($O$14:$Z$14)-COLUMN($O$14)+1,2))+ SUMPRODUCT(($P$14:$Z$14="CO6")*($P$17:$Z$17)*MOD(COLUMN($P$14:$Z$14)-COLUMN($P$14)+1,2)) ) -> 0 | AH34: =SUM(AB34:AG34) -> 79 | AI34: =AB34/(SUMIF($E$14:$N$14,"CO1",$E$13:$N$13)+SUMPRODUCT(($O$14:$Z$14="CO1")*($O34:$Z34>0)*($O$13:$Z$13)))*100 -> 80 | AJ34: =AC34/(SUMIF($E$14:$N$14,"CO2",$E$13:$N$13)+SUMPRODUCT(($O$14:$Z$14="CO2")*($O34:$Z34>0)*($O$13:$Z$13)))*100 -> 77.5 | AK34: =AD34/(SUMIF($E$14:$N$14,"CO3",$E$13:$N$13)+SUMPRODUCT(($O$14:$Z$14="CO3")*($O34:$Z34>0)*($O$13:$Z$13)))*100 -> 80
A35: 19 | B35: ='STUDENT NAMELIST'!B23 -> 211423243053 | C35: ='STUDENT NAMELIST'!C23 -> 2023PEC AI 119 | D35: ='STUDENT NAMELIST'!D23 -> ATSHAYA S | E35: 1 | F35: 1 | G35: 1 | H35: 0 | I35: 1 | J35: 2 | K35: 1 | L35: 0 | M35: 1 | N35: 1 | O35: 16 | P35: 0 | Q35: 0 | R35: 16 | S35: 14 | T35: 0 | U35: 16 | V35: 0 | W35: 0 | X35: 13 | AA35: =SUM(E35,F35,G35,H35,I35,J35,K35,L35,M35,N35,O35,P35,Q35,R35,S35,T35,U35,V35,W35,X35,Y35,Z35) -> 84 | AB35: =SUMIF($E$14:$N$14,"CO1",E35:N35)+IF(O35>=0,SUMPRODUCT(($O$14:$Z$14="CO1")*(O35:Z35)*MOD(COLUMN($O$14:$Z$14)-COLUMN($O$14)+1,2))+SUMPRODUCT(($P$14:$Z$14="CO1")*(P35:Z35)*MOD(COLUMN($P$14:$Z$14)-COLUMN($P$14)+1,2))) -> 35 | AC35: =SUMIF($E$14:$N$14,"CO1",F35:O35)+IF(P35>=0,SUMPRODUCT(($O$14:$Z$14="CO1")*(P35:AA35)*MOD(COLUMN($O$14:$Z$14)-COLUMN($O$14)+1,2))+SUMPRODUCT(($P$14:$Z$14="CO1")*(Q35:AA35)*MOD(COLUMN($P$14:$Z$14)-COLUMN($P$14)+1,2))) -> 33 | AD35: =SUMIF($E$14:$N$14,"CO3",E35:N35)+IF(O35>=0, SUMPRODUCT(($O$14:$Z$14="CO3")*(O35:Z35)*MOD(COLUMN($O$14:$Z$14)-COLUMN($O$14)+1,2))+ SUMPRODUCT(($P$14:$Z$14="CO3")*(P35:Z35)*MOD(COLUMN($P$14:$Z$14)-COLUMN($P$14)+1,2))) -> 15 | AE35: =SUMIF($E$14:$N$14,"CO4",$E$17:$N$17) + IF(O35>=0, SUMPRODUCT(($O$14:$Z$14="CO4")*(O35:Z35)*MOD(COLUMN($O$14:$Z$14)-COLUMN($O$14)+1,2))+ SUMPRODUCT(($P$14:$Z$14="CO4")*(P35:Z35)*MOD(COLUMN($P$14:$Z$14)-COLUMN($P$14)+1,2))) -> 0 | AF35: =SUMIF($E$14:$N$14,"CO5",$E$17:$N$17) + IF(O35>=0, SUMPRODUCT(($O$14:$Z$14="CO5")*(O35:Z35)*MOD(COLUMN($O$14:$Z$14)-COLUMN($O$14)+1,2))+ SUMPRODUCT(($P$14:$Z$14="CO5")*(P35:Z35)*MOD(COLUMN($P$14:$Z$14)-COLUMN($P$14)+1,2)) ) -> 0 | AG35: =SUMIF($E$14:$N$14,"CO6",$E$17:$N$17) + IF(O35>0, SUMPRODUCT(($O$14:$Z$14="CO6")*($O$17:$Z$17)*MOD(COLUMN($O$14:$Z$14)-COLUMN($O$14)+1,2))+ SUMPRODUCT(($P$14:$Z$14="CO6")*($P$17:$Z$17)*MOD(COLUMN($P$14:$Z$14)-COLUMN($P$14)+1,2)) ) -> 0 | AH35: =SUM(AB35:AG35) -> 83 | AI35: =AB35/(SUMIF($E$14:$N$14,"CO1",$E$13:$N$13)+SUMPRODUCT(($O$14:$Z$14="CO1")*($O35:$Z35>0)*($O$13:$Z$13)))*100 -> 87.5 | AJ35: =AC35/(SUMIF($E$14:$N$14,"CO2",$E$13:$N$13)+SUMPRODUCT(($O$14:$Z$14="CO2")*($O35:$Z35>0)*($O$13:$Z$13)))*100 -> 82.5 | AK35: =AD35/(SUMIF($E$14:$N$14,"CO3",$E$13:$N$13)+SUMPRODUCT(($O$14:$Z$14="CO3")*($O35:$Z35>0)*($O$13:$Z$13)))*100 -> 75
A36: 20 | B36: ='STUDENT NAMELIST'!B24 -> 211423243054 | C36: ='STUDENT NAMELIST'!C24 -> 2023PEC AI 120 | D36: ='STUDENT NAMELIST'!D24 -> AYSHA KETHAR FATHIMA A S | E36: 2 | F36: 2 | G36: 1 | H36: 2 | I36: 2 | J36: 0 | K36: 1 | L36: 1 | M36: 0 | N36: 0 | O36: 14 | Q36: 14 | S36: 14 | U36: 14 | W36: 14 | AA36: =SUM(E36,F36,G36,H36,I36,J36,K36,L36,M36,N36,O36,P36,Q36,R36,S36,T36,U36,V36,W36,X36,Y36,Z36) -> 81 | AB36: =SUMIF($E$14:$N$14,"CO1",E36:N36)+IF(O36>=0,SUMPRODUCT(($O$14:$Z$14="CO1")*(O36:Z36)*MOD(COLUMN($O$14:$Z$14)-COLUMN($O$14)+1,2))+SUMPRODUCT(($P$14:$Z$14="CO1")*(P36:Z36)*MOD(COLUMN($P$14:$Z$14)-COLUMN($P$14)+1,2))) -> 35 | AC36: =SUMIF($E$14:$N$14,"CO1",F36:O36)+IF(P36>=0,SUMPRODUCT(($O$14:$Z$14="CO1")*(P36:AA36)*MOD(COLUMN($O$14:$Z$14)-COLUMN($O$14)+1,2))+SUMPRODUCT(($P$14:$Z$14="CO1")*(Q36:AA36)*MOD(COLUMN($P$14:$Z$14)-COLUMN($P$14)+1,2))) -> 35 | AD36: =SUMIF($E$14:$N$14,"CO3",E36:N36)+IF(O36>=0, SUMPRODUCT(($O$14:$Z$14="CO3")*(O36:Z36)*MOD(COLUMN($O$14:$Z$14)-COLUMN($O$14)+1,2))+ SUMPRODUCT(($P$14:$Z$14="CO3")*(P36:Z36)*MOD(COLUMN($P$14:$Z$14)-COLUMN($P$14)+1,2))) -> 14 | AE36: =SUMIF($E$14:$N$14,"CO4",$E$17:$N$17) + IF(O36>=0, SUMPRODUCT(($O$14:$Z$14="CO4")*(O36:Z36)*MOD(COLUMN($O$14:$Z$14)-COLUMN($O$14)+1,2))+ SUMPRODUCT(($P$14:$Z$14="CO4")*(P36:Z36)*MOD(COLUMN($P$14:$Z$14)-COLUMN($P$14)+1,2))) -> 0 | AF36: =SUMIF($E$14:$N$14,"CO5",$E$17:$N$17) + IF(O36>=0, SUMPRODUCT(($O$14:$Z$14="CO5")*(O36:Z36)*MOD(COLUMN($O$14:$Z$14)-COLUMN($O$14)+1,2))+ SUMPRODUCT(($P$14:$Z$14="CO5")*(P36:Z36)*MOD(COLUMN($P$14:$Z$14)-COLUMN($P$14)+1,2)) ) -> 0 | AG36: =SUMIF($E$14:$N$14,"CO6",$E$17:$N$17) + IF(O36>0, SUMPRODUCT(($O$14:$Z$14="CO6")*($O$17:$Z$17)*MOD(COLUMN($O$14:$Z$14)-COLUMN($O$14)+1,2))+ SUMPRODUCT(($P$14:$Z$14="CO6")*($P$17:$Z$17)*MOD(COLUMN($P$14:$Z$14)-COLUMN($P$14)+1,2)) ) -> 0 | AH36: =SUM(AB36:AG36) -> 84 | AI36: =AB36/(SUMIF($E$14:$N$14,"CO1",$E$13:$N$13)+SUMPRODUCT(($O$14:$Z$14="CO1")*($O36:$Z36>0)*($O$13:$Z$13)))*100 -> 87.5 | AJ36: =AC36/(SUMIF($E$14:$N$14,"CO2",$E$13:$N$13)+SUMPRODUCT(($O$14:$Z$14="CO2")*($O36:$Z36>0)*($O$13:$Z$13)))*100 -> 87.5 | AK36: =AD36/(SUMIF($E$14:$N$14,"CO3",$E$13:$N$13)+SUMPRODUCT(($O$14:$Z$14="CO3")*($O36:$Z36>0)*($O$13:$Z$13)))*100 -> 70
A37: 21 | B37: ='STUDENT NAMELIST'!B25 -> 211423243055 | C37: ='STUDENT NAMELIST'!C25 -> 2023PEC AI 121 | D37: ='STUDENT NAMELIST'!D25 -> AYSHVARYA P | E37: 0 | F37: 2 | G37: 2 | H37: 2 | I37: 1 | J37: 2 | K37: 1 | L37: 1 | M37: 1 | N37: 0 | O37: 16 | P37: 0 | Q37: 0 | R37: 16 | S37: 14 | T37: 0 | U37: 16 | V37: 0 | W37: 0 | X37: 13 | AA37: =SUM(E37,F37,G37,H37,I37,J37,K37,L37,M37,N37,O37,P37,Q37,R37,S37,T37,U37,V37,W37,X37,Y37,Z37) -> 87 | AB37: =SUMIF($E$14:$N$14,"CO1",E37:N37)+IF(O37>=0,SUMPRODUCT(($O$14:$Z$14="CO1")*(O37:Z37)*MOD(COLUMN($O$14:$Z$14)-COLUMN($O$14)+1,2))+SUMPRODUCT(($P$14:$Z$14="CO1")*(P37:Z37)*MOD(COLUMN($P$14:$Z$14)-COLUMN($P$14)+1,2))) -> 38 | AC37: =SUMIF($E$14:$N$14,"CO1",F37:O37)+IF(P37>=0,SUMPRODUCT(($O$14:$Z$14="CO1")*(P37:AA37)*MOD(COLUMN($O$14:$Z$14)-COLUMN($O$14)+1,2))+SUMPRODUCT(($P$14:$Z$14="CO1")*(Q37:AA37)*MOD(COLUMN($P$14:$Z$14)-COLUMN($P$14)+1,2))) -> 37 | AD37: =SUMIF($E$14:$N$14,"CO3",E37:N37)+IF(O37>=0, SUMPRODUCT(($O$14:$Z$14="CO3")*(O37:Z37)*MOD(COLUMN($O$14:$Z$14)-COLUMN($O$14)+1,2))+ SUMPRODUCT(($P$14:$Z$14="CO3")*(P37:Z37)*MOD(COLUMN($P$14:$Z$14)-COLUMN($P$14)+1,2))) -> 14 | AE37: =SUMIF($E$14:$N$14,"CO4",$E$17:$N$17) + IF(O37>=0, SUMPRODUCT(($O$14:$Z$14="CO4")*(O37:Z37)*MOD(COLUMN($O$14:$Z$14)-COLUMN($O$14)+1,2))+ SUMPRODUCT(($P$14:$Z$14="CO4")*(P37:Z37)*MOD(COLUMN($P$14:$Z$14)-COLUMN($P$14)+1,2))) -> 0 | AF37: =SUMIF($E$14:$N$14,"CO5",$E$17:$N$17) + IF(O37>=0, SUMPRODUCT(($O$14:$Z$14="CO5")*(O37:Z37)*MOD(COLUMN($O$14:$Z$14)-COLUMN($O$14)+1,2))+ SUMPRODUCT(($P$14:$Z$14="CO5")*(P37:Z37)*MOD(COLUMN($P$14:$Z$14)-COLUMN($P$14)+1,2)) ) -> 0 | AG37: =SUMIF($E$14:$N$14,"CO6",$E$17:$N$17) + IF(O37>0, SUMPRODUCT(($O$14:$Z$14="CO6")*($O$17:$Z$17)*MOD(COLUMN($O$14:$Z$14)-COLUMN($O$14)+1,2))+ SUMPRODUCT(($P$14:$Z$14="CO6")*($P$17:$Z$17)*MOD(COLUMN($P$14:$Z$14)-COLUMN($P$14)+1,2)) ) -> 0 | AH37: =SUM(AB37:AG37) -> 89 | AI37: =AB37/(SUMIF($E$14:$N$14,"CO1",$E$13:$N$13)+SUMPRODUCT(($O$14:$Z$14="CO1")*($O37:$Z37>0)*($O$13:$Z$13)))*100 -> 95 | AJ37: =AC37/(SUMIF($E$14:$N$14,"CO2",$E$13:$N$13)+SUMPRODUCT(($O$14:$Z$14="CO2")*($O37:$Z37>0)*($O$13:$Z$13)))*100 -> 92.5 | AK37: =AD37/(SUMIF($E$14:$N$14,"CO3",$E$13:$N$13)+SUMPRODUCT(($O$14:$Z$14="CO3")*($O37:$Z37>0)*($O$13:$Z$13)))*100 -> 70
A38: 22 | B38: ='STUDENT NAMELIST'!B26 -> 211423243065 | C38: ='STUDENT NAMELIST'!C26 -> 2023PEC AI 122 | D38: ='STUDENT NAMELIST'!D26 -> BINDU SAI A | E38: 1 | F38: 1 | G38: 2 | H38: 1 | I38: 1 | J38: 0 | K38: 0 | L38: 1 | M38: 1 | N38: 0 | O38: 14 | Q38: 14 | S38: 14 | U38: 14 | W38: 14 | AA38: =SUM(E38,F38,G38,H38,I38,J38,K38,L38,M38,N38,O38,P38,Q38,R38,S38,T38,U38,V38,W38,X38,Y38,Z38) -> 78 | AB38: =SUMIF($E$14:$N$14,"CO1",E38:N38)+IF(O38>=0,SUMPRODUCT(($O$14:$Z$14="CO1")*(O38:Z38)*MOD(COLUMN($O$14:$Z$14)-COLUMN($O$14)+1,2))+SUMPRODUCT(($P$14:$Z$14="CO1")*(P38:Z38)*MOD(COLUMN($P$14:$Z$14)-COLUMN($P$14)+1,2))) -> 33 | AC38: =SUMIF($E$14:$N$14,"CO1",F38:O38)+IF(P38>=0,SUMPRODUCT(($O$14:$Z$14="CO1")*(P38:AA38)*MOD(COLUMN($O$14:$Z$14)-COLUMN($O$14)+1,2))+SUMPRODUCT(($P$14:$Z$14="CO1")*(Q38:AA38)*MOD(COLUMN($P$14:$Z$14)-COLUMN($P$14)+1,2))) -> 33 | AD38: =SUMIF($E$14:$N$14,"CO3",E38:N38)+IF(O38>=0, SUMPRODUCT(($O$14:$Z$14="CO3")*(O38:Z38)*MOD(COLUMN($O$14:$Z$14)-COLUMN($O$14)+1,2))+ SUMPRODUCT(($P$14:$Z$14="CO3")*(P38:Z38)*MOD(COLUMN($P$14:$Z$14)-COLUMN($P$14)+1,2))) -> 15 | AE38: =SUMIF($E$14:$N$14,"CO4",$E$17:$N$17) + IF(O38>=0, SUMPRODUCT(($O$14:$Z$14="CO4")*(O38:Z38)*MOD(COLUMN($O$14:$Z$14)-COLUMN($O$14)+1,2))+ SUMPRODUCT(($P$14:$Z$14="CO4")*(P38:Z38)*MOD(COLUMN($P$14:$Z$14)-COLUMN($P$14)+1,2))) -> 0 | AF38: =SUMIF($E$14:$N$14,"CO5",$E$17:$N$17) + IF(O38>=0, SUMPRODUCT(($O$14:$Z$14="CO5")*(O38:Z38)*MOD(COLUMN($O$14:$Z$14)-COLUMN($O$14)+1,2))+ SUMPRODUCT(($P$14:$Z$14="CO5")*(P38:Z38)*MOD(COLUMN($P$14:$Z$14)-COLUMN($P$14)+1,2)) ) -> 0 | AG38: =SUMIF($E$14:$N$14,"CO6",$E$17:$N$17) + IF(O38>0, SUMPRODUCT(($O$14:$Z$14="CO6")*($O$17:$Z$17)*MOD(COLUMN($O$14:$Z$14)-COLUMN($O$14)+1,2))+ SUMPRODUCT(($P$14:$Z$14="CO6")*($P$17:$Z$17)*MOD(COLUMN($P$14:$Z$14)-COLUMN($P$14)+1,2)) ) -> 0 | AH38: =SUM(AB38:AG38) -> 81 | AI38: =AB38/(SUMIF($E$14:$N$14,"CO1",$E$13:$N$13)+SUMPRODUCT(($O$14:$Z$14="CO1")*($O38:$Z38>0)*($O$13:$Z$13)))*100 -> 82.5 | AJ38: =AC38/(SUMIF($E$14:$N$14,"CO2",$E$13:$N$13)+SUMPRODUCT(($O$14:$Z$14="CO2")*($O38:$Z38>0)*($O$13:$Z$13)))*100 -> 82.5 | AK38: =AD38/(SUMIF($E$14:$N$14,"CO3",$E$13:$N$13)+SUMPRODUCT(($O$14:$Z$14="CO3")*($O38:$Z38>0)*($O$13:$Z$13)))*100 -> 75
