Workbook

Sheet COURSE ASSESSMENT
A1: PANIMALAR ENGINEERING COLLEGE
A3: Department of AI&DS
A4: Course Assessment Work Sheet
A6: SUBJECT NAME | B6: FORMAL LANGUAGES AND AUTOMATA THEORY | L6: Threshold | M6: Level 1 | N6: 60% students scoring more than threshold
A7: SUBJECT CODE | B7: 23AD1501 | L7: 60 | M7: Level 2 | N7: 70% students scoring more than threshold
A8: COURSE CODE | B8: C301 | M8: Level 3 | N8: 80% students scoring more than threshold
A9: YEAR / SEM | B9: III/V
A10: BATCH | B10: 2023-2027
A11: ACADEMIC YEAR | B11: 2025 - 2026
A12: THRESHOLD | B12: 60
A16: Upon Successful Completion of this Course, Students will be able to
A18: CO1 | B18: Recall definitions and basic components of automata, grammars, and languages.
A19: CO2 | B19: Summarize how different automata models operate and relate to each other and regular expressions used to represent regular languages.
A20: CO3 | B20: Construct automata, grammars, or machines for specified languages and patterns and apply pumping lemma, and minimization methods to determine language regularity.
A21: CO4 | B21: Compare, prove, Closure properties of languages and automata models and reframe grammars into normal forms
A22: CO5 | B22: Judge the decidability, complexity, or equivalence of computational problems and models.
A23: CO6 | B23: Design automata, grammars, or machines to solve advanced language recognition problems.
A26: Program Outcomes
A28: 1 | B28: PO1: Engineering Knowledge Apply knowledge of mathematics, natural science, computing, engineering fundamentals and an engineering specialization as specified in WK1 to WK4 respectively to develop to the solution of complex engineering problems.
A29: 2 | B29: PO2: Problem Analysis Identify, formulate, review research literature and analyze complex engineering problems reaching substantiated conclusions with consideration for sustainable development. (WK1 to WK4)
A30: 3 | B30: PO3: Design/Development of Solutions Design creative solutions for complex engineering problems and design/develop systems/components/processes to meet identified needs with consideration for the public health and safety, whole-life cost, net zero carbon, culture, society and environment as required. (WK5)
A31: 4 | B31: PO4: Conduct Investigations of Complex Problems Conduct investigations of complex engineering problems using research-based knowledge including design of experiments, modelling, analysis & interpretation of data to provide valid conclusions. (WK8).
A32: 5 | B32: PO5: Engineering Tool Usage Create, select and apply appropriate techniques, resources and modern engineering & IT tools, including prediction and modelling recognizing their limitations to solve complex engineering problems. (WK2 and WK6)
A33: 6 | B33: PO6: The Engineer and the World Analyze and evaluate societal and environmental aspects while solving complex engineering problems for its impact on sustainability with reference to economy, health, safety, legal framework, culture and environment. (WK1, WK5 and WK7).
A34: 7 | B34: PO7: Ethics Apply ethical principles and commit to professional ethics, human values, diversity and inclusion; adhere to national & international laws. (WK9).
A35: 8 | B35: PO8: Individual and Collaborative Team Work Function effectively as an individual, and as a member or leader in diverse/multi-disciplinary teams.
A36: 9 | B36: PO9: Communication Communicate effectively and inclusively within the engineering community and society at large, such as being able to comprehend and write effective reports and design documentation, make effective presentations considering cultural, language, and learning differences.
A37: 10 | B37: PO10: Project Management and Finance Apply knowledge and understanding of engineering management principles and economic decision-making and apply these to one’s own work, as a member and leader in a team, and to manage projects and in multidisciplinary environments.
A38: 11 | B38: PO11: Life-Long Learning Recognize the need for, and have the preparation and ability for i) independent and life-long learning ii) adaptability to new and emerging technologies and iii) critical thinking in the broadest context of technological change. (WK8) .
A42: Program Specific Outcomes
A44: 1 | B44: PSO 1 : AI Driven Innovation Graduates should be able to evolve AI based efficient domain specific processes for effective decision making in several domains such as business and governance domains.
A45: 2 | B45: PSO 2 : Data-Driven Decision Making Insight Graduates should be able to arrive at actionable fore sight, insight, hind sight from data for solving business and engineering problems.
A46: 3 | B46: PSO 3 : Societal Intelligence Solutions Graduates should be able to create, select and apply the theoretical knowledge of AI and Data Analytics along with practical industrial tools and techniques to manage and solve wicked societal problems.
A50: CO - PO Matrix
A52: CO | B52: PO1 | C52: PO2 | D52: PO3 | E52: PO4 | F52: PO5 | G52: PO6 | H52: PO7 | I52: PO8 | J52: PO9 | K52: PO10 | L52: PO11 | M52: PSO1 | O52: PSO2 | Q52: PSO3
A53: C301.1 | B53: 3 | C53: 1 | D53: 1 | E53: 1 | F53: 1 | G53: 1 | H53: 1 | I53: 1 | J53: 1 | K53: 1 | L53: 1 | M53: 0 | O53: 1 | Q53: 1
A54: C301.2 | B54: 3 | C54: 1 | D54: 1 | E54: 1 | F54: 1 | G54: 1 | H54: 1 | I54: 1 | J54: 1 | K54: 1 | L54: 1 | M54: 1 | O54: 1 | Q54: 1
A55: C301.3 | B55: 3 | C55: 3 | D55: 1 | E55: 1 | F55: 1 | G55: 1 | H55: 1 | I55: 1 | J55: 1 | K55: 1 | L55: 1 | M55: 1 | O55: 1 | Q55: 1
A56: C301.4 | B56: 3 | C56: 3 | D56: 1 | E56: 2 | F56: 1 | G56: 1 | H56: 0 | I56: 1 | J56: 1 | K56: 1 | L56: 1 | M56: 1 | O56: 1 | Q56: 1
A57: C301.5 | B57: 1 | C57: 2 | D57: 1 | E57: 1 | F57: 1 | G57: 1 | H57: 1 | I57: 1 | J57: 1 | K57: 1 | L57: 1 | M57: 1 | O57: 1 | Q57: 1
...

Sheet STUDENT NAMELIST
A1: PANIMALAR ENGINEERING COLLEGE
A2: STUDENTS NAMELIST
A3: S.NO | B3: REG.NO | C3: ROLL.NO | D3: STUDENT NAME
A5: 1 | B5: 2023PEC AI 541 | C5: 211423243001 | D5: AATHISUDHAN A
A6: 2 | B6: 2023PEC AI 542 | C6: 211423243002 | D6: ABESHEK SRIRAMN
A7: 3 | B7: 2023PEC AI 101 | C7: 211423243003 | D7: ABINAYA M
A8: 4 | B8: 2023PEC AI 543 | C8: 211423243004 | D8: ABINESH KUMAR T
A9: 5 | B9: 2023PEC AI 102 | C9: 211423243005 | D9: ABIRAMI A
A10: 6 | B10: 2023PEC AI 103 | C10: 211423243006 | D10: ABIRAMI G
A11: 7 | B11: 2023PEC AI 544 | C11: 211423243007 | D11: ABISHAI SINGH J
A12: 8 | B12: 2023PEC AI 545 | C12: 211423243008 | D12: ABISHEK RANGARAJ M
A13: 9 | B13: 2023PEC AI 104 | C13: 211423243009 | D13: ABITHA R D
A14: 10 | B14: 2023PEC AI 546 | C14: 211423243010 | D14: ABRAHAM S J
A15: 11 | B15: 2023PEC AI 105 | C15: 211423243011 | D15: ADELINE JERUSHA AUGUSTINE
A16: 12 | B16: 2023PEC AI 547 | C16: 211423243012 | D16: ADHINARAYANAN A
... A500: 496 | B500: 2023PEC AI 282 | C500: 211423243504 | D500: YUVASRI V
A501: 497 | C501: 211423243901 | D501: ALDRIN DENISTON N
A502: 498 | C502: 211423243902 | D502: DIYANATH K
A503: 499 | C503: 211423243903 | D503: KAVIVARSHINI G
A504: 500 | C504: 211423243904 | D504: KEERTHIVASAN S
A505: 501 | C505: 211423243905 | D505: KRISHNA AKSHAI M
A506: 502 | C506: 211423243906 | D506: NIRANJAN N
A507: 503 | C507: 211423243907 | D507: PRASANTH N

Sheet INTERNAL - I
A1: SUBJECT NAME | C1: OBJECT ORIENTED PROGRAMMING PARADIGM | E1: =IF(E14="NA",1,0) -> 0 | F1: =IF(F14="NA",1,0) -> 0 | G1: =IF(G14="NA",1,0) -> 0 | H1: =IF(H14="NA",1,0) -> 0 | J1: =IF(J14="NA",1,0) -> 0 | K1: =IF(K14="NA",1,0) -> 0 | L1: =IF(L14="NA",1,0) -> 0 | M1: =IF(M14="NA",1,0) -> 0 | O1: =IF(O14="NA",1,0) -> 0 | P1: =IF(P14="NA",1,0) -> 0 | Q1: =IF(Q14="NA",1,0) -> 0 | R1: =IF(R14="NA",1,0) -> 0 | S1: =IF(S14="NA",1,0) -> 0 | T1: =IF(T14="NA",1,0) -> 0 | U1: =IF(U14="NA",1,0) -> 0 | V1: =IF(V14="NA",1,0) -> 0 | ... Z1: =IF(Z14="NA",1,0) -> 0
A2: SUBJECT CODE | C2: 21AD1303 | D2: COURSE CODE | E2: 0
A3: YEAR / SEM | C3: II / III | D3: BATCH | E3: 2022-26
A4: ACADEMIC YEAR | C4: 2023-24
A5: FACULTY NAME(S) | C5: MRS.J.ANITHA,MRS.S.SRINIDHI,Dr.S.HEMAMALINI
A6: REGULATION | C6: 0 | E6: INTERNAL ASSESSMENT - I
A7: PANIMALAR ENGINEERING COLLEGE
A8: ACEDAMIC YEAR: | E8: ='COURSE ASSESSMENT'!$B$6 -> FORMAL LANGUAGES AND AUTOMATA THEORY | H8: INTERNAL - I RESULT | AA8: INT-I TOTAL
A9: Sl. No | B9: ROLL NO. | C9: REG NO. | D9: QUESTION NUMBER >> | E9: PART A
E10: Q. No.1 | F10: Q. No.2 | G10: Q. No.3 | H10: Q. No. 4 | I10: Q. No. 5 | J10: Q. No. 6 | K10: Q. No. 7 | L10: Q. No. 8 | M10: Q. No. 9 | N10: Q. No. 10 | O10: Q. No. 11 | Q10: Q. No. 12 | S10: Q. No. 13 | U10: Q. No. 14 | W10: Q. No. 15 | Y10: Q. No. 16 | AA10: PART - A | AB10: =SUMIF($E$14:$N$14,"CO1",$E$13:$N$13) -> 6 | AC10: =SUMIF($E$14:$N$14,"CO2",$E$13:$N$13) -> 10 | AD10: =SUMIF($E$14:$N$14,"CO3",$E$13:$N$13) -> 4 | AE10: =SUMIF($E$14:$N$14,"CO4",$E$13:$N$13) -> 0 | AF10: =SUMIF($E$14:$N$14,"CO5",$E$13:$N$13) -> 0 | AG10: =SUMIF($E$14:$N$14,"CO6",$E$13:$N$13) -> 0
AA11: PART-B (a) | AB11: =SUMPRODUCT(($O$14:$Z$14="CO1")*($O$13:$Z$13)*MOD(COLUMN($O$14:$Z$14)-COLUMN($O$14)+1,2)) -> 0 | AC11: =SUMPRODUCT(($O$14:$Z$14="CO2")*($O$13:$Z$13)*MOD(COLUMN($O$14:$Z$14)-COLUMN($O$14)+1,2)) -> 13 | AD11: =SUMPRODUCT(($O$14:$Z$14="CO3")*($O$13:$Z$13)*MOD(COLUMN($O$14:$Z$14)-COLUMN($O$14)+1,2)) -> 26 | AE11: =SUMPRODUCT(($O$14:$Z$14="CO4")*($O$13:$Z$13)*MOD(COLUMN($O$14:$Z$14)-COLUMN($O$14)+1,2)) -> 13 | AF11: =SUMPRODUCT(($O$14:$Z$14="CO5")*($O$13:$Z$13)*MOD(COLUMN($O$14:$Z$14)-COLUMN($O$14)+1,2)) -> 28 | AG11: =SUMPRODUCT(($O$14:$Z$14="CO6")*($O$13:$Z$13)*MOD(COLUMN($O$14:$Z$14)-COLUMN($O$14)+1,2)) -> 0
O12: 11.a | P12: 11.b | Q12: 12.a | R12: 12.b | S12: 13.a | T12: 13.b | U12: 14.a | V12: 14.b | W12: 15 a | X12: 15 b | Y12: 16.a | Z12: 16.b | AA12: PART-B (b) | AB12: =SUMPRODUCT(($P$14:$Z$14="CO1")*($P$13:$Z$13)*MOD(COLUMN($P$14:$Z$14)-COLUMN($P$14)+1,2)) -> 0 | AC12: =SUMPRODUCT(($P$14:$Z$14="CO2")*($P$13:$Z$13)*MOD(COLUMN($P$14:$Z$14)-COLUMN($P$14)+1,2)) -> 0 | AD12: =SUMPRODUCT(($P$14:$Z$14="CO3")*($P$13:$Z$13)*MOD(COLUMN($P$14:$Z$14)-COLUMN($P$14)+1,2)) -> 26 | AE12: =SUMPRODUCT(($P$14:$Z$14="CO4")*($P$13:$Z$13)*MOD(COLUMN($P$14:$Z$14)-COLUMN($P$14)+1,2)) -> 26 | AF12: =SUMPRODUCT(($P$14:$Z$14="CO5")*($P$13:$Z$13)*MOD(COLUMN($P$14:$Z$14)-COLUMN($P$14)+1,2)) -> 28 | AG12: =SUMPRODUCT(($P$14:$Z$14="CO6")*($P$13:$Z$13)*MOD(COLUMN($P$14:$Z$14)-COLUMN($P$14)+1,2)) -> 0
D13: MAXIMUM MARK >> | E13: 2 | F13: 2 | G13: 2 | H13: 2 | I13: 2 | J13: 2 | K13: 2 | L13: 2 | M13: 2 | N13: 2 | O13: 13 | P13: 13 | Q13: 13 | R13: 13 | S13: 13 | T13: 13 | U13: 13 | V13: 13 | W13: 13 | X13: 13 | Y13: 15 | Z13: 15 | AA13: 100 | AH13: TOTAL (100)
D14: COURSE OUTCOME >> | E14: CO2 | F14: CO1 | G14: CO2 | H14: CO2 | I14: CO3 | J14: CO2 | K14: CO1 | L14: CO1 | M14: CO3 | N14: CO2 | O14: CO3 | P14: CO3 | Q14: CO3 | R14: CO3 | S14: CO4 | T14: CO4 | U14: CO2 | V14: CO4 | W14: CO5 | X14: CO5 | Y14: CO5 | Z14: CO5 | AB14: CO1 | AC14: CO2 | AD14: CO3 | AE14: CO4 | AF14: CO5 | AG14: CO6 | AI14: CO1% | AJ14: CO2% | AK14: CO3% | AL14: CO4% | AM14: CO5% | AN14: CO6%
D15: STUDENT NAME | AB15: =SUMIF($E$14:$Z$14,"CO1",$E$13:$Z$13) -> 6 | AC15: =SUMIF($E$14:$Z$14,"CO2",$E$13:$Z$13) -> 23 | AD15: =SUMIF($E$14:$Z$14,"CO3",$E$13:$Z$13) -> 56 | AE15: =SUMIF($E$14:$Z$14,"CO4",$E$13:$Z$13) -> 39 | AF15: =SUMIF($E$14:$Z$14,"CO5",$E$13:$Z$13) -> 56 | AG15: =SUMIF($E$14:$Z$14,"CO6",$E$13:$Z$13) -> 0
A17: 1 | B17: ='STUDENT NAMELIST'!B5 -> 2023PEC AI 541 | C17: ='STUDENT NAMELIST'!C5 -> 211423243001 | D17: ='STUDENT NAMELIST'!D5 -> AATHISUDHAN A | E17: 2 | F17: 2 | G17: 2 | H17: 2 | I17: 2 | J17: 2 | K17: 2 | L17: 2 | M17: 2 | N17: 0 | O17: 13 | P17: 0 | Q17: 0 | R17: 13 | S17: 11 | T17: 0 | U17: 13 | V17: 0 | W17: 0 | X17: 8 | Y17: 14 | Z17: 0 | AA17: =SUM(E17,F17,G17,H17,I17,J17,K17,L17,M17,N17,O17,P17,Q17,R17,S17,T17,U17,V17,W17,X17,Y17,Z17) -> 90 | AB17: =SUMIF($E$14:$N$14,"CO1",E17:N17)+IF(O17>=0,SUMPRODUCT(($O$14:$Z$14="CO1")*(O17:Z17)*MOD(COLUMN($O$14:$Z$14)-COLUMN($O$14)+1,2))+SUMPRODUCT(($P$14:$Z$14="CO1")*(P17:Z17)*MOD(COLUMN($P$14:$Z$14)-COLUMN($P$14)+1,2))) -> 6 | AC17: =SUMIF($E$14:$N$14,"CO2",E17:N17)+IF(O17>=0,SUMPRODUCT(($O$14:$Z$14="CO2")*(O17:Z17)*MOD(COLUMN($O$14:$Z$14)-COLUMN($O$14)+1,2))+SUMPRODUCT(($P$14:$Z$14="CO2")*(Q17:AA17)*MOD(COLUMN($P$14:$Z$14)-COLUMN($P$14)+1,2))) -> 21 | AD17: =SUMIF($E$14:$N$14,"CO3",E17:N17)+IF(O17>=0, SUMPRODUCT(($O$14:$Z$14="CO3")*(O17:Z17)*MOD(COLUMN($O$14:$Z$14)-COLUMN($O$14)+1,2))+ SUMPRODUCT(($P$14:$Z$14="CO3")*(P17:Z17)*MOD(COLUMN($P$14:$Z$14)-COLUMN($P$14)+1,2))) -> 30 | AE17: =SUMIF($E$14:$N$14,"CO4",$E$17:$N$17) + IF(O17>=0, SUMPRODUCT(($O$14:$Z$14="CO4")*(O17:Z17)*MOD(COLUMN($O$14:$Z$14)-COLUMN($O$14)+1,2))+ SUMPRODUCT(($P$14:$Z$14="CO4")*(P17:Z17)*MOD(COLUMN($P$14:$Z$14)-COLUMN($P$14)+1,2))) -> 11 | AF17: =SUMIF($E$14:$N$14,"CO5",$E$17:$N$17) + IF(O17>=0, SUMPRODUCT(($O$14:$Z$14="CO5")*(O17:Z17)*MOD(COLUMN($O$14:$Z$14)-COLUMN($O$14)+1,2))+ SUMPRODUCT(($P$14:$Z$14="CO5")*(P17:Z17)*MOD(COLUMN($P$14:$Z$14)-COLUMN($P$14)+1,2)) ) -> 22 | AG17: =SUMIF($E$14:$N$14,"CO6",$E$17:$N$17) + IF(O17>0, SUMPRODUCT(($O$14:$Z$14="CO6")*($O$17:$Z$17)*MOD(COLUMN($O$14:$Z$14)-COLUMN($O$14)+1,2))+ SUMPRODUCT(($P$14:$Z$14="CO6")*($P$17:$Z$17)*MOD(COLUMN($P$14:$Z$14)-COLUMN($P$14)+1,2)) ) -> 0 | AH17: =SUM(AB17:AG17) -> 90 | AI17: =AB17/(SUMIF($E$14:$N$14,"CO1",$E$13:$N$13)+SUMPRODUCT(($O$14:$Z$14="CO1")*($O17:$Z17>0)*($O$13:$Z$13)))*100 -> 100 | AJ17: =AC17/(SUMIF($E$14:$N$14,"CO2",$E$13:$N$13)+SUMPRODUCT(($O$14:$Z$14="CO2")*($O17:$Z17>0)*($O$13:$Z$13)))*100 -> 91.304348 | AK17: =AD17/(SUMIF($E$14:$N$14,"CO3",$E$13:$N$13)+SUMPRODUCT(($O$14:$Z$14="CO3")*($O17:$Z17>0)*($O$13:$Z$13)))*100 -> 100 | AL17: =AE17/(SUMIF($E$14:$N$14,"CO4",$E$13:$N$13)+SUMPRODUCT(($O$14:$Z$14="CO4")*($O17:$Z17>0)*($O$13:$Z$13)))*100 -> 84.615385 | AM17: =AF17/(SUMIF($E$14:$N$14,"CO5",$E$13:$N$13)+SUMPRODUCT(($O$14:$Z$14="CO5")*($O17:$Z17>0)*($O$13:$Z$13)))*100 -> 78.571429 | AN17: =AG17/(SUMIF($E$14:$N$14,"CO5",$E$13:$N$13)+SUMPRODUCT(($O$14:$Z$14="CO5")*($O17:$Z17>0)*($O$13:$Z$13)))*100 -> 0
A18: 2 | B18: ='STUDENT NAMELIST'!B6 -> 2023PEC AI 542 | C18: ='STUDENT NAMELIST'!C6 -> 211423243002 | D18: ='STUDENT NAMELIST'!D6 -> ABESHEK SRIRAMN | E18: 2 | F18: 2 | G18: 2 | H18: 2 | I18: 2 | J18: 2 | K18: 2 | L18: 0 | M18: 0 | N18: 0 | O18: 0 | P18: 10 | Q18: 10 | R18: 0 | S18: 0 | T18: 10 | U18: 0 | V18: 10 | W18: 5 | X18: 0 | Y18: 0 | Z18: 11 | AA18: =SUM(E18,F18,G18,H18,I18,J18,K18,L18,M18,N18,O18,P18,Q18,R18,S18,T18,U18,V18,W18,X18,Y18,Z18) -> 70 | AB18: =SUMIF($E$14:$N$14,"CO1",E18:N18)+IF(O18>=0,SUMPRODUCT(($O$14:$Z$14="CO1")*(O18:Z18)*MOD(COLUMN($O$14:$Z$14)-COLUMN($O$14)+1,2))+SUMPRODUCT(($P$14:$Z$14="CO1")*(P18:Z18)*MOD(COLUMN($P$14:$Z$14)-COLUMN($P$14)+1,2))) -> 4 | AC18: =SUMIF($E$14:$N$14,"CO2",E18:N18)+IF(O18>=0,SUMPRODUCT(($O$14:$Z$14="CO2")*(O18:Z18)*MOD(COLUMN($O$14:$Z$14)-COLUMN($O$14)+1,2))+SUMPRODUCT(($P$14:$Z$14="CO2")*(Q18:AA18)*MOD(COLUMN($P$14:$Z$14)-COLUMN($P$14)+1,2))) -> 8 | AD18: =SUMIF($E$14:$N$14,"CO3",E18:N18)+IF(O18>=0, SUMPRODUCT(($O$14:$Z$14="CO3")*(O18:Z18)*MOD(COLUMN($O$14:$Z$14)-COLUMN($O$14)+1,2))+ SUMPRODUCT(($P$14:$Z$14="CO3")*(P18:Z18)*MOD(COLUMN($P$14:$Z$14)-COLUMN($P$14)+1,2))) -> 22 | AE18: =SUMIF($E$14:$N$14,"CO4",$E$17:$N$17) + IF(O18>=0, SUMPRODUCT(($O$14:$Z$14="CO4")*(O18:Z18)*MOD(COLUMN($O$14:$Z$14)-COLUMN($O$14)+1,2))+ SUMPRODUCT(($P$14:$Z$14="CO4")*(P18:Z18)*MOD(COLUMN($P$14:$Z$14)-COLUMN($P$14)+1,2))) -> 20 | AF18: =SUMIF($E$14:$N$14,"CO5",$E$17:$N$17) + IF(O18>=0, SUMPRODUCT(($O$14:$Z$14="CO5")*(O18:Z18)*MOD(COLUMN($O$14:$Z$14)-COLUMN($O$14)+1,2))+ SUMPRODUCT(($P$14:$Z$14="CO5")*(P18:Z18)*MOD(COLUMN($P$14:$Z$14)-COLUMN($P$14)+1,2)) ) -> 16 | AG18: =SUMIF($E$14:$N$14,"CO6",$E$17:$N$17) + IF(O18>0, SUMPRODUCT(($O$14:$Z$14="CO6")*($O$17:$Z$17)*MOD(COLUMN($O$14:$Z$14)-COLUMN($O$14)+1,2))+ SUMPRODUCT(($P$14:$Z$14="CO6")*($P$17:$Z$17)*MOD(COLUMN($P$14:$Z$14)-COLUMN($P$14)+1,2)) ) -> 0 | AH18: =SUM(AB18:AG18) -> 70 | AI18: =AB18/(SUMIF($E$14:$N$14,"CO1",$E$13:$N$13)+SUMPRODUCT(($O$14:$Z$14="CO1")*($O18:$Z18>0)*($O$13:$Z$13)))*100 -> 66.666667 | AJ18: =AC18/(SUMIF($E$14:$N$14,"CO2",$E$13:$N$13)+SUMPRODUCT(($O$14:$Z$14="CO2")*($O18:$Z18>0)*($O$13:$Z$13)))*100 -> 80 | AK18: =AD18/(SUMIF($E$14:$N$14,"CO3",$E$13:$N$13)+SUMPRODUCT(($O$14:$Z$14="CO3")*($O18:$Z18>0)*($O$13:$Z$13)))*100 -> 73.333333 | AL18: =AE18/(SUMIF($E$14:$N$14,"CO4",$E$13:$N$13)+SUMPRODUCT(($O$14:$Z$14="CO4")*($O18:$Z18>0)*($O$13:$Z$13)))*100 -> 76.923077 | AM18: =AF18/(SUMIF($E$14:$N$14,"CO5",$E$13:$N$13)+SUMPRODUCT(($O$14:$Z$14="CO5")*($O18:$Z18>0)*($O$13:$Z$13)))*100 -> 57.142857 | AN18: =AG18/(SUMIF($E$14:$N$14,"CO5",$E$13:$N$13)+SUMPRODUCT(($O$14:$Z$14="CO5")*($O18:$Z18>0)*($O$13:$Z$13)))*100 -> 0
A19: 3 | B19: ='STUDENT NAMELIST'!B7 -> 2023PEC AI 101 | C19: ='STUDENT NAMELIST'!C7 -> 211423243003 | D19: ='STUDENT NAMELIST'!D7 -> ABINAYA M | E19: 2 | F19: 2 | G19: 2 | H19: 2 | I19: 2 | J19: 2 | K19: 2 | L19: 2 | M19: 1 | N19: 0 | O19: 12 | P19: 0 | Q19: 0 | R19: 12 | S19: 11 | T19: 0 | U19: 12 | V19: 0 | W19: 0 | X19: 8 | Y19: 13 | Z19: 0 | AA19: =SUM(E19,F19,G19,H19,I19,J19,K19,L19,M19,N19,O19,P19,Q19,R19,S19,T19,U19,V19,W19,X19,Y19,Z19) -> 85 | AB19: =SUMIF($E$14:$N$14,"CO1",E19:N19)+IF(O19>=0,SUMPRODUCT(($O$14:$Z$14="CO1")*(O19:Z19)*MOD(COLUMN($O$14:$Z$14)-COLUMN($O$14)+1,2))+SUMPRODUCT(($P$14:$Z$14="CO1")*(P19:Z19)*MOD(COLUMN($P$14:$Z$14)-COLUMN($P$14)+1,2))) -> 6 | AC19: =SUMIF($E$14:$N$14,"CO2",E19:N19)+IF(O19>=0,SUMPRODUCT(($O$14:$Z$14="CO2")*(O19:Z19)*MOD(COLUMN($O$14:$Z$14)-COLUMN($O$14)+1,2))+SUMPRODUCT(($P$14:$Z$14="CO2")*(Q19:AA19)*MOD(COLUMN($P$14:$Z$14)-COLUMN($P$14)+1,2))) -> 20 | AD19: =SUMIF($E$14:$N$14,"CO3",E19:N19)+IF(O19>=0, SUMPRODUCT(($O$14:$Z$14="CO3")*(O19:Z19)*MOD(COLUMN($O$14:$Z$14)-COLUMN($O$14)+1,2))+ SUMPRODUCT(($P$14:$Z$14="CO3")*(P19:Z19)*MOD(COLUMN($P$14:$Z$14)-COLUMN($P$14)+1,2))) -> 27 | AE19: =SUMIF($E$14:$N$14,"CO4",$E$17:$N$17) + IF(O19>=0, SUMPRODUCT(($O$14:$Z$14="CO4")*(O19:Z19)*MOD(COLUMN($O$14:$Z$14)-COLUMN($O$14)+1,2))+ SUMPRODUCT(($P$14:$Z$14="CO4")*(P19:Z19)*MOD(COLUMN($P$14:$Z$14)-COLUMN($P$14)+1,2))) -> 11 | AF19: =SUMIF($E$14:$N$14,"CO5",$E$17:$N$17) + IF(O19>=0, SUMPRODUCT(($O$14:$Z$14="CO5")*(O19:Z19)*MOD(COLUMN($O$14:$Z$14)-COLUMN($O$14)+1,2))+ SUMPRODUCT(($P$14:$Z$14="CO5")*(P19:Z19)*MOD(COLUMN($P$14:$Z$14)-COLUMN($P$14)+1,2)) ) -> 21 | AG19: =SUMIF($E$14:$N$14,"CO6",$E$17:$N$17) + IF(O19>0, SUMPRODUCT(($O$14:$Z$14="CO6")*($O$17:$Z$17)*MOD(COLUMN($O$14:$Z$14)-COLUMN($O$14)+1,2))+ SUMPRODUCT(($P$14:$Z$14="CO6")*($P$17:$Z$17)*MOD(COLUMN($P$14:$Z$14)-COLUMN($P$14)+1,2)) ) -> 0 | AH19: =SUM(AB19:AG19) -> 85 | AI19: =AB19/(SUMIF($E$14:$N$14,"CO1",$E$13:$N$13)+SUMPRODUCT(($O$14:$Z$14="CO1")*($O19:$Z19>0)*($O$13:$Z$13)))*100 -> 100 | AJ19: =AC19/(SUMIF($E$14:$N$14,"CO2",$E$13:$N$13)+SUMPRODUCT(($O$14:$Z$14="CO2")*($O19:$Z19>0)*($O$13:$Z$13)))*100 -> 86.956522 | AK19: =AD19/(SUMIF($E$14:$N$14,"CO3",$E$13:$N$13)+SUMPRODUCT(($O$14:$Z$14="CO3")*($O19:$Z19>0)*($O$13:$Z$13)))*100 -> 90 | AL19: =AE19/(SUMIF($E$14:$N$14,"CO4",$E$13:$N$13)+SUMPRODUCT(($O$14:$Z$14="CO4")*($O19:$Z19>0)*($O$13:$Z$13)))*100 -> 84.615385 | AM19: =AF19/(SUMIF($E$14:$N$14,"CO5",$E$13:$N$13)+SUMPRODUCT(($O$14:$Z$14="CO5")*($O19:$Z19>0)*($O$13:$Z$13)))*100 -> 75 | AN19: =AG19/(SUMIF($E$14:$N$14,"CO5",$E$13:$N$13)+SUMPRODUCT(($O$14:$Z$14="CO5")*($O19:$Z19>0)*($O$13:$Z$13)))*100 -> 0
A20: 4 | B20: ='STUDENT NAMELIST'!B8 -> 2023PEC AI 543 | C20: ='STUDENT NAMELIST'!C8 -> 211423243004 | D20: ='STUDENT NAMELIST'!D8 -> ABINESH KUMAR T | E20: 2 | F20: 2 | G20: 2 | H20: 2 | I20: 2 | J20: 2 | K20: 0 | L20: 0 | M20: 0 | N20: 0 | O20: 0 | P20: 8 | Q20: 9 | R20: 0 | S20: 0 | T20: 9 | U20: 0 | V20: 9 | W20: 4 | X20: 0 | Y20: 0 | Z20: 9 | AA20: =SUM(E20,F20,G20,H20,I20,J20,K20,L20,M20,N20,O20,P20,Q20,R20,S20,T20,U20,V20,W20,X20,Y20,Z20) -> 60 | AB20: =SUMIF($E$14:$N$14,"CO1",E20:N20)+IF(O20>=0,SUMPRODUCT(($O$14:$Z$14="CO1")*(O20:Z20)*MOD(COLUMN($O$14:$Z$14)-COLUMN($O$14)+1,2))+SUMPRODUCT(($P$14:$Z$14="CO1")*(P20:Z20)*MOD(COLUMN($P$14:$Z$14)-COLUMN($P$14)+1,2))) -> 2 | AC20: =SUMIF($E$14:$N$14,"CO2",E20:N20)+IF(O20>=0,SUMPRODUCT(($O$14:$Z$14="CO2")*(O20:Z20)*MOD(COLUMN($O$14:$Z$14)-COLUMN($O$14)+1,2))+SUMPRODUCT(($P$14:$Z$14="CO2")*(Q20:AA20)*MOD(COLUMN($P$14:$Z$14)-COLUMN($P$14)+1,2))) -> 8 | AD20: =SUMIF($E$14:$N$14,"CO3",E20:N20)+IF(O20>=0, SUMPRODUCT(($O$14:$Z$14="CO3")*(O20:Z20)*MOD(COLUMN($O$14:$Z$14)-COLUMN($O$14)+1,2))+ SUMPRODUCT(($P$14:$Z$14="CO3")*(P20:Z20)*MOD(COLUMN($P$14:$Z$14)-COLUMN($P$14)+1,2))) -> 19 | AE20: =SUMIF($E$14:$N$14,"CO4",$E$17:$N$17) + IF(O20>=0, SUMPRODUCT(($O$14:$Z$14="CO4")*(O20:Z20)*MOD(COLUMN($O$14:$Z$14)-COLUMN($O$14)+1,2))+ SUMPRODUCT(($P$14:$Z$14="CO4")*(P20:Z20)*MOD(COLUMN($P$14:$Z$14)-COLUMN($P$14)+1,2))) -> 18 | AF20: =SUMIF($E$14:$N$14,"CO5",$E$17:$N$17) + IF(O20>=0, SUMPRODUCT(($O$14:$Z$14="CO5")*(O20:Z20)*MOD(COLUMN($O$14:$Z$14)-COLUMN($O$14)+1,2))+ SUMPRODUCT(($P$14:$Z$14="CO5")*(P20:Z20)*MOD(COLUMN($P$14:$Z$14)-COLUMN($P$14)+1,2)) ) -> 13 | AG20: =SUMIF($E$14:$N$14,"CO6",$E$17:$N$17) + IF(O20>0, SUMPRODUCT(($O$14:$Z$14="CO6")*($O$17:$Z$17)*MOD(COLUMN($O$14:$Z$14)-COLUMN($O$14)+1,2))+ SUMPRODUCT(($P$14:$Z$14="CO6")*($P$17:$Z$17)*MOD(COLUMN($P$14:$Z$14)-COLUMN($P$14)+1,2)) ) -> 0 | AH20: =SUM(AB20:AG20) -> 60 | AI20: =AB20/(SUMIF($E$14:$N$14,"CO1",$E$13:$N$13)+SUMPRODUCT(($O$14:$Z$14="CO1")*($O20:$Z20>0)*($O$13:$Z$13)))*100 -> 33.333333 | AJ20: =AC20/(SUMIF($E$14:$N$14,"CO2",$E$13:$N$13)+SUMPRODUCT(($O$14:$Z$14="CO2")*($O20:$Z20>0)*($O$13:$Z$13)))*100 -> 80 | AK20: =AD20/(SUMIF($E$14:$N$14,"CO3",$E$13:$N$13)+SUMPRODUCT(($O$14:$Z$14="CO3")*($O20:$Z20>0)*($O$13:$Z$13)))*100 -> 63.333333 | AL20: =AE20/(SUMIF($E$14:$N$14,"CO4",$E$13:$N$13)+SUMPRODUCT(($O$14:$Z$14="CO4")*($O20:$Z20>0)*($O$13:$Z$13)))*100 -> 69.230769 | AM20: =AF20/(SUMIF($E$14:$N$14,"CO5",$E$13:$N$13)+SUMPRODUCT(($O$14:$Z$14="CO5")*($O20:$Z20>0)*($O$13:$Z$13)))*100 -> 46.428571 | AN20: =AG20/(SUMIF($E$14:$N$14,"CO5",$E$13:$N$13)+SUMPRODUCT(($O$14:$Z$14="CO5")*($O20:$Z20>0)*($O$13:$Z$13)))*100 -> 0
A21: 5 | B21: ='STUDENT NAMELIST'!B9 -> 2023PEC AI 102 | C21: ='STUDENT NAMELIST'!C9 -> 211423243005 | D21: ='STUDENT NAMELIST'!D9 -> ABIRAMI A | E21: 2 | F21: 2 | G21: 2 | H21: 2 | I21: 2 | J21: 2 | K21: 2 | L21: 2 | M21: 2 | N21: 1 | O21: 13 | P21: 0 | Q21: 0 | R21: 13 | S21: 12 | T21: 0 | U21: 13 | V21: 0 | W21: 0 | X21: 11 | Y21: 14 | Z21: 0 | AA21: =SUM(E21,F21,G21,H21,I21,J21,K21,L21,M21,N21,O21,P21,Q21,R21,S21,T21,U21,V21,W21,X21,Y21,Z21) -> 95 | AB21: =SUMIF($E$14:$N$14,"CO1",E21:N21)+IF(O21>=0,SUMPRODUCT(($O$14:$Z$14="CO1")*(O21:Z21)*MOD(COLUMN($O$14:$Z$14)-COLUMN($O$14)+1,2))+SUMPRODUCT(($P$14:$Z$14="CO1")*(P21:Z21)*MOD(COLUMN($P$14:$Z$14)-COLUMN($P$14)+1,2))) -> 6 | AC21: =SUMIF($E$14:$N$14,"CO2",E21:N21)+IF(O21>=0,SUMPRODUCT(($O$14:$Z$14="CO2")*(O21:Z21)*MOD(COLUMN($O$14:$Z$14)-COLUMN($O$14)+1,2))+SUMPRODUCT(($P$14:$Z$14="CO2")*(Q21:AA21)*MOD(COLUMN($P$14:$Z$14)-COLUMN($P$14)+1,2))) -> 22 | AD21: =SUMIF($E$14:$N$14,"CO3",E21:N21)+IF(O21>=0, SUMPRODUCT(($O$14:$Z$14="CO3")*(O21:Z21)*MOD(COLUMN($O$14:$Z$14)-COLUMN($O$14)+1,2))+ SUMPRODUCT(($P$14:$Z$14="CO3")*(P21:Z21)*MOD(COLUMN($P$14:$Z$14)-COLUMN($P$14)+1,2))) -> 30 | AE21: =SUMIF($E$14:$N$14,"CO4",$E$17:$N$17) + IF(O21>=0, SUMPRODUCT(($O$14:$Z$14="CO4")*(O21:Z21)*MOD(COLUMN($O$14:$Z$14)-COLUMN($O$14)+1,2))+ SUMPRODUCT(($P$14:$Z$14="CO4")*(P21:Z21)*MOD(COLUMN($P$14:$Z$14)-COLUMN($P$14)+1,2))) -> 12 | AF21: =SUMIF($E$14:$N$14,"CO5",$E$17:$N$17) + IF(O21>=0, SUMPRODUCT(($O$14:$Z$14="CO5")*(O21:Z21)*MOD(COLUMN($O$14:$Z$14)-COLUMN($O$14)+1,2))+ SUMPRODUCT(($P$14:$Z$14="CO5")*(P21:Z21)*MOD(COLUMN($P$14:$Z$14)-COLUMN($P$14)+1,2)) ) -> 25 | AG21: =SUMIF($E$14:$N$14,"CO6",$E$17:$N$17) + IF(O21>0, SUMPRODUCT(($O$14:$Z$14="CO6")*($O$17:$Z$17)*MOD(COLUMN($O$14:$Z$14)-COLUMN($O$14)+1,2))+ SUMPRODUCT(($P$14:$Z$14="CO6")*($P$17:$Z$17)*MOD(COLUMN($P$14:$Z$14)-COLUMN($P$14)+1,2)) ) -> 0 | AH21: =SUM(AB21:AG21) -> 95 | AI21: =AB21/(SUMIF($E$14:$N$14,"CO1",$E$13:$N$13)+SUMPRODUCT(($O$14:$Z$14="CO1")*($O21:$Z21>0)*($O$13:$Z$13)))*100 -> 100 | AJ21: =AC21/(SUMIF($E$14:$N$14,"CO2",$E$13:$N$13)+SUMPRODUCT(($O$14:$Z$14="CO2")*($O21:$Z21>0)*($O$13:$Z$13)))*100 -> 95.652174 | AK21: =AD21/(SUMIF($E$14:$N$14,"CO3",$E$13:$N$13)+SUMPRODUCT(($O$14:$Z$14="CO3")*($O21:$Z21>0)*($O$13:$Z$13)))*100 -> 100 | AL21: =AE21/(SUMIF($E$14:$N$14,"CO4",$E$13:$N$13)+SUMPRODUCT(($O$14:$Z$14="CO4")*($O21:$Z21>0)*($O$13:$Z$13)))*100 -> 92.307692 | AM21: =AF21/(SUMIF($E$14:$N$14,"CO5",$E$13:$N$13)+SUMPRODUCT(($O$14:$Z$14="CO5")*($O21:$Z21>0)*($O$13:$Z$13)))*100 -> 89.285714 | AN21: =AG21/(SUMIF($E$14:$N$14,"CO5",$E$13:$N$13)+SUMPRODUCT(($O$14:$Z$14="CO5")*($O21:$Z21>0)*($O$13:$Z$13)))*100 -> 0
A22: 6 | B22: ='STUDENT NAMELIST'!B10 -> 2023PEC AI 103 | C22: ='STUDENT NAMELIST'!C10 -> 211423243006 | D22: ='STUDENT NAMELIST'!D10 -> ABIRAMI G | E22: 2 | F22: 2 | G22: 2 | H22: 2 | I22: 2 | J22: 2 | K22: 0 | L22: 0 | M22: 0 | N22: 0 | O22: 0 | P22: 9 | Q22: 9 | R22: 0 | S22: 0 | T22: 9 | U22: 0 | V22: 9 | W22: 5 | X22: 0 | Y22: 0 | Z22: 9 | AA22: =SUM(E22,F22,G22,H22,I22,J22,K22,L22,M22,N22,O22,P22,Q22,R22,S22,T22,U22,V22,W22,X22,Y22,Z22) -> 62 | AB22: =SUMIF($E$14:$N$14,"CO1",E22:N22)+IF(O22>=0,SUMPRODUCT(($O$14:$Z$14="CO1")*(O22:Z22)*MOD(COLUMN($O$14:$Z$14)-COLUMN($O$14)+1,2))+SUMPRODUCT(($P$14:$Z$14="CO1")*(P22:Z22)*MOD(COLUMN($P$14:$Z$14)-COLUMN($P$14)+1,2))) -> 2 | AC22: =SUMIF($E$14:$N$14,"CO2",E22:N22)+IF(O22>=0,SUMPRODUCT(($O$14:$Z$14="CO2")*(O22:Z22)*MOD(COLUMN($O$14:$Z$14)-COLUMN($O$14)+1,2))+SUMPRODUCT(($P$14:$Z$14="CO2")*(Q22:AA22)*MOD(COLUMN($P$14:$Z$14)-COLUMN($P$14)+1,2))) -> 8 | AD22: =SUMIF($E$14:$N$14,"CO3",E22:N22)+IF(O22>=0, SUMPRODUCT(($O$14:$Z$14="CO3")*(O22:Z22)*MOD(COLUMN($O$14:$Z$14)-COLUMN($O$14)+1,2))+ SUMPRODUCT(($P$14:$Z$14="CO3")*(P22:Z22)*MOD(COLUMN($P$14:$Z$14)-COLUMN($P$14)+1,2))) -> 20 | AE22: =SUMIF($E$14:$N$14,"CO4",$E$17:$N$17) + IF(O22>=0, SUMPRODUCT(($O$14:$Z$14="CO4")*(O22:Z22)*MOD(COLUMN($O$14:$Z$14)-COLUMN($O$14)+1,2))+ SUMPRODUCT(($P$14:$Z$14="CO4")*(P22:Z22)*MOD(COLUMN($P$14:$Z$14)-COLUMN($P$14)+1,2))) -> 18 | AF22: =SUMIF($E$14:$N$14,"CO5",$E$17:$N$17) + IF(O22>=0, SUMPRODUCT(($O$14:$Z$14="CO5")*(O22:Z22)*MOD(COLUMN($O$14:$Z$14)-COLUMN($O$14)+1,2))+ SUMPRODUCT(($P$14:$Z$14="CO5")*(P22:Z22)*MOD(COLUMN($P$14:$Z$14)-COLUMN($P$14)+1,2)) ) -> 14 | AG22: =SUMIF($E$14:$N$14,"CO6",$E$17:$N$17) + IF(O22>0, SUMPRODUCT(($O$14:$Z$14="CO6")*($O$17:$Z$17)*MOD(COLUMN($O$14:$Z$14)-COLUMN($O$14)+1,2))+ SUMPRODUCT(($P$14:$Z$14="CO6")*($P$17:$Z$17)*MOD(COLUMN($P$14:$Z$14)-COLUMN($P$14)+1,2)) ) -> 0 | AH22: =SUM(AB22:AG22) -> 62 | AI22: =AB22/(SUMIF($E$14:$N$14,"CO1",$E$13:$N$13)+SUMPRODUCT(($O$14:$Z$14="CO1")*($O22:$Z22>0)*($O$13:$Z$13)))*100 -> 33.333333 | AJ22: =AC22/(SUMIF($E$14:$N$14,"CO2",$E$13:$N$13)+SUMPRODUCT(($O$14:$Z$14="CO2")*($O22:$Z22>0)*($O$13:$Z$13)))*100 -> 80 | AK22: =AD22/(SUMIF($E$14:$N$14,"CO3",$E$13:$N$13)+SUMPRODUCT(($O$14:$Z$14="CO3")*($O22:$Z22>0)*($O$13:$Z$13)))*100 -> 66.666667 | AL22: =AE22/(SUMIF($E$14:$N$14,"CO4",$E$13:$N$13)+SUMPRODUCT(($O$14:$Z$14="CO4")*($O22:$Z22>0)*($O$13:$Z$13)))*100 -> 69.230769 | AM22: =AF22/(SUMIF($E$14:$N$14,"CO5",$E$13:$N$13)+SUMPRODUCT(($O$14:$Z$14="CO5")*($O22:$Z22>0)*($O$13:$Z$13)))*100 -> 50 | AN22: =AG22/(SUMIF($E$14:$N$14,"CO5",$E$13:$N$13)+SUMPRODUCT(($O$14:$Z$14="CO5")*($O22:$Z22>0)*($O$13:$Z$13)))*100 -> 0
A23: 7 | B23: ='STUDENT NAMELIST'!B11 -> 2023PEC AI 544 | C23: ='STUDENT NAMELIST'!C11 -> 211423243007 | D23: ='STUDENT NAMELIST'!D11 -> ABISHAI SINGH J | E23: 2 | F23: 2 | G23: 2 | H23: 2 | I23: 2 | J23: 1 | K23: 0 | L23: 0 | M23: 0 | N23: 0 | O23: 8 | P23: 0 | Q23: 0 | R23: 8 | S23: 7 | T23: 0 | U23: 8 | V23: 0 | W23: 0 | X23: 6 | Y23: 8 | Z23: 0 | AA23: =SUM(E23,F23,G23,H23,I23,J23,K23,L23,M23,N23,O23,P23,Q23,R23,S23,T23,U23,V23,W23,X23,Y23,Z23) -> 56 | AB23: =SUMIF($E$14:$N$14,"CO1",E23:N23)+IF(O23>=0,SUMPRODUCT(($O$14:$Z$14="CO1")*(O23:Z23)*MOD(COLUMN($O$14:$Z$14)-COLUMN($O$14)+1,2))+SUMPRODUCT(($P$14:$Z$14="CO1")*(P23:Z23)*MOD(COLUMN($P$14:$Z$14)-COLUMN($P$14)+1,2))) -> 2 | AC23: =SUMIF($E$14:$N$14,"CO2",E23:N23)+IF(O23>=0,SUMPRODUCT(($O$14:$Z$14="CO2")*(O23:Z23)*MOD(COLUMN($O$14:$Z$14)-COLUMN($O$14)+1,2))+SUMPRODUCT(($P$14:$Z$14="CO2")*(Q23:AA23)*MOD(COLUMN($P$14:$Z$14)-COLUMN($P$14)+1,2))) -> 15 | AD23: =SUMIF($E$14:$N$14,"CO3",E23:N23)+IF(O23>=0, SUMPRODUCT(($O$14:$Z$14="CO3")*(O23:Z23)*MOD(COLUMN($O$14:$Z$14)-COLUMN($O$14)+1,2))+ SUMPRODUCT(($P$14:$Z$14="CO3")*(P23:Z23)*MOD(COLUMN($P$14:$Z$14)-COLUMN($P$14)+1,2))) -> 18 | AE23: =SUMIF($E$14:$N$14,"CO4",$E$17:$N$17) + IF(O23>=0, SUMPRODUCT(($O$14:$Z$14="CO4")*(O23:Z23)*MOD(COLUMN($O$14:$Z$14)-COLUMN($O$14)+1,2))+ SUMPRODUCT(($P$14:$Z$14="CO4")*(P23:Z23)*MOD(COLUMN($P$14:$Z$14)-COLUMN($P$14)+1,2))) -> 7 | AF23: =SUMIF($E$14:$N$14,"CO5",$E$17:$N$17) + IF(O23>=0, SUMPRODUCT(($O$14:$Z$14="CO5")*(O23:Z23)*MOD(COLUMN($O$14:$Z$14)-COLUMN($O$14)+1,2))+ SUMPRODUCT(($P$14:$Z$14="CO5")*(P23:Z23)*MOD(COLUMN($P$14:$Z$14)-COLUMN($P$14)+1,2)) ) -> 14 | AG23: =SUMIF($E$14:$N$14,"CO6",$E$17:$N$17) + IF(O23>0, SUMPRODUCT(($O$14:$Z$14="CO6")*($O$17:$Z$17)*MOD(COLUMN($O$14:$Z$14)-COLUMN($O$14)+1,2))+ SUMPRODUCT(($P$14:$Z$14="CO6")*($P$17:$Z$17)*MOD(COLUMN($P$14:$Z$14)-COLUMN($P$14)+1,2)) ) -> 0 | AH23: =SUM(AB23:AG23) -> 56 | AI23: =AB23/(SUMIF($E$14:$N$14,"CO1",$E$13:$N$13)+SUMPRODUCT(($O$14:$Z$14="CO1")*($O23:$Z23>0)*($O$13:$Z$13)))*100 -> 33.333333 | AJ23: =AC23/(SUMIF($E$14:$N$14,"CO2",$E$13:$N$13)+SUMPRODUCT(($O$14:$Z$14="CO2")*($O23:$Z23>0)*($O$13:$Z$13)))*100 -> 65.217391 | AK23: =AD23/(SUMIF($E$14:$N$14,"CO3",$E$13:$N$13)+SUMPRODUCT(($O$14:$Z$14="CO3")*($O23:$Z23>0)*($O$13:$Z$13)))*100 -> 60 | AL23: =AE23/(SUMIF($E$14:$N$14,"CO4",$E$13:$N$13)+SUMPRODUCT(($O$14:$Z$14="CO4")*($O23:$Z23>0)*($O$13:$Z$13)))*100 -> 53.846154 | AM23: =AF23/(SUMIF($E$14:$N$14,"CO5",$E$13:$N$13)+SUMPRODUCT(($O$14:$Z$14="CO5")*($O23:$Z23>0)*($O$13:$Z$13)))*100 -> 50 | AN23: =AG23/(SUMIF($E$14:$N$14,"CO5",$E$13:$N$13)+SUMPRODUCT(($O$14:$Z$14="CO5")*($O23:$Z23>0)*($O$13:$Z$13)))*100 -> 0
A24: 8 | B24: ='STUDENT NAMELIST'!B12 -> 2023PEC AI 545 | C24: ='STUDENT NAMELIST'!C12 -> 211423243008 | D24: ='STUDENT NAMELIST'!D12 -> ABISHEK RANGARAJ M | E24: 2 | F24: 2 | G24: 2 | H24: 0 | I24: 0 | J24: 0 | K24: 0 | L24: 0 | M24: 0 | N24: 0 | O24: 0 | P24: 4 | Q24: 5 | R24: 0 | S24: 0 | T24: 5 | U24: 0 | V24: 5 | W24: 0 | X24: 0 | Y24: 0 | Z24: 5 | AA24: =SUM(E24,F24,G24,H24,I24,J24,K24,L24,M24,N24,O24,P24,Q24,R24,S24,T24,U24,V24,W24,X24,Y24,Z24) -> 30 | AB24: =SUMIF($E$14:$N$14,"CO1",E24:N24)+IF(O24>=0,SUMPRODUCT(($O$14:$Z$14="CO1")*(O24:Z24)*MOD(COLUMN($O$14:$Z$14)-COLUMN($O$14)+1,2))+SUMPRODUCT(($P$14:$Z$14="CO1")*(P24:Z24)*MOD(COLUMN($P$14:$Z$14)-COLUMN($P$14)+1,2))) -> 2 | AC24: =SUMIF($E$14:$N$14,"CO2",E24:N24)+IF(O24>=0,SUMPRODUCT(($O$14:$Z$14="CO2")*(O24:Z24)*MOD(COLUMN($O$14:$Z$14)-COLUMN($O$14)+1,2))+SUMPRODUCT(($P$14:$Z$14="CO2")*(Q24:AA24)*MOD(COLUMN($P$14:$Z$14)-COLUMN($P$14)+1,2))) -> 4 | AD24: =SUMIF($E$14:$N$14,"CO3",E24:N24)+IF(O24>=0, SUMPRODUCT(($O$14:$Z$14="CO3")*(O24:Z24)*MOD(COLUMN($O$14:$Z$14)-COLUMN($O$14)+1,2))+ SUMPRODUCT(($P$14:$Z$14="CO3")*(P24:Z24)*MOD(COLUMN($P$14:$Z$14)-COLUMN($P$14)+1,2))) -> 9 | AE24: =SUMIF($E$14:$N$14,"CO4",$E$17:$N$17) + IF(O24>=0, SUMPRODUCT(($O$14:$Z$14="CO4")*(O24:Z24)*MOD(COLUMN($O$14:$Z$14)-COLUMN($O$14)+1,2))+ SUMPRODUCT(($P$14:$Z$14="CO4")*(P24:Z24)*MOD(COLUMN($P$14:$Z$14)-COLUMN($P$14)+1,2))) -> 10 | AF24: 10 | AG24: =SUMIF($E$14:$N$14,"CO6",$E$17:$N$17) + IF(O24>0, SUMPRODUCT(($O$14:$Z$14="CO6")*($O$17:$Z$17)*MOD(COLUMN($O$14:$Z$14)-COLUMN($O$14)+1,2))+ SUMPRODUCT(($P$14:$Z$14="CO6")*($P$17:$Z$17)*MOD(COLUMN($P$14:$Z$14)-COLUMN($P$14)+1,2)) ) -> 0 | AH24: =SUM(AB24:AG24) -> 35 | AI24: =AB24/(SUMIF($E$14:$N$14,"CO1",$E$13:$N$13)+SUMPRODUCT(($O$14:$Z$14="CO1")*($O24:$Z24>0)*($O$13:$Z$13)))*100 -> 33.333333 | AJ24: =AC24/(SUMIF($E$14:$N$14,"CO2",$E$13:$N$13)+SUMPRODUCT(($O$14:$Z$14="CO2")*($O24:$Z24>0)*($O$13:$Z$13)))*100 -> 40 | AK24: =AD24/(SUMIF($E$14:$N$14,"CO3",$E$13:$N$13)+SUMPRODUCT(($O$14:$Z$14="CO3")*($O24:$Z24>0)*($O$13:$Z$13)))*100 -> 30 | AL24: =AE24/(SUMIF($E$14:$N$14,"CO4",$E$13:$N$13)+SUMPRODUCT(($O$14:$Z$14="CO4")*($O24:$Z24>0)*($O$13:$Z$13)))*100 -> 38.461538 | AM24: =AF24/(SUMIF($E$14:$N$14,"CO5",$E$13:$N$13)+SUMPRODUCT(($O$14:$Z$14="CO5")*($O24:$Z24>0)*($O$13:$Z$13)))*100 -> 66.666667 | AN24: =AG24/(SUMIF($E$14:$N$14,"CO5",$E$13:$N$13)+SUMPRODUCT(($O$14:$Z$14="CO5")*($O24:$Z24>0)*($O$13:$Z$13)))*100 -> 0
A25: 9 | B25: ='STUDENT NAMELIST'!B13 -> 2023PEC AI 104 | C25: ='STUDENT NAMELIST'!C13 -> 211423243009 | D25: ='STUDENT NAMELIST'!D13 -> ABITHA R D | E25: 2 | F25: 2 | G25: 2 | H25: 2 | I25: 2 | J25: 2 | K25: 2 | L25: 2 | M25: 2 | N25: 1 | O25: 13 | P25: 0 | Q25: 0 | R25: 13 | S25: 12 | T25: 0 | U25: 13 | V25: 0 | W25: 0 | X25: 9 | Y25: 14 | Z25: 0 | AA25: =SUM(E25,F25,G25,H25,I25,J25,K25,L25,M25,N25,O25,P25,Q25,R25,S25,T25,U25,V25,W25,X25,Y25,Z25) -> 93 | AB25: =SUMIF($E$14:$N$14,"CO1",E25:N25)+IF(O25>=0,SUMPRODUCT(($O$14:$Z$14="CO1")*(O25:Z25)*MOD(COLUMN($O$14:$Z$14)-COLUMN($O$14)+1,2))+SUMPRODUCT(($P$14:$Z$14="CO1")*(P25:Z25)*MOD(COLUMN($P$14:$Z$14)-COLUMN($P$14)+1,2))) -> 6 | AC25: =SUMIF($E$14:$N$14,"CO2",E25:N25)+IF(O25>=0,SUMPRODUCT(($O$14:$Z$14="CO2")*(O25:Z25)*MOD(COLUMN($O$14:$Z$14)-COLUMN($O$14)+1,2))+SUMPRODUCT(($P$14:$Z$14="CO2")*(Q25:AA25)*MOD(COLUMN($P$14:$Z$14)-COLUMN($P$14)+1,2))) -> 22 | AD25: =SUMIF($E$14:$N$14,"CO3",E25:N25)+IF(O25>=0, SUMPRODUCT(($O$14:$Z$14="CO3")*(O25:Z25)*MOD(COLUMN($O$14:$Z$14)-COLUMN($O$14)+1,2))+ SUMPRODUCT(($P$14:$Z$14="CO3")*(P25:Z25)*MOD(COLUMN($P$14:$Z$14)-COLUMN($P$14)+1,2))) -> 30 | AE25: =SUMIF($E$14:$N$14,"CO4",$E$17:$N$17) + IF(O25>=0, SUMPRODUCT(($O$14:$Z$14="CO4")*(O25:Z25)*MOD(COLUMN($O$14:$Z$14)-COLUMN($O$14)+1,2))+ SUMPRODUCT(($P$14:$Z$14="CO4")*(P25:Z25)*MOD(COLUMN($P$14:$Z$14)-COLUMN($P$14)+1,2))) -> 12 | AF25: =SUMIF($E$14:$N$14,"CO5",$E$17:$N$17) + IF(O25>=0, SUMPRODUCT(($O$14:$Z$14="CO5")*(O25:Z25)*MOD(COLUMN($O$14:$Z$14)-COLUMN($O$14)+1,2))+ SUMPRODUCT(($P$14:$Z$14="CO5")*(P25:Z25)*MOD(COLUMN($P$14:$Z$14)-COLUMN($P$14)+1,2)) ) -> 23 | AG25: =SUMIF($E$14:$N$14,"CO6",$E$17:$N$17) + IF(O25>0, SUMPRODUCT(($O$14:$Z$14="CO6")*($O$17:$Z$17)*MOD(COLUMN($O$14:$Z$14)-COLUMN($O$14)+1,2))+ SUMPRODUCT(($P$14:$Z$14="CO6")*($P$17:$Z$17)*MOD(COLUMN($P$14:$Z$14)-COLUMN($P$14)+1,2)) ) -> 0 | AH25: =SUM(AB25:AG25) -> 93 | AI25: =AB25/(SUMIF($E$14:$N$14,"CO1",$E$13:$N$13)+SUMPRODUCT(($O$14:$Z$14="CO1")*($O25:$Z25>0)*($O$13:$Z$13)))*100 -> 100 | AJ25: =AC25/(SUMIF($E$14:$N$14,"CO2",$E$13:$N$13)+SUMPRODUCT(($O$14:$Z$14="CO2")*($O25:$Z25>0)*($O$13:$Z$13)))*100 -> 95.652174 | AK25: =AD25/(SUMIF($E$14:$N$14,"CO3",$E$13:$N$13)+SUMPRODUCT(($O$14:$Z$14="CO3")*($O25:$Z25>0)*($O$13:$Z$13)))*100 -> 100 | AL25: =AE25/(SUMIF($E$14:$N$14,"CO4",$E$13:$N$13)+SUMPRODUCT(($O$14:$Z$14="CO4")*($O25:$Z25>0)*($O$13:$Z$13)))*100 -> 92.307692 | AM25: =AF25/(SUMIF($E$14:$N$14,"CO5",$E$13:$N$13)+SUMPRODUCT(($O$14:$Z$14="CO5")*($O25:$Z25>0)*($O$13:$Z$13)))*100 -> 82.142857 | AN25: =AG25/(SUMIF($E$14:$N$14,"CO5",$E$13:$N$13)+SUMPRODUCT(($O$14:$Z$14="CO5")*($O25:$Z25>0)*($O$13:$Z$13)))*100 -> 0
A26: 10 | B26: ='STUDENT NAMELIST'!B14 -> 2023PEC AI 546 | C26: ='STUDENT NAMELIST'!C14 -> 211423243010 | D26: ='STUDENT NAMELIST'!D14 -> ABRAHAM S J | E26: 2 | F26: 2 | G26: 2 | H26: 2 | I26: 2 | J26: 0 | K26: 0 | L26: 0 | M26: 0 | N26: 0 | O26: 0 | P26: 7 | Q26: 7 | R26: 0 | S26: 0 | T26: 7 | U26: 0 | V26: 7 | W26: 4 | X26: 0 | Y26: 0 | Z26: 8 | AA26: =SUM(E26,F26,G26,H26,I26,J26,K26,L26,M26,N26,O26,P26,Q26,R26,S26,T26,U26,V26,W26,X26,Y26,Z26) -> 50 | AB26: =SUMIF($E$14:$N$14,"CO1",E26:N26)+IF(O26>=0,SUMPRODUCT(($O$14:$Z$14="CO1")*(O26:Z26)*MOD(COLUMN($O$14:$Z$14)-COLUMN($O$14)+1,2))+SUMPRODUCT(($P$14:$Z$14="CO1")*(P26:Z26)*MOD(COLUMN($P$14:$Z$14)-COLUMN($P$14)+1,2))) -> 2 | AC26: =SUMIF($E$14:$N$14,"CO2",E26:N26)+IF(O26>=0,SUMPRODUCT(($O$14:$Z$14="CO2")*(O26:Z26)*MOD(COLUMN($O$14:$Z$14)-COLUMN($O$14)+1,2))+SUMPRODUCT(($P$14:$Z$14="CO2")*(Q26:AA26)*MOD(COLUMN($P$14:$Z$14)-COLUMN($P$14)+1,2))) -> 6 | AD26: =SUMIF($E$14:$N$14,"CO3",E26:N26)+IF(O26>=0, SUMPRODUCT(($O$14:$Z$14="CO3")*(O26:Z26)*MOD(COLUMN($O$14:$Z$14)-COLUMN($O$14)+1,2))+ SUMPRODUCT(($P$14:$Z$14="CO3")*(P26:Z26)*MOD(COLUMN($P$14:$Z$14)-COLUMN($P$14)+1,2))) -> 16 | AE26: =SUMIF($E$14:$N$14,"CO4",$E$17:$N$17) + IF(O26>=0, SUMPRODUCT(($O$14:$Z$14="CO4")*(O26:Z26)*MOD(COLUMN($O$14:$Z$14)-COLUMN($O$14)+1,2))+ SUMPRODUCT(($P$14:$Z$14="CO4")*(P26:Z26)*MOD(COLUMN($P$14:$Z$14)-COLUMN($P$14)+1,2))) -> 14 | AF26: =SUMIF($E$14:$N$14,"CO5",$E$17:$N$17) + IF(O26>=0, SUMPRODUCT(($O$14:$Z$14="CO5")*(O26:Z26)*MOD(COLUMN($O$14:$Z$14)-COLUMN($O$14)+1,2))+ SUMPRODUCT(($P$14:$Z$14="CO5")*(P26:Z26)*MOD(COLUMN($P$14:$Z$14)-COLUMN($P$14)+1,2)) ) -> 12 | AG26: =SUMIF($E$14:$N$14,"CO6",$E$17:$N$17) + IF(O26>0, SUMPRODUCT(($O$14:$Z$14="CO6")*($O$17:$Z$17)*MOD(COLUMN($O$14:$Z$14)-COLUMN($O$14)+1,2))+ SUMPRODUCT(($P$14:$Z$14="CO6")*($P$17:$Z$17)*MOD(COLUMN($P$14:$Z$14)-COLUMN($P$14)+1,2)) ) -> 0 | AH26: =SUM(AB26:AG26) -> 50 | AI26: =AB26/(SUMIF($E$14:$N$14,"CO1",$E$13:$N$13)+SUMPRODUCT(($O$14:$Z$14="CO1")*($O26:$Z26>0)*($O$13:$Z$13)))*100 -> 33.333333 | AJ26: =AC26/(SUMIF($E$14:$N$14,"CO2",$E$13:$N$13)+SUMPRODUCT(($O$14:$Z$14="CO2")*($O26:$Z26>0)*($O$13:$Z$13)))*100 -> 60 | AK26: =AD26/(SUMIF($E$14:$N$14,"CO3",$E$13:$N$13)+SUMPRODUCT(($O$14:$Z$14="CO3")*($O26:$Z26>0)*($O$13:$Z$13)))*100 -> 53.333333 | AL26: =AE26/(SUMIF($E$14:$N$14,"CO4",$E$13:$N$13)+SUMPRODUCT(($O$14:$Z$14="CO4")*($O26:$Z26>0)*($O$13:$Z$13)))*100 -> 53.846154 | AM26: =AF26/(SUMIF($E$14:$N$14,"CO5",$E$13:$N$13)+SUMPRODUCT(($O$14:$Z$14="CO5")*($O26:$Z26>0)*($O$13:$Z$13)))*100 -> 42.857143 | AN26: =AG26/(SUMIF($E$14:$N$14,"CO5",$E$13:$N$13)+SUMPRODUCT(($O$14:$Z$14="CO5")*($O26:$Z26>0)*($O$13:$Z$13)))*100 -> 0
A27: 11 | B27: ='STUDENT NAMELIST'!B15 -> 2023PEC AI 105 | C27: ='STUDENT NAMELIST'!C15 -> 211423243011 | D27: ='STUDENT NAMELIST'!D15 -> ADELINE JERUSHA AUGUSTINE | E27: 2 | F27: 2 | G27: 2 | H27: 2 | I27: 2 | J27: 2 | K27: 2 | L27: 1 | M27: 0 | N27: 0 | O27: 11 | P27: 0 | Q27: 0 | R27: 11 | S27: 9 | T27: 0 | U27: 11 | V27: 0 | W27: 0 | X27: 7 | Y27: 11 | Z27: 0 | AA27: =SUM(E27,F27,G27,H27,I27,J27,K27,L27,M27,N27,O27,P27,Q27,R27,S27,T27,U27,V27,W27,X27,Y27,Z27) -> 75 | AB27: =SUMIF($E$14:$N$14,"CO1",E27:N27)+IF(O27>=0,SUMPRODUCT(($O$14:$Z$14="CO1")*(O27:Z27)*MOD(COLUMN($O$14:$Z$14)-COLUMN($O$14)+1,2))+SUMPRODUCT(($P$14:$Z$14="CO1")*(P27:Z27)*MOD(COLUMN($P$14:$Z$14)-COLUMN($P$14)+1,2))) -> 5 | AC27: =SUMIF($E$14:$N$14,"CO2",E27:N27)+IF(O27>=0,SUMPRODUCT(($O$14:$Z$14="CO2")*(O27:Z27)*MOD(COLUMN($O$14:$Z$14)-COLUMN($O$14)+1,2))+SUMPRODUCT(($P$14:$Z$14="CO2")*(Q27:AA27)*MOD(COLUMN($P$14:$Z$14)-COLUMN($P$14)+1,2))) -> 19 | AD27: =SUMIF($E$14:$N$14,"CO3",E27:N27)+IF(O27>=0, SUMPRODUCT(($O$14:$Z$14="CO3")*(O27:Z27)*MOD(COLUMN($O$14:$Z$14)-COLUMN($O$14)+1,2))+ SUMPRODUCT(($P$14:$Z$14="CO3")*(P27:Z27)*MOD(COLUMN($P$14:$Z$14)-COLUMN($P$14)+1,2))) -> 24 | AE27: =SUMIF($E$14:$N$14,"CO4",$E$17:$N$17) + IF(O27>=0, SUMPRODUCT(($O$14:$Z$14="CO4")*(O27:Z27)*MOD(COLUMN($O$14:$Z$14)-COLUMN($O$14)+1,2))+ SUMPRODUCT(($P$14:$Z$14="CO4")*(P27:Z27)*MOD(COLUMN($P$14:$Z$14)-COLUMN($P$14)+1,2))) -> 9 | AF27: =SUMIF($E$14:$N$14,"CO5",$E$17:$N$17) + IF(O27>=0, SUMPRODUCT(($O$14:$Z$14="CO5")*(O27:Z27)*MOD(COLUMN($O$14:$Z$14)-COLUMN($O$14)+1,2))+ SUMPRODUCT(($P$14:$Z$14="CO5")*(P27:Z27)*MOD(COLUMN($P$14:$Z$14)-COLUMN($P$14)+1,2)) ) -> 18 | AG27: =SUMIF($E$14:$N$14,"CO6",$E$17:$N$17) + IF(O27>0, SUMPRODUCT(($O$14:$Z$14="CO6")*($O$17:$Z$17)*MOD(COLUMN($O$14:$Z$14)-COLUMN($O$14)+1,2))+ SUMPRODUCT(($P$14:$Z$14="CO6")*($P$17:$Z$17)*MOD(COLUMN($P$14:$Z$14)-COLUMN($P$14)+1,2)) ) -> 0 | AH27: =SUM(AB27:AG27) -> 75 | AI27: =AB27/(SUMIF($E$14:$N$14,"CO1",$E$13:$N$13)+SUMPRODUCT(($O$14:$Z$14="CO1")*($O27:$Z27>0)*($O$13:$Z$13)))*100 -> 83.333333 | AJ27: =AC27/(SUMIF($E$14:$N$14,"CO2",$E$13:$N$13)+SUMPRODUCT(($O$14:$Z$14="CO2")*($O27:$Z27>0)*($O$13:$Z$13)))*100 -> 82.608696 | AK27: =AD27/(SUMIF($E$14:$N$14,"CO3",$E$13:$N$13)+SUMPRODUCT(($O$14:$Z$14="CO3")*($O27:$Z27>0)*($O$13:$Z$13)))*100 -> 80 | AL27: =AE27/(SUMIF($E$14:$N$14,"CO4",$E$13:$N$13)+SUMPRODUCT(($O$14:$Z$14="CO4")*($O27:$Z27>0)*($O$13:$Z$13)))*100 -> 69.230769 | AM27: =AF27/(SUMIF($E$14:$N$14,"CO5",$E$13:$N$13)+SUMPRODUCT(($O$14:$Z$14="CO5")*($O27:$Z27>0)*($O$13:$Z$13)))*100 -> 64.285714 | AN27: =AG27/(SUMIF($E$14:$N$14,"CO5",$E$13:$N$13)+SUMPRODUCT(($O$14:$Z$14="CO5")*($O27:$Z27>0)*($O$13:$Z$13)))*100 -> 0
A28: 12 | B28: ='STUDENT NAMELIST'!B16 -> 2023PEC AI 547 | C28: ='STUDENT NAMELIST'!C16 -> 211423243012 | D28: ='STUDENT NAMELIST'!D16 -> ADHINARAYANAN A | E28: 2 | F28: 2 | G28: 2 | H28: 0 | I28: 0 | J28: 0 | K28: 0 | L28: 0 | M28: 0 | N28: 0 | O28: 0 | P28: 4 | Q28: 5 | R28: 0 | S28: 0 | T28: 5 | U28: 0 | V28: 5 | W28: 0 | X28: 0 | Y28: 0 | Z28: 5 | AA28: =SUM(E28,F28,G28,H28,I28,J28,K28,L28,M28,N28,O28,P28,Q28,R28,S28,T28,U28,V28,W28,X28,Y28,Z28) -> 30 | AB28: =SUMIF($E$14:$N$14,"CO1",E28:N28)+IF(O28>=0,SUMPRODUCT(($O$14:$Z$14="CO1")*(O28:Z28)*MOD(COLUMN($O$14:$Z$14)-COLUMN($O$14)+1,2))+SUMPRODUCT(($P$14:$Z$14="CO1")*(P28:Z28)*MOD(COLUMN($P$14:$Z$14)-COLUMN($P$14)+1,2))) -> 2 | AC28: =SUMIF($E$14:$N$14,"CO2",E28:N28)+IF(O28>=0,SUMPRODUCT(($O$14:$Z$14="CO2")*(O28:Z28)*MOD(COLUMN($O$14:$Z$14)-COLUMN($O$14)+1,2))+SUMPRODUCT(($P$14:$Z$14="CO2")*(Q28:AA28)*MOD(COLUMN($P$14:$Z$14)-COLUMN($P$14)+1,2))) -> 4 | AD28: =SUMIF($E$14:$N$14,"CO3",E28:N28)+IF(O28>=0, SUMPRODUCT(($O$14:$Z$14="CO3")*(O28:Z28)*MOD(COLUMN($O$14:$Z$14)-COLUMN($O$14)+1,2))+ SUMPRODUCT(($P$14:$Z$14="CO3")*(P28:Z28)*MOD(COLUMN($P$14:$Z$14)-COLUMN($P$14)+1,2))) -> 9 | AE28: =SUMIF($E$14:$N$14,"CO4",$E$17:$N$17) + IF(O28>=0, SUMPRODUCT(($O$14:$Z$14="CO4")*(O28:Z28)*MOD(COLUMN($O$14:$Z$14)-COLUMN($O$14)+1,2))+ SUMPRODUCT(($P$14:$Z$14="CO4")*(P28:Z28)*MOD(COLUMN($P$14:$Z$14)-COLUMN($P$14)+1,2))) -> 10 | AF28: =SUMIF($E$14:$N$14,"CO5",$E$17:$N$17) + IF(O28>=0, SUMPRODUCT(($O$14:$Z$14="CO5")*(O28:Z28)*MOD(COLUMN($O$14:$Z$14)-COLUMN($O$14)+1,2))+ SUMPRODUCT(($P$14:$Z$14="CO5")*(P28:Z28)*MOD(COLUMN($P$14:$Z$14)-COLUMN($P$14)+1,2)) ) -> 5 | AG28: =SUMIF($E$14:$N$14,"CO6",$E$17:$N$17) + IF(O28>0, SUMPRODUCT(($O$14:$Z$14="CO6")*($O$17:$Z$17)*MOD(COLUMN($O$14:$Z$14)-COLUMN($O$14)+1,2))+ SUMPRODUCT(($P$14:$Z$14="CO6")*($P$17:$Z$17)*MOD(COLUMN($P$14:$Z$14)-COLUMN($P$14)+1,2)) ) -> 0 | AH28: =SUM(AB28:AG28) -> 30 | AI28: =AB28/(SUMIF($E$14:$N$14,"CO1",$E$13:$N$13)+SUMPRODUCT(($O$14:$Z$14="CO1")*($O28:$Z28>0)*($O$13:$Z$13)))*100 -> 33.333333 | AJ28: =AC28/(SUMIF($E$14:$N$14,"CO2",$E$13:$N$13)+SUMPRODUCT(($O$14:$Z$14="CO2")*($O28:$Z28>0)*($O$13:$Z$13)))*100 -> 40 | AK28: =AD28/(SUMIF($E$14:$N$14,"CO3",$E$13:$N$13)+SUMPRODUCT(($O$14:$Z$14="CO3")*($O28:$Z28>0)*($O$13:$Z$13)))*100 -> 30 | AL28: =AE28/(SUMIF($E$14:$N$14,"CO4",$E$13:$N$13)+SUMPRODUCT(($O$14:$Z$14="CO4")*($O28:$Z28>0)*($O$13:$Z$13)))*100 -> 38.461538 | AM28: =AF28/(SUMIF($E$14:$N$14,"CO5",$E$13:$N$13)+SUMPRODUCT(($O$14:$Z$14="CO5")*($O28:$Z28>0)*($O$13:$Z$13)))*100 -> 33.333333 | AN28: =AG28/(SUMIF($E$14:$N$14,"CO5",$E$13:$N$13)+SUMPRODUCT(($O$14:$Z$14="CO5")*($O28:$Z28>0)*($O$13:$Z$13)))*100 -> 0
A29: 13 | B29: ='STUDENT NAMELIST'!B17 -> 2023PEC AI 548 | C29: ='STUDENT NAMELIST'!C17 -> 211423243013 | D29: ='STUDENT NAMELIST'!D17 -> ADHITYAN R | E29: 2 | F29: 2 | G29: 2 | H29: 2 | I29: 2 | J29: 0 | K29: 0 | L29: 0 | M29: 0 | N29: 0 | O29: 8 | P29: 0 | Q29: 0 | R29: 8 | S29: 7 | T29: 0 | U29: 8 | V29: 0 | W29: 0 | X29: 2 | Y29: 8 | Z29: 0 | AA29: =SUM(E29,F29,G29,H29,I29,J29,K29,L29,M29,N29,O29,P29,Q29,R29,S29,T29,U29,V29,W29,X29,Y29,Z29) -> 51 | AB29: =SUMIF($E$14:$N$14,"CO1",E29:N29)+IF(O29>=0,SUMPRODUCT(($O$14:$Z$14="CO1")*(O29:Z29)*MOD(COLUMN($O$14:$Z$14)-COLUMN($O$14)+1,2))+SUMPRODUCT(($P$14:$Z$14="CO1")*(P29:Z29)*MOD(COLUMN($P$14:$Z$14)-COLUMN($P$14)+1,2))) -> 2 | AC29: =SUMIF($E$14:$N$14,"CO2",E29:N29)+IF(O29>=0,SUMPRODUCT(($O$14:$Z$14="CO2")*(O29:Z29)*MOD(COLUMN($O$14:$Z$14)-COLUMN($O$14)+1,2))+SUMPRODUCT(($P$14:$Z$14="CO2")*(Q29:AA29)*MOD(COLUMN($P$14:$Z$14)-COLUMN($P$14)+1,2))) -> 14 | AD29: =SUMIF($E$14:$N$14,"CO3",E29:N29)+IF(O29>=0, SUMPRODUCT(($O$14:$Z$14="CO3")*(O29:Z29)*MOD(COLUMN($O$14:$Z$14)-COLUMN($O$14)+1,2))+ SUMPRODUCT(($P$14:$Z$14="CO3")*(P29:Z29)*MOD(COLUMN($P$14:$Z$14)-COLUMN($P$14)+1,2))) -> 18 | AE29: =SUMIF($E$14:$N$14,"CO4",$E$17:$N$17) + IF(O29>=0, SUMPRODUCT(($O$14:$Z$14="CO4")*(O29:Z29)*MOD(COLUMN($O$14:$Z$14)-COLUMN($O$14)+1,2))+ SUMPRODUCT(($P$14:$Z$14="CO4")*(P29:Z29)*MOD(COLUMN($P$14:$Z$14)-COLUMN($P$14)+1,2))) -> 7 | AF29: =SUMIF($E$14:$N$14,"CO5",$E$17:$N$17) + IF(O29>=0, SUMPRODUCT(($O$14:$Z$14="CO5")*(O29:Z29)*MOD(COLUMN($O$14:$Z$14)-COLUMN($O$14)+1,2))+ SUMPRODUCT(($P$14:$Z$14="CO5")*(P29:Z29)*MOD(COLUMN($P$14:$Z$14)-COLUMN($P$14)+1,2)) ) -> 10 | AG29: =SUMIF($E$14:$N$14,"CO6",$E$17:$N$17) + IF(O29>0, SUMPRODUCT(($O$14:$Z$14="CO6")*($O$17:$Z$17)*MOD(COLUMN($O$14:$Z$14)-COLUMN($O$14)+1,2))+ SUMPRODUCT(($P$14:$Z$14="CO6")*($P$17:$Z$17)*MOD(COLUMN($P$14:$Z$14)-COLUMN($P$14)+1,2)) ) -> 0 | AH29: =SUM(AB29:AG29) -> 51 | AI29: =AB29/(SUMIF($E$14:$N$14,"CO1",$E$13:$N$13)+SUMPRODUCT(($O$14:$Z$14="CO1")*($O29:$Z29>0)*($O$13:$Z$13)))*100 -> 33.333333 | AJ29: =AC29/(SUMIF($E$14:$N$14,"CO2",$E$13:$N$13)+SUMPRODUCT(($O$14:$Z$14="CO2")*($O29:$Z29>0)*($O$13:$Z$13)))*100 -> 60.869565 | AK29: =AD29/(SUMIF($E$14:$N$14,"CO3",$E$13:$N$13)+SUMPRODUCT(($O$14:$Z$14="CO3")*($O29:$Z29>0)*($O$13:$Z$13)))*100 -> 60 | AL29: =AE29/(SUMIF($E$14:$N$14,"CO4",$E$13:$N$13)+SUMPRODUCT(($O$14:$Z$14="CO4")*($O29:$Z29>0)*($O$13:$Z$13)))*100 -> 53.846154 | AM29: =AF29/(SUMIF($E$14:$N$14,"CO5",$E$13:$N$13)+SUMPRODUCT(($O$14:$Z$14="CO5")*($O29:$Z29>0)*($O$13:$Z$13)))*100 -> 35.714286 | AN29: =AG29/(SUMIF($E$14:$N$14,"CO5",$E$13:$N$13)+SUMPRODUCT(($O$14:$Z$14="CO5")*($O29:$Z29>0)*($O$13:$Z$13)))*100 -> 0
A30: 14 | B30: ='STUDENT NAMELIST'!B18 -> 2023PEC AI 106 | C30: ='STUDENT NAMELIST'!C18 -> 211423243014 | D30: ='STUDENT NAMELIST'!D18 -> AFIFA FATHIMA S | E30: 2 | F30: 2 | G30: 2 | H30: 2 | I30: 2 | J30: 2 | K30: 2 | L30: 2 | M30: 2 | N30: 1 | O30: 0 | P30: 13 | Q30: 13 | R30: 0 | S30: 0 | T30: 13 | U30: 0 | V30: 13 | W30: 8 | X30: 0 | Y30: 0 | Z30: 14 | AA30: =SUM(E30,F30,G30,H30,I30,J30,K30,L30,M30,N30,O30,P30,Q30,R30,S30,T30,U30,V30,W30,X30,Y30,Z30) -> 93 | AB30: =SUMIF($E$14:$N$14,"CO1",E30:N30)+IF(O30>=0,SUMPRODUCT(($O$14:$Z$14="CO1")*(O30:Z30)*MOD(COLUMN($O$14:$Z$14)-COLUMN($O$14)+1,2))+SUMPRODUCT(($P$14:$Z$14="CO1")*(P30:Z30)*MOD(COLUMN($P$14:$Z$14)-COLUMN($P$14)+1,2))) -> 6 | AC30: =SUMIF($E$14:$N$14,"CO2",E30:N30)+IF(O30>=0,SUMPRODUCT(($O$14:$Z$14="CO2")*(O30:Z30)*MOD(COLUMN($O$14:$Z$14)-COLUMN($O$14)+1,2))+SUMPRODUCT(($P$14:$Z$14="CO2")*(Q30:AA30)*MOD(COLUMN($P$14:$Z$14)-COLUMN($P$14)+1,2))) -> 9 | AD30: =SUMIF($E$14:$N$14,"CO3",E30:N30)+IF(O30>=0, SUMPRODUCT(($O$14:$Z$14="CO3")*(O30:Z30)*MOD(COLUMN($O$14:$Z$14)-COLUMN($O$14)+1,2))+ SUMPRODUCT(($P$14:$Z$14="CO3")*(P30:Z30)*MOD(COLUMN($P$14:$Z$14)-COLUMN($P$14)+1,2))) -> 30 | AE30: =SUMIF($E$14:$N$14,"CO4",$E$17:$N$17) + IF(O30>=0, SUMPRODUCT(($O$14:$Z$14="CO4")*(O30:Z30)*MOD(COLUMN($O$14:$Z$14)-COLUMN($O$14)+1,2))+ SUMPRODUCT(($P$14:$Z$14="CO4")*(P30:Z30)*MOD(COLUMN($P$14:$Z$14)-COLUMN($P$14)+1,2))) -> 26 | AF30: =SUMIF($E$14:$N$14,"CO5",$E$17:$N$17) + IF(O30>=0, SUMPRODUCT(($O$14:$Z$14="CO5")*(O30:Z30)*MOD(COLUMN($O$14:$Z$14)-COLUMN($O$14)+1,2))+ SUMPRODUCT(($P$14:$Z$14="CO5")*(P30:Z30)*MOD(COLUMN($P$14:$Z$14)-COLUMN($P$14)+1,2)) ) -> 22 | AG30: =SUMIF($E$14:$N$14,"CO6",$E$17:$N$17) + IF(O30>0, SUMPRODUCT(($O$14:$Z$14="CO6")*($O$17:$Z$17)*MOD(COLUMN($O$14:$Z$14)-COLUMN($O$14)+1,2))+ SUMPRODUCT(($P$14:$Z$14="CO6")*($P$17:$Z$17)*MOD(COLUMN($P$14:$Z$14)-COLUMN($P$14)+1,2)) ) -> 0 | AH30: =SUM(AB30:AG30) -> 93 | AI30: =AB30/(SUMIF($E$14:$N$14,"CO1",$E$13:$N$13)+SUMPRODUCT(($O$14:$Z$14="CO1")*($O30:$Z30>0)*($O$13:$Z$13)))*100 -> 100 | AJ30: =AC30/(SUMIF($E$14:$N$14,"CO2",$E$13:$N$13)+SUMPRODUCT(($O$14:$Z$14="CO2")*($O30:$Z30>0)*($O$13:$Z$13)))*100 -> 90 | AK30: =AD30/(SUMIF($E$14:$N$14,"CO3",$E$13:$N$13)+SUMPRODUCT(($O$14:$Z$14="CO3")*($O30:$Z30>0)*($O$13:$Z$13)))*100 -> 100 | AL30: =AE30/(SUMIF($E$14:$N$14,"CO4",$E$13:$N$13)+SUMPRODUCT(($O$14:$Z$14="CO4")*($O30:$Z30>0)*($O$13:$Z$13)))*100 -> 100 | AM30: =AF30/(SUMIF($E$14:$N$14,"CO5",$E$13:$N$13)+SUMPRODUCT(($O$14:$Z$14="CO5")*($O30:$Z30>0)*($O$13:$Z$13)))*100 -> 78.571429 | AN30: =AG30/(SUMIF($E$14:$N$14,"CO5",$E$13:$N$13)+SUMPRODUCT(($O$14:$Z$14="CO5")*($O30:$Z30>0)*($O$13:$Z$13)))*100 -> 0
A31: 15 | B31: ='STUDENT NAMELIST'!B19 -> 2023PEC AI 549 | C31: ='STUDENT NAMELIST'!C19 -> 211423243015 | D31: ='STUDENT NAMELIST'!D19 -> AFRIN W A | E31: 2 | F31: 2 | G31: 2 | H31: 0 | I31: 0 | J31: 0 | K31: 0 | L31: 0 | M31: 0 | N31: 0 | O31: 5 | P31: 0 | Q31: 0 | R31: 5 | S31: 4 | T31: 0 | U31: 5 | V31: 0 | W31: 0 | X31: 0 | Y31: 5 | Z31: 0 | AA31: =SUM(E31,F31,G31,H31,I31,J31,K31,L31,M31,N31,O31,P31,Q31,R31,S31,T31,U31,V31,W31,X31,Y31,Z31) -> 30 | AB31: =SUMIF($E$14:$N$14,"CO1",E31:N31)+IF(O31>=0,SUMPRODUCT(($O$14:$Z$14="CO1")*(O31:Z31)*MOD(COLUMN($O$14:$Z$14)-COLUMN($O$14)+1,2))+SUMPRODUCT(($P$14:$Z$14="CO1")*(P31:Z31)*MOD(COLUMN($P$14:$Z$14)-COLUMN($P$14)+1,2))) -> 2 | AC31: =SUMIF($E$14:$N$14,"CO2",E31:N31)+IF(O31>=0,SUMPRODUCT(($O$14:$Z$14="CO2")*(O31:Z31)*MOD(COLUMN($O$14:$Z$14)-COLUMN($O$14)+1,2))+SUMPRODUCT(($P$14:$Z$14="CO2")*(Q31:AA31)*MOD(COLUMN($P$14:$Z$14)-COLUMN($P$14)+1,2))) -> 9 | AD31: =SUMIF($E$14:$N$14,"CO3",E31:N31)+IF(O31>=0, SUMPRODUCT(($O$14:$Z$14="CO3")*(O31:Z31)*MOD(COLUMN($O$14:$Z$14)-COLUMN($O$14)+1,2))+ SUMPRODUCT(($P$14:$Z$14="CO3")*(P31:Z31)*MOD(COLUMN($P$14:$Z$14)-COLUMN($P$14)+1,2))) -> 10 | AE31: =SUMIF($E$14:$N$14,"CO4",$E$17:$N$17) + IF(O31>=0, SUMPRODUCT(($O$14:$Z$14="CO4")*(O31:Z31)*MOD(COLUMN($O$14:$Z$14)-COLUMN($O$14)+1,2))+ SUMPRODUCT(($P$14:$Z$14="CO4")*(P31:Z31)*MOD(COLUMN($P$14:$Z$14)-COLUMN($P$14)+1,2))) -> 4 | AF31: =SUMIF($E$14:$N$14,"CO5",$E$17:$N$17) + IF(O31>=0, SUMPRODUCT(($O$14:$Z$14="CO5")*(O31:Z31)*MOD(COLUMN($O$14:$Z$14)-COLUMN($O$14)+1,2))+ SUMPRODUCT(($P$14:$Z$14="CO5")*(P31:Z31)*MOD(COLUMN($P$14:$Z$14)-COLUMN($P$14)+1,2)) ) -> 5 | AG31: =SUMIF($E$14:$N$14,"CO6",$E$17:$N$17) + IF(O31>0, SUMPRODUCT(($O$14:$Z$14="CO6")*($O$17:$Z$17)*MOD(COLUMN($O$14:$Z$14)-COLUMN($O$14)+1,2))+ SUMPRODUCT(($P$14:$Z$14="CO6")*($P$17:$Z$17)*MOD(COLUMN($P$14:$Z$14)-COLUMN($P$14)+1,2)) ) -> 0 | AH31: =SUM(AB31:AG31) -> 30 | AI31: =AB31/(SUMIF($E$14:$N$14,"CO1",$E$13:$N$13)+SUMPRODUCT(($O$14:$Z$14="CO1")*($O31:$Z31>0)*($O$13:$Z$13)))*100 -> 33.333333 | AJ31: =AC31/(SUMIF($E$14:$N$14,"CO2",$E$13:$N$13)+SUMPRODUCT(($O$14:$Z$14="CO2")*($O31:$Z31>0)*($O$13:$Z$13)))*100 -> 39.130435 | AK31: =AD31/(SUMIF($E$14:$N$14,"CO3",$E$13:$N$13)+SUMPRODUCT(($O$14:$Z$14="CO3")*($O31:$Z31>0)*($O$13:$Z$13)))*100 -> 33.333333 | AL31: =AE31/(SUMIF($E$14:$N$14,"CO4",$E$13:$N$13)+SUMPRODUCT(($O$14:$Z$14="CO4")*($O31:$Z31>0)*($O$13:$Z$13)))*100 -> 30.769231 | AM31: =AF31/(SUMIF($E$14:$N$14,"CO5",$E$13:$N$13)+SUMPRODUCT(($O$14:$Z$14="CO5")*($O31:$Z31>0)*($O$13:$Z$13)))*100 -> 33.333333 | AN31: =AG31/(SUMIF($E$14:$N$14,"CO5",$E$13:$N$13)+SUMPRODUCT(($O$14:$Z$14="CO5")*($O31:$Z31>0)*($O$13:$Z$13)))*100 -> 0
A32: 16 | B32: ='STUDENT NAMELIST'!B20 -> 2023PEC AI 107 | C32: ='STUDENT NAMELIST'!C20 -> 211423243016 | D32: ='STUDENT NAMELIST'!D20 -> AFSHAN TAJ F | E32: 2 | F32: 2 | G32: 2 | H32: 2 | I32: 2 | J32: 2 | K32: 2 | L32: 2 | M32: 1 | N32: 0 | O32: 0 | P32: 11 | Q32: 12 | R32: 0 | S32: 0 | T32: 12 | U32: 0 | V32: 12 | W32: 7 | X32: 0 | Y32: 0 | Z32: 12 | AA32: =SUM(E32,F32,G32,H32,I32,J32,K32,L32,M32,N32,O32,P32,Q32,R32,S32,T32,U32,V32,W32,X32,Y32,Z32) -> 83 | AB32: =SUMIF($E$14:$N$14,"CO1",E32:N32)+IF(O32>=0,SUMPRODUCT(($O$14:$Z$14="CO1")*(O32:Z32)*MOD(COLUMN($O$14:$Z$14)-COLUMN($O$14)+1,2))+SUMPRODUCT(($P$14:$Z$14="CO1")*(P32:Z32)*MOD(COLUMN($P$14:$Z$14)-COLUMN($P$14)+1,2))) -> 6 | AC32: =SUMIF($E$14:$N$14,"CO2",E32:N32)+IF(O32>=0,SUMPRODUCT(($O$14:$Z$14="CO2")*(O32:Z32)*MOD(COLUMN($O$14:$Z$14)-COLUMN($O$14)+1,2))+SUMPRODUCT(($P$14:$Z$14="CO2")*(Q32:AA32)*MOD(COLUMN($P$14:$Z$14)-COLUMN($P$14)+1,2))) -> 8 | AD32: =SUMIF($E$14:$N$14,"CO3",E32:N32)+IF(O32>=0, SUMPRODUCT(($O$14:$Z$14="CO3")*(O32:Z32)*MOD(COLUMN($O$14:$Z$14)-COLUMN($O$14)+1,2))+ SUMPRODUCT(($P$14:$Z$14="CO3")*(P32:Z32)*MOD(COLUMN($P$14:$Z$14)-COLUMN($P$14)+1,2))) -> 26 | AE32: =SUMIF($E$14:$N$14,"CO4",$E$17:$N$17) + IF(O32>=0, SUMPRODUCT(($O$14:$Z$14="CO4")*(O32:Z32)*MOD(COLUMN($O$14:$Z$14)-COLUMN($O$14)+1,2))+ SUMPRODUCT(($P$14:$Z$14="CO4")*(P32:Z32)*MOD(COLUMN($P$14:$Z$14)-COLUMN($P$14)+1,2))) -> 24 | AF32: =SUMIF($E$14:$N$14,"CO5",$E$17:$N$17) + IF(O32>=0, SUMPRODUCT(($O$14:$Z$14="CO5")*(O32:Z32)*MOD(COLUMN($O$14:$Z$14)-COLUMN($O$14)+1,2))+ SUMPRODUCT(($P$14:$Z$14="CO5")*(P32:Z32)*MOD(COLUMN($P$14:$Z$14)-COLUMN($P$14)+1,2)) ) -> 19 | AG32: =SUMIF($E$14:$N$14,"CO6",$E$17:$N$17) + IF(O32>0, SUMPRODUCT(($O$14:$Z$14="CO6")*($O$17:$Z$17)*MOD(COLUMN($O$14:$Z$14)-COLUMN($O$14)+1,2))+ SUMPRODUCT(($P$14:$Z$14="CO6")*($P$17:$Z$17)*MOD(COLUMN($P$14:$Z$14)-COLUMN($P$14)+1,2)) ) -> 0 | AH32: =SUM(AB32:AG32) -> 83 | AI32: =AB32/(SUMIF($E$14:$N$14,"CO1",$E$13:$N$13)+SUMPRODUCT(($O$14:$Z$14="CO1")*($O32:$Z32>0)*($O$13:$Z$13)))*100 -> 100 | AJ32: =AC32/(SUMIF($E$14:$N$14,"CO2",$E$13:$N$13)+SUMPRODUCT(($O$14:$Z$14="CO2")*($O32:$Z32>0)*($O$13:$Z$13)))*100 -> 80 | AK32: =AD32/(SUMIF($E$14:$N$14,"CO3",$E$13:$N$13)+SUMPRODUCT(($O$14:$Z$14="CO3")*($O32:$Z32>0)*($O$13:$Z$13)))*100 -> 86.666667 | AL32: =AE32/(SUMIF($E$14:$N$14,"CO4",$E$13:$N$13)+SUMPRODUCT(($O$14:$Z$14="CO4")*($O32:$Z32>0)*($O$13:$Z$13)))*100 -> 92.307692 | AM32: =AF32/(SUMIF($E$14:$N$14,"CO5",$E$13:$N$13)+SUMPRODUCT(($O$14:$Z$14="CO5")*($O32:$Z32>0)*($O$13:$Z$13)))*100 -> 67.857143 | AN32: =AG32/(SUMIF($E$14:$N$14,"CO5",$E$13:$N$13)+SUMPRODUCT(($O$14:$Z$14="CO5")*($O32:$Z32>0)*($O$13:$Z$13)))*100 -> 0
A33: 17 | B33: ='STUDENT NAMELIST'!B21 -> 2023PEC AI 108 | C33: ='STUDENT NAMELIST'!C21 -> 211423243017 | D33: ='STUDENT NAMELIST'!D21 -> AISHWARYA P | E33: 2 | F33: 2 | G33: 2 | H33: 2 | I33: 2 | J33: 2 | K33: 2 | L33: 2 | M33: 1 | N33: 0 | O33: 13 | P33: 0 | Q33: 0 | R33: 13 | S33: 11 | T33: 0 | U33: 13 | V33: 0 | W33: 0 | X33: 7 | Y33: 13 | Z33: 0 | AA33: =SUM(E33,F33,G33,H33,I33,J33,K33,L33,M33,N33,O33,P33,Q33,R33,S33,T33,U33,V33,W33,X33,Y33,Z33) -> 87 | AB33: =SUMIF($E$14:$N$14,"CO1",E33:N33)+IF(O33>=0,SUMPRODUCT(($O$14:$Z$14="CO1")*(O33:Z33)*MOD(COLUMN($O$14:$Z$14)-COLUMN($O$14)+1,2))+SUMPRODUCT(($P$14:$Z$14="CO1")*(P33:Z33)*MOD(COLUMN($P$14:$Z$14)-COLUMN($P$14)+1,2))) -> 6 | AC33: =SUMIF($E$14:$N$14,"CO2",E33:N33)+IF(O33>=0,SUMPRODUCT(($O$14:$Z$14="CO2")*(O33:Z33)*MOD(COLUMN($O$14:$Z$14)-COLUMN($O$14)+1,2))+SUMPRODUCT(($P$14:$Z$14="CO2")*(Q33:AA33)*MOD(COLUMN($P$14:$Z$14)-COLUMN($P$14)+1,2))) -> 21 | AD33: =SUMIF($E$14:$N$14,"CO3",E33:N33)+IF(O33>=0, SUMPRODUCT(($O$14:$Z$14="CO3")*(O33:Z33)*MOD(COLUMN($O$14:$Z$14)-COLUMN($O$14)+1,2))+ SUMPRODUCT(($P$14:$Z$14="CO3")*(P33:Z33)*MOD(COLUMN($P$14:$Z$14)-COLUMN($P$14)+1,2))) -> 29 | AE33: =SUMIF($E$14:$N$14,"CO4",$E$17:$N$17) + IF(O33>=0, SUMPRODUCT(($O$14:$Z$14="CO4")*(O33:Z33)*MOD(COLUMN($O$14:$Z$14)-COLUMN($O$14)+1,2))+ SUMPRODUCT(($P$14:$Z$14="CO4")*(P33:Z33)*MOD(COLUMN($P$14:$Z$14)-COLUMN($P$14)+1,2))) -> 11 | AF33: =SUMIF($E$14:$N$14,"CO5",$E$17:$N$17) + IF(O33>=0, SUMPRODUCT(($O$14:$Z$14="CO5")*(O33:Z33)*MOD(COLUMN($O$14:$Z$14)-COLUMN($O$14)+1,2))+ SUMPRODUCT(($P$14:$Z$14="CO5")*(P33:Z33)*MOD(COLUMN($P$14:$Z$14)-COLUMN($P$14)+1,2)) ) -> 20 | AG33: =SUMIF($E$14:$N$14,"CO6",$E$17:$N$17) + IF(O33>0, SUMPRODUCT(($O$14:$Z$14="CO6")*($O$17:$Z$17)*MOD(COLUMN($O$14:$Z$14)-COLUMN($O$14)+1,2))+ SUMPRODUCT(($P$14:$Z$14="CO6")*($P$17:$Z$17)*MOD(COLUMN($P$14:$Z$14)-COLUMN($P$14)+1,2)) ) -> 0 | AH33: =SUM(AB33:AG33) -> 87 | AI33: =AB33/(SUMIF($E$14:$N$14,"CO1",$E$13:$N$13)+SUMPRODUCT(($O$14:$Z$14="CO1")*($O33:$Z33>0)*($O$13:$Z$13)))*100 -> 100 | AJ33: =AC33/(SUMIF($E$14:$N$14,"CO2",$E$13:$N$13)+SUMPRODUCT(($O$14:$Z$14="CO2")*($O33:$Z33>0)*($O$13:$Z$13)))*100 -> 91.304348 | AK33: =AD33/(SUMIF($E$14:$N$14,"CO3",$E$13:$N$13)+SUMPRODUCT(($O$14:$Z$14="CO3")*($O33:$Z33>0)*($O$13:$Z$13)))*100 -> 96.666667 | AL33: =AE33/(SUMIF($E$14:$N$14,"CO4",$E$13:$N$13)+SUMPRODUCT(($O$14:$Z$14="CO4")*($O33:$Z33>0)*($O$13:$Z$13)))*100 -> 84.615385 | AM33: =AF33/(SUMIF($E$14:$N$14,"CO5",$E$13:$N$13)+SUMPRODUCT(($O$14:$Z$14="CO5")*($O33:$Z33>0)*($O$13:$Z$13)))*100 -> 71.428571 | AN33: =AG33/(SUMIF($E$14:$N$14,"CO5",$E$13:$N$13)+SUMPRODUCT(($O$14:$Z$14="CO5")*($O33:$Z33>0)*($O$13:$Z$13)))*100 -> 0
A34: 18 | B34: ='STUDENT NAMELIST'!B22 -> 2023PEC AI 550 | C34: ='STUDENT NAMELIST'!C22 -> 211423243018 | D34: ='STUDENT NAMELIST'!D22 -> AKASH A | E34: 2 | F34: 2 | G34: 2 | H34: 2 | I34: 2 | J34: 2 | K34: 2 | L34: 0 | M34: 0 | N34: 0 | O34: 0 | P34: 10 | Q34: 10 | R34: 0 | S34: 0 | T34: 10 | U34: 0 | V34: 10 | W34: 5 | X34: 0 | Y34: 0 | Z34: 11 | AA34: =SUM(E34,F34,G34,H34,I34,J34,K34,L34,M34,N34,O34,P34,Q34,R34,S34,T34,U34,V34,W34,X34,Y34,Z34) -> 70 | AB34: =SUMIF($E$14:$N$14,"CO1",E34:N34)+IF(O34>=0,SUMPRODUCT(($O$14:$Z$14="CO1")*(O34:Z34)*MOD(COLUMN($O$14:$Z$14)-COLUMN($O$14)+1,2))+SUMPRODUCT(($P$14:$Z$14="CO1")*(P34:Z34)*MOD(COLUMN($P$14:$Z$14)-COLUMN($P$14)+1,2))) -> 4 | AC34: =SUMIF($E$14:$N$14,"CO2",E34:N34)+IF(O34>=0,SUMPRODUCT(($O$14:$Z$14="CO2")*(O34:Z34)*MOD(COLUMN($O$14:$Z$14)-COLUMN($O$14)+1,2))+SUMPRODUCT(($P$14:$Z$14="CO2")*(Q34:AA34)*MOD(COLUMN($P$14:$Z$14)-COLUMN($P$14)+1,2))) -> 8 | AD34: =SUMIF($E$14:$N$14,"CO3",E34:N34)+IF(O34>=0, SUMPRODUCT(($O$14:$Z$14="CO3")*(O34:Z34)*MOD(COLUMN($O$14:$Z$14)-COLUMN($O$14)+1,2))+ SUMPRODUCT(($P$14:$Z$14="CO3")*(P34:Z34)*MOD(COLUMN($P$14:$Z$14)-COLUMN($P$14)+1,2))) -> 22 | AE34: =SUMIF($E$14:$N$14,"CO4",$E$17:$N$17) + IF(O34>=0, SUMPRODUCT(($O$14:$Z$14="CO4")*(O34:Z34)*MOD(COLUMN($O$14:$Z$14)-COLUMN($O$14)+1,2))+ SUMPRODUCT(($P$14:$Z$14="CO4")*(P34:Z34)*MOD(COLUMN($P$14:$Z$14)-COLUMN($P$14)+1,2))) -> 20 | AF34: =SUMIF($E$14:$N$14,"CO5",$E$17:$N$17) + IF(O34>=0, SUMPRODUCT(($O$14:$Z$14="CO5")*(O34:Z34)*MOD(COLUMN($O$14:$Z$14)-COLUMN($O$14)+1,2))+ SUMPRODUCT(($P$14:$Z$14="CO5")*(P34:Z34)*MOD(COLUMN($P$14:$Z$14)-COLUMN($P$14)+1,2)) ) -> 16 | AG34: =SUMIF($E$14:$N$14,"CO6",$E$17:$N$17) + IF(O34>0, SUMPRODUCT(($O$14:$Z$14="CO6")*($O$17:$Z$17)*MOD(COLUMN($O$14:$Z$14)-COLUMN($O$14)+1,2))+ SUMPRODUCT(($P$14:$Z$14="CO6")*($P$17:$Z$17)*MOD(COLUMN($P$14:$Z$14)-COLUMN($P$14)+1,2)) ) -> 0 | AH34: =SUM(AB34:AG34) -> 70 | AI34: =AB34/(SUMIF($E$14:$N$14,"CO1",$E$13:$N$13)+SUMPRODUCT(($O$14:$Z$14="CO1")*($O34:$Z34>0)*($O$13:$Z$13)))*100 -> 66.666667 | AJ34: =AC34/(SUMIF($E$14:$N$14,"CO2",$E$13:$N$13)+SUMPRODUCT(($O$14:$Z$14="CO2")*($O34:$Z34>0)*($O$13:$Z$13)))*100 -> 80 | AK34: =AD34/(SUMIF($E$14:$N$14,"CO3",$E$13:$N$13)+SUMPRODUCT(($O$14:$Z$14="CO3")*($O34:$Z34>0)*($O$13:$Z$13)))*100 -> 73.333333 | AL34: =AE34/(SUMIF($E$14:$N$14,"CO4",$E$13:$N$13)+SUMPRODUCT(($O$14:$Z$14="CO4")*($O34:$Z34>0)*($O$13:$Z$13)))*100 -> 76.923077 | AM34: =AF34/(SUMIF($E$14:$N$14,"CO5",$E$13:$N$13)+SUMPRODUCT(($O$14:$Z$14="CO5")*($O34:$Z34>0)*($O$13:$Z$13)))*100 -> 57.142857 | AN34: =AG34/(SUMIF($E$14:$N$14,"CO5",$E$13:$N$13)+SUMPRODUCT(($O$14:$Z$14="CO5")*($O34:$Z34>0)*($O$13:$Z$13)))*100 -> 0
